Workbook

Sheet General
A1: Municipalidad | B1: F.P. | C1: F.V. | D1: N° Lote | E1: Bolsa (Kg) | F1: Cantidad (Kg) | G1: Fecha | H1: Fecha Env. | I1: Marca | J1: Producto
A2: San Jose | B2: 45597 | C2: 45962 | D2: 1 | E2: 1 | F2: 3347 | G2: 45630 | I2: FACLAC | J2: MEZCLA DE CEREALES: HOJUELAS DE AVENA, QUINUA, KIWICHA CON MACA Y SOYA ENRIQUECIDA CON VITAMINAS Y MINERALES
A3: Pataz - Tayabamba | B3: 45627 | C3: 45809 | D3: 1 | E3: 1 | F3: 9286 | G3: 45642 | I3: FACLAC | J3: MEZCLA PRECOCIDA DE AVENA, KIWICHA, QUINUA, CAÑIHUA, CON SOYA Y MACA FORTIFICADA CON VITAMINAS Y MINERALES
A4: Viru | B4: 45627 | C4: 45992 | D4: 1 | E4: 1 | F4: 2810 | G4: 45653 | I4: FACLAC | J4: HOJUELAS PRECOCIDAS DE QUINUA, AVENA, KIWICHA, MACA, LINAZA, AJONJOLI, CON PROTEINA AISLADA DE SOYA Y OMEGA 3, FORTIFICADA CON VITAMINAS Y MINERALES
A5: Julcán | B5: 45627 | C5: 45992 | D5: 1 | E5: 1 | F5: 2588 | G5: 45656 | I5: FACLAC | J5: HOJUELAS PRECOCIDAS DE AVENA, QUINUA CON HARINA DE SOYA Y HARINA DE MACA FORTIFICADAS CON VITAMINAS Y MINERALES
A6: Olmos | B6: 45658 | C6: 46023 | D6: 1 | E6: 1 | F6: 5252 | G6: 45665 | I6: FACLAC | J6: MEZCLA PRECOCIDA DE QUINUA, KIWICHA, AVENA Y HARINA DE SOYA INTEGRAL TOSTADA CON LECHE ENTERA EN POLVO FORTIFICADA CON VITAMINAS Y MINERALES
A7: Marcabal | B7: 45658 | C7: 46023 | D7: 2 | E7: 1.5671 | F7: 4061.92 | G7: 45671 | I7: FACLAC | J7: HOJUELAS PRECOCIDAS DE KIWICHA, SOYA, CHUFLA, AVENA, PALLAR, CON MACA Y AZÚCAR RUBIA ENRIQUECIDA CON VITAMINAS Y MINERALES
A8: Julcán | B8: 45658 | C8: 46023 | D8: 2 | E8: 1 | F8: 2588 | G8: 45673 | I8: FACLAC | J8: HOJUELAS PRECOCIDAS DE AVENA, QUINUA CON HARINA DE SOYA Y HARINA DE MACA FORTIFICADAS CON VITAMINAS Y MINERALES
A9: Olmos | B9: 45689 | C9: 46054 | D9: 2 | E9: 1 | F9: 5840 | G9: 45691 | I9: FACLAC | J9: MEZCLA PRECOCIDA DE QUINUA, KIWICHA, AVENA Y HARINA DE SOYA INTEGRAL TOSTADA CON LECHE ENTERA EN POLVO FORTIFICADA CON VITAMINAS Y MINERALES
A10: San Pedro de Lloc | B10: 45658 | C10: 46023 | D10: 1 | E10: 1 | F10: 4691 | G10: 45691 | I10: FACLAC | J10: HOJUELA PRECOCIDAS DE AVENA, QUINUA, KIWICHA, MACA, FREJO TARWI, GARBANZOS Y SOYA FORTIFICADA CON VITAMINAS Y MINERALES
A11: Marcabal | B11: 45689 | C11: 46054 | D11: 3 | E11: 1.5671 | F11: 4061.92 | G11: 45700 | I11: FACLAC | J11: HOJUELAS PRECOCIDAS DE KIWICHA, SOYA, CHUFLA, AVENA, PALLAR, CON MACA Y AZÚCAR RUBIA ENRIQUECIDA CON VITAMINAS Y MINERALES
A12: Julcán | B12: 45689 | C12: 46054 | D12: 3 | E12: 1 | F12: 2600 | G12: 45702 | I12: FACLAC | J12: HOJUELAS PRECOCIDAS DE AVENA, QUINUA CON HARINA DE SOYA Y HARINA DE MACA FORTIFICADAS CON VITAMINAS Y MINERALES
A13: Viru | B13: 45689 | C13: 46054 | D13: 2 | E13: 1 | F13: 3108 | G13: 45702 | I13: FACLAC | J13: HOJUELAS PRECOCIDAS DE QUINUA, AVENA, KIWICHA, MACA, LINAZA, AJONJOLI, CON PROTEINA AISLADA DE SOYA Y OMEGA 3, FORTIFICADA CON VITAMINAS Y MINERALES
... A21: Pataz - Tayabamba | B21: 45717 | C21: 45901 | D21: 2 | E21: 1 | F21: 9268 | G21: 45739 | I21: FACLAC | J21: MEZCLA PRECOCIDA DE AVENA, KIWICHA, QUINUA, CAÑIHUA, CON SOYA Y MACA FORTIFICADA CON VITAMINAS Y MINERALES
A22: Chiclayo | B22: 45748 | C22: 46113 | D22: 1 | E22: 1 | F22: 30058 | G22: 45751 | H22: 45749 | I22: FACLAC | J22: HOJUELA PRECOCIDA DE QUINUA, AVENA Y CEBADA TOSTADA Y MOLIDA ENRIQUECIDA CON VITAMINAS Y MINERALES
A23: Olmos | B23: 45748 | C23: 46113 | D23: 4 | E23: 1 | F23: 5840 | G23: 45751 | H23: 45751 | I23: FACLAC | J23: MEZCLA PRECOCIDA DE QUINUA, KIWICHA, AVENA Y HARINA DE SOYA INTEGRAL TOSTADA CON LECHE ENTERA EN POLVO FORTIFICADA CON VITAMINAS Y MINERALES
A24: Marcabal | B24: 45748 | C24: 46113 | D24: 5 | E24: 1.5671 | F24: 4061.92 | G24: 45756 | H24: 45754 | I24: FACLAC | J24: HOJUELAS PRECOCIDAS DE KIWICHA, SOYA, CHUFLA, AVENA, PALLAR, CON MACA Y AZÚCAR RUBIA ENRIQUECIDA CON VITAMINAS Y MINERALES
A25: Cajamarca | B25: 45748 | C25: 46113 | D25: 1 | E25: 2.24 | F25: 10671.72 | G25: 45763 | H25: 45758 | I25: FACLAC | J25: HOJUELA PRECOCIDAS DE AVENA KIWICHA QUINUA CON HARINA DE SOYA, ACEITE VEGETAL, FORTIFICADA CON VITAMINAS Y MINERALES
A26: Cajamarca | B26: 45748 | C26: 46113 | D26: 1 | E26: 2.4 | F26: 11433.6 | G26: 45763 | H26: 45758 | I26: FACLAC | J26: HOJUELA PRECOCIDAS DE AVENA KIWICHA QUINUA CON HARINA DE SOYA, ACEITE VEGETAL, FORTIFICADA CON VITAMINAS Y MINERALES
A27: Cajamarca | B27: 45748 | C27: 46113 | D27: 1 | E27: 2.48 | F27: 23470.72 | G27: 45763 | H27: 45758 | I27: FACLAC | J27: HOJUELA PRECOCIDAS DE AVENA KIWICHA QUINUA CON HARINA DE SOYA, ACEITE VEGETAL, FORTIFICADA CON VITAMINAS Y MINERALES
A28: Julcán | B28: 45748 | C28: 46113 | D28: 5 | E28: 1 | F28: 2588 | G28: 45763 | H28: 45761 | I28: FACLAC | J28: HOJUELAS PRECOCIDAS DE AVENA, QUINUA CON HARINA DE SOYA Y HARINA DE MACA FORTIFICADAS CON VITAMINAS Y MINERALES
A29: Viru | B29: 45748 | C29: 46113 | D29: 4 | E29: 1 | F29: 3104 | G29: 45763 | H29: 45762 | I29: FACLAC | J29: HOJUELAS PRECOCIDAS DE QUINUA, AVENA, KIWICHA, MACA, LINAZA, AJONJOLI, CON PROTEINA AISLADA DE SOYA Y OMEGA 3, FORTIFICADA CON VITAMINAS Y MINERALES
A30: Chongoyape | B30: 45748 | C30: 46113 | D30: 2 | E30: 1 | F30: 1771 | G30: 45764 | H30: 45763 | I30: FACLAC | J30: MEZCLA PRECOCIDA DE AVENA, QUINUA, KIWICHA CON SOYA Y MACA AZUCARADA FORTIFICADO CON VITAMINAS Y MINERALES
A31: Olmos | B31: 45778 | C31: 46143 | D31: 5 | E31: 1 | F31: 5611 | G31: 45779 | H31: 45779 | I31: FACLAC | J31: MEZCLA PRECOCIDA DE QUINUA, KIWICHA, AVENA Y HARINA DE SOYA INTEGRAL TOSTADA CON LECHE ENTERA EN POLVO FORTIFICADA CON VITAMINAS Y MINERALES
A32: Cajamarca | B32: 45778 | C32: 46143 | D32: 2 | E32: 2.4 | F32: 11448 | G32: 45782 | H32: 45780 | I32: FACLAC | J32: HOJUELA PRECOCIDAS DE AVENA KIWICHA QUINUA CON HARINA DE SOYA, ACEITE VEGETAL, FORTIFICADA CON VITAMINAS Y MINERALES
A33: Cajamarca | B33: 45778 | C33: 46143 | D33: 2 | E33: 2.48 | F33: 11829.6 | G33: 45782 | H33: 45780 | I33: FACLAC | J33: HOJUELA PRECOCIDAS DE AVENA KIWICHA QUINUA CON HARINA DE SOYA, ACEITE VEGETAL, FORTIFICADA CON VITAMINAS Y MINERALES
... A55: Chiclayo | B55: 45839 | C55: 46204 | D55: 3 | E55: 1 | F55: 12220 | G55: 45853 | H55: 45852 | I55: FACLAC | J55: HOJUELA PRECOCIDA DE QUINUA, AVENA Y CEBADA TOSTADA Y MOLIDA ENRIQUECIDA CON VITAMINAS Y MINERALES
A56: Olmos | B56: 45870 | C56: 46235 | D56: 8 | E56: 1 | F56: 5619 | G56: 45870 | I56: FACLAC | J56: MEZCLA PRECOCIDA DE QUINUA, KIWICHA, AVENA Y HARINA DE SOYA INTEGRAL TOSTADA CON LECHE ENTERA EN POLVO FORTIFICADA CON VITAMINAS Y MINERALES
A57: Marcabal | B57: 45870 | C57: 46235 | D57: 9 | E57: 1.5671 | F57: 4061.92 | G57: 45876 | H57: 45874 | I57: FACLAC | J57: HOJUELAS PRECOCIDAS DE KIWICHA, SOYA, CHUFLA, AVENA, PALLAR, CON MACA Y AZÚCAR RUBIA ENRIQUECIDA CON VITAMINAS Y MINERALES
A58: Julcán | B58: 45870 | C58: 46235 | D58: 9 | E58: 1 | F58: 2588 | G58: 45880 | H58: 45878 | I58: FACLAC | J58: HOJUELAS PRECOCIDAS DE AVENA, QUINUA CON HARINA DE SOYA Y HARINA DE MACA FORTIFICADAS CON VITAMINAS Y MINERALES
A59: Chongoyape | B59: 45870 | C59: 46235 | D59: 6 | E59: 1 | F59: 1771 | G59: 45881 | I59: FACLAC | J59: MEZCLA PRECOCIDA DE AVENA, QUINUA, KIWICHA CON SOYA Y MACA AZUCARADA FORTIFICADO CON VITAMINAS Y MINERALES
A60: Viru | B60: 45870 | C60: 46235 | D60: 8 | E60: 1 | F60: 3006 | G60: 45887 | H60: 45881 | I60: FACLAC | J60: HOJUELAS PRECOCIDAS DE QUINUA, AVENA, KIWICHA, MACA, LINAZA, AJONJOLI, CON PROTEINA AISLADA DE SOYA Y OMEGA 3, FORTIFICADA CON VITAMINAS Y MINERALES
A61: Chiclayo | B61: 45870 | C61: 46235 | D61: 4 | E61: 1 | F61: 11825 | G61: 45887 | H61: 45884 | I61: FACLAC | J61: HOJUELA PRECOCIDA DE QUINUA, AVENA Y CEBADA TOSTADA Y MOLIDA ENRIQUECIDA CON VITAMINAS Y MINERALES
A62: Cajamarca | B62: 45901 | C62: 46266 | D62: 4 | E62: 2.4 | F62: 11448 | G62: 45902 | I62: FACLAC | J62: HOJUELA PRECOCIDAS DE AVENA KIWICHA QUINUA CON HARINA DE SOYA, ACEITE VEGETAL, FORTIFICADA CON VITAMINAS Y MINERALES
A63: Cajamarca | B63: 45901 | C63: 46266 | D63: 4 | E63: 2.48 | F63: 11829.6 | G63: 45902 | I63: FACLAC | J63: HOJUELA PRECOCIDAS DE AVENA KIWICHA QUINUA CON HARINA DE SOYA, ACEITE VEGETAL, FORTIFICADA CON VITAMINAS Y MINERALES
A64: Marcabal | B64: 45901 | C64: 46266 | D64: 10 | E64: 1.5671 | F64: 4061.92 | G64: 45908 | I64: FACLAC | J64: HOJUELAS PRECOCIDAS DE KIWICHA, SOYA, CHUFLA, AVENA, PALLAR, CON MACA Y AZÚCAR RUBIA ENRIQUECIDA CON VITAMINAS Y MINERALES
A65: Viru | B65: 45901 | C65: 46266 | D65: 9 | E65: 1 | F65: 3104 | G65: 45913 | I65: FACLAC | J65: HOJUELAS PRECOCIDAS DE QUINUA, AVENA, KIWICHA, MACA, LINAZA, AJONJOLI, CON PROTEINA AISLADA DE SOYA Y OMEGA 3, FORTIFICADA CON VITAMINAS Y MINERALES
A66: Chongoyape | B66: 45901 | C66: 46266 | D66: 7 | E66: 1 | F66: 5209 | G66: 45915 | I66: FACLAC | J66: MEZCLA PRECOCIDA DE AVENA, QUINUA, KIWICHA CON SOYA Y MACA AZUCARADA FORTIFICADO CON VITAMINAS Y MINERALES
A67: Chiclayo | B67: 45901 | C67: 46266 | D67: 5 | E67: 1 | F67: 12220 | G67: 45916 | I67: FACLAC | J67: HOJUELA PRECOCIDA DE QUINUA, AVENA Y CEBADA TOSTADA Y MOLIDA ENRIQUECIDA CON VITAMINAS Y MINERALES
A68: Julcán | B68: 45901 | C68: 46266 | D68: 10 | E68: 1 | F68: 2588 | G68: 45916 | I68: FACLAC | J68: HOJUELAS PRECOCIDAS DE AVENA, QUINUA CON HARINA DE SOYA Y HARINA DE MACA FORTIFICADAS CON VITAMINAS Y MINERALES
...

Sheet Mezclado
A1: Municipalidad | B1: Cantidad (Kg) | C1: Fecha | D1: Mezclado | E1: Avena | F1: Quinua | G1: Kiwicha | H1: Soya | I1: Maca | J1: Azucar | K1: Cebada | L1: Maiz Chufla | M1: Leche Polvo | N1: Cañihua | O1: Aceite Girasol | P1: Pallar seco | Q1: Almidon maca | R1: Linaza | S1: Ajonjoli | T1: Proteina aislada soya | U1: Frejol tarhui | V1: Garbanzo | W1: Fosfato Tricálcio | X1: Mix vitaminico
A2: {=General!A2:A74} -> San Jose | B2: {=General!F2:G74} -> 3347 | C2: 45630 | D2: =B2*1/(1-Formula!$B$19) -> 3350.3504 | E2: {=_xlfn._xlws.FILTER(Formula!$B$2:$U$12,Formula!$A$2:$A$12=A2,0)*D2} -> 377.91952 | F2: 824.85626 | G2: 1237.2844 | H2: 68.682182 | I2: 687.49189 | J2: 0 | K2: 0 | L2: 0 | M2: 0 | N2: 0 | O2: 0 | P2: 0 | Q2: 0 | R2: 0 | S2: 0 | T2: 0 | U2: 0 | V2: 0 | W2: 145.74024 | X2: 8.3758759
A3: Pataz - Tayabamba | B3: 9286 | C3: 45642 | D3: =B3*1/(1-Formula!$B$19) -> 9295.2953 | E3: {=_xlfn._xlws.FILTER(Formula!$B$2:$U$12,Formula!$A$2:$A$12=A3,0)*D3} -> 802.18398 | F3: 2479.0553 | G3: 2624.9914 | H3: 728.75115 | I3: 0 | J3: 0 | K3: 0 | L3: 0 | M3: 0 | N3: 1312.4957 | O3: 0 | P3: 0 | Q3: 1020.6234 | R3: 0 | S3: 0 | T3: 0 | U3: 0 | V3: 0 | W3: 309.53333 | X3: 17.661061
A4: Viru | B4: 2810 | C4: 45653 | D4: =B4*1/(1-Formula!$B$19) -> 2812.8128 | E4: {=_xlfn._xlws.FILTER(Formula!$B$2:$U$12,Formula!$A$2:$A$12=A4,0)*D4} -> 366.22823 | F4: 631.1952 | G4: 1262.3904 | H4: 0 | I4: 286.90691 | J4: 0 | K4: 0 | L4: 0 | M4: 0 | N4: 0 | O4: 51.755756 | P4: 0 | Q4: 0 | R4: 28.690691 | S4: 28.690691 | T4: 28.690691 | U4: 0 | V4: 0 | W4: 121.51351 | X4: 6.7507508
A5: Julcán | B5: 2588 | C5: 45656 | D5: =B5*1/(1-Formula!$B$19) -> 2590.5906 | E5: {=_xlfn._xlws.FILTER(Formula!$B$2:$U$12,Formula!$A$2:$A$12=A5,0)*D5} -> 141.96436 | F5: 417.34414 | G5: 0 | H5: 249.21481 | I5: 1670.1538 | J5: 0 | K5: 0 | L5: 0 | M5: 0 | N5: 0 | O5: 0 | P5: 0 | Q5: 0 | R5: 0 | S5: 0 | T5: 0 | U5: 0 | V5: 0 | W5: 105.95516 | X5: 5.9583584
A6: Olmos | B6: 5252 | C6: 45665 | D6: =B6*1/(1-Formula!$B$19) -> 5257.2573 | E6: {=_xlfn._xlws.FILTER(Formula!$B$2:$U$12,Formula!$A$2:$A$12=A6,0)*D6} -> 1883.6753 | F6: 1569.817 | G6: 627.71652 | H6: 46.263864 | I6: 0 | J6: 0 | K6: 0 | L6: 0 | M6: 923.17437 | N6: 0 | O6: 0 | P6: 0 | Q6: 0 | R6: 0 | S6: 0 | T6: 0 | U6: 0 | V6: 0 | W6: 195.56997 | X6: 11.04024
A7: Marcabal | B7: 4061.92 | C7: 45671 | D7: =B7*1/(1-Formula!$B$19) -> 4065.986 | E7: {=_xlfn._xlws.FILTER(Formula!$B$2:$U$12,Formula!$A$2:$A$12=A7,0)*D7} -> 467.18179 | F7: 0 | G7: 2367.6236 | H7: 328.53167 | I7: 0 | J7: 260.6297 | K7: 0 | L7: 449.69805 | M7: 0 | N7: 0 | O7: 0 | P7: 7.7253734 | Q7: 7.7253734 | R7: 0 | S7: 0 | T7: 0 | U7: 0 | V7: 0 | W7: 167.51862 | X7: 9.3517678
A8: Julcán | B8: 2588 | C8: 45673 | D8: =B8*1/(1-Formula!$B$19) -> 2590.5906 | E8: {=_xlfn._xlws.FILTER(Formula!$B$2:$U$12,Formula!$A$2:$A$12=A8,0)*D8} -> 141.96436 | F8: 417.34414 | G8: 0 | H8: 249.21481 | I8: 1670.1538 | J8: 0 | K8: 0 | L8: 0 | M8: 0 | N8: 0 | O8: 0 | P8: 0 | Q8: 0 | R8: 0 | S8: 0 | T8: 0 | U8: 0 | V8: 0 | W8: 105.95516 | X8: 5.9583584
A9: Olmos | B9: 5840 | C9: 45691 | D9: =B9*1/(1-Formula!$B$19) -> 5845.8458 | E9: {=_xlfn._xlws.FILTER(Formula!$B$2:$U$12,Formula!$A$2:$A$12=A9,0)*D9} -> 2094.5666 | F9: 1745.5696 | G9: 697.99399 | H9: 51.443443 | I9: 0 | J9: 0 | K9: 0 | L9: 0 | M9: 1026.5305 | N9: 0 | O9: 0 | P9: 0 | Q9: 0 | R9: 0 | S9: 0 | T9: 0 | U9: 0 | V9: 0 | W9: 217.46547 | X9: 12.276276
A10: San Pedro de Lloc | B10: 4691 | C10: 45691 | D10: =B10*1/(1-Formula!$B$19) -> 4695.6957 | E10: {=_xlfn._xlws.FILTER(Formula!$B$2:$U$12,Formula!$A$2:$A$12=A10,0)*D10} -> 299.11582 | F10: 729.24154 | G10: 2734.3036 | H10: 72.783283 | I10: 547.04855 | J10: 0 | K10: 0 | L10: 0 | M10: 0 | N10: 0 | O10: 0 | P10: 0 | Q10: 0 | R10: 0 | S10: 0 | T10: 0 | U10: 91.096496 | V10: 18.313213 | W10: 192.99309 | X10: 10.8001
A11: Marcabal | B11: 4061.92 | C11: 45700 | D11: =B11*1/(1-Formula!$B$19) -> 4065.986 | E11: {=_xlfn._xlws.FILTER(Formula!$B$2:$U$12,Formula!$A$2:$A$12=A11,0)*D11} -> 467.18179 | F11: 0 | G11: 2367.6236 | H11: 328.53167 | I11: 0 | J11: 260.6297 | K11: 0 | L11: 449.69805 | M11: 0 | N11: 0 | O11: 0 | P11: 7.7253734 | Q11: 7.7253734 | R11: 0 | S11: 0 | T11: 0 | U11: 0 | V11: 0 | W11: 167.51862 | X11: 9.3517678
A12: Julcán | B12: 2600 | C12: 45702 | D12: =B12*1/(1-Formula!$B$19) -> 2602.6026 | E12: {=_xlfn._xlws.FILTER(Formula!$B$2:$U$12,Formula!$A$2:$A$12=A12,0)*D12} -> 142.62262 | F12: 419.27928 | G12: 0 | H12: 250.37037 | I12: 1677.8979 | J12: 0 | K12: 0 | L12: 0 | M12: 0 | N12: 0 | O12: 0 | P12: 0 | Q12: 0 | R12: 0 | S12: 0 | T12: 0 | U12: 0 | V12: 0 | W12: 106.44645 | X12: 5.985986
A13: Viru | B13: 3108 | C13: 45702 | D13: =B13*1/(1-Formula!$B$19) -> 3111.1111 | E13: {=_xlfn._xlws.FILTER(Formula!$B$2:$U$12,Formula!$A$2:$A$12=A13,0)*D13} -> 405.06667 | F13: 698.13333 | G13: 1396.2667 | H13: 0 | I13: 317.33333 | J13: 0 | K13: 0 | L13: 0 | M13: 0 | N13: 0 | O13: 57.244444 | P13: 0 | Q13: 0 | R13: 31.733333 | S13: 31.733333 | T13: 31.733333 | U13: 0 | V13: 0 | W13: 134.4 | X13: 7.4666667
A14: Olmos | B14: 5611 | C14: 45717 | D14: =B14*1/(1-Formula!$B$19) -> 5616.6166 | E14: {=_xlfn._xlws.FILTER(Formula!$B$2:$U$12,Formula!$A$2:$A$12=A14,0)*D14} -> 2012.4337 | F14: 1677.1217 | G14: 670.62402 | H14: 49.426226 | I14: 0 | J14: 0 | K14: 0 | L14: 0 | M14: 986.27788 | N14: 0 | O14: 0 | P14: 0 | Q14: 0 | R14: 0 | S14: 0 | T14: 0 | U14: 0 | V14: 0 | W14: 208.93814 | X14: 11.794895
... A74: Olmos | B74: 5840 | C74: 45962 | D74: =B74*1/(1-Formula!$B$19) -> 5845.8458 | E74: {=_xlfn._xlws.FILTER(Formula!$B$2:$U$12,Formula!$A$2:$A$12=A74,0)*D74} -> 2094.5666 | F74: 1745.5696 | G74: 697.99399 | H74: 51.443443 | I74: 0 | J74: 0 | K74: 0 | L74: 0 | M74: 1026.5305 | N74: 0 | O74: 0 | P74: 0 | Q74: 0 | R74: 0 | S74: 0 | T74: 0 | U74: 0 | V74: 0 | W74: 217.46547 | X74: 12.276276
A79: Cajamarca - kg | E79: {=400*Formula!B2:U2} -> 138.8 | F79: 75 | G79: 150 | H79: 15 | I79: 0 | J79: 0 | K79: 0 | L79: 0 | M79: 0 | N79: 0 | O79: 10 | P79: 0 | Q79: 0 | R79: 0 | S79: 0 | T79: 0 | U79: 0 | V79: 0 | W79: 10.6 | X79: 0.6
A80: Chiclayo - kg | C80: =D74/400 -> 14.614615 | D80: =(C80-14)*400 -> 245.84585 | E80: {=400*Formula!B3:U3} -> 112.924 | F80: 157 | G80: 0 | H80: 0 | I80: 0 | J80: 0 | K80: 112.924 | L80: 0 | M80: 0 | N80: 0 | O80: 0 | P80: 0 | Q80: 0 | R80: 0 | S80: 0 | T80: 0 | U80: 0 | V80: 0 | W80: 16.24 | X80: 0.916
A81: Chongoyape kg | E81: {=400*Formula!B4:U4} -> 24.76 | F81: 62.76 | G81: 203.92 | H81: 20.4 | I81: 39.2 | J81: 31.36 | K81: 0 | L81: 0 | M81: 0 | N81: 0 | O81: 0 | P81: 0 | Q81: 0 | R81: 0 | S81: 0 | T81: 0 | U81: 0 | V81: 0 | W81: 16.64 | X81: 0.96
A82: Julcán kg | E82: {=400*Formula!B5:U5} -> 21.92 | F82: 64.44 | G82: 0 | H82: 38.48 | I82: 257.88 | J82: 0 | K82: 0 | L82: 0 | M82: 0 | N82: 0 | O82: 0 | P82: 0 | Q82: 0 | R82: 0 | S82: 0 | T82: 0 | U82: 0 | V82: 0 | W82: 16.36 | X82: 0.92
A83: Marcabal kg | E83: {=400*Formula!B6:U6} -> 45.96 | F83: 0 | G83: 232.92 | H83: 32.32 | I83: 0 | J83: 25.64 | K83: 0 | L83: 44.24 | M83: 0 | N83: 0 | O83: 0 | P83: 0.76 | Q83: 0.76 | R83: 0 | S83: 0 | T83: 0 | U83: 0 | V83: 0 | W83: 16.48 | X83: 0.92
A84: Olmos kg | E84: {=400*Formula!B7:U7} -> 143.32 | F84: 119.44 | G84: 47.76 | H84: 3.52 | I84: 0 | J84: 0 | K84: 0 | L84: 0 | M84: 70.24 | N84: 0 | O84: 0 | P84: 0 | Q84: 0 | R84: 0 | S84: 0 | T84: 0 | U84: 0 | V84: 0 | W84: 14.88 | X84: 0.84
A85: San Jose kg | E85: {=400*Formula!B8:U8} -> 45.12 | F85: 98.48 | G85: 147.72 | H85: 8.2 | I85: 82.08 | J85: 0 | K85: 0 | L85: 0 | M85: 0 | N85: 0 | O85: 0 | P85: 0 | Q85: 0 | R85: 0 | S85: 0 | T85: 0 | U85: 0 | V85: 0 | W85: 17.4 | X85: 1
A86: Pataz - Tayabamba kg | E86: {=400*Formula!B9:U9} -> 34.52 | F86: 106.68 | G86: 112.96 | H86: 31.36 | I86: 0 | J86: 0 | K86: 0 | L86: 0 | M86: 0 | N86: 56.48 | O86: 0 | P86: 0 | Q86: 43.92 | R86: 0 | S86: 0 | T86: 0 | U86: 0 | V86: 0 | W86: 13.32 | X86: 0.76
A87: Viru kg | E87: {=400*Formula!B10:U10} -> 52.08 | F87: 89.76 | G87: 179.52 | H87: 0 | I87: 40.8 | J87: 0 | K87: 0 | L87: 0 | M87: 0 | N87: 0 | O87: 7.36 | P87: 0 | Q87: 0 | R87: 4.08 | S87: 4.08 | T87: 4.08 | U87: 0 | V87: 0 | W87: 17.28 | X87: 0.96
A88: San Pedro de Lloc kg | E88: {=400*Formula!B11:U11} -> 25.48 | F88: 62.12 | G88: 232.92 | H88: 6.2 | I88: 46.6 | J88: 0 | K88: 0 | L88: 0 | M88: 0 | N88: 0 | O88: 0 | P88: 0 | Q88: 0 | R88: 0 | S88: 0 | T88: 0 | U88: 7.76 | V88: 1.56 | W88: 16.44 | X88: 0.92
A89: Cajatambo kg | E89: {=400*Formula!B12:U12} -> 280 | F89: 120 | G89: 0 | H89: 0 | I89: 0 | J89: 0 | K89: 0 | L89: 0 | M89: 0 | N89: 0 | O89: 0 | P89: 0 | Q89: 0 | R89: 0 | S89: 0 | T89: 0 | U89: 0 | V89: 0 | W89: 0 | X89: 0
D92: =D80 -> 245.84585 | E92: {=D92*Formula!B12:U12} -> 172.09209 | F92: 73.753754 | G92: 0 | H92: 0 | I92: 0 | J92: 0 | K92: 0 | L92: 0 | M92: 0 | N92: 0 | O92: 0 | P92: 0 | Q92: 0 | R92: 0 | S92: 0 | T92: 0 | U92: 0 | V92: 0 | W92: 0 | X92: 0

Sheet Laminado
A1: Municipalidad | B1: Cantidad (Kg) | C1: Fecha | D1: Avena | E1: Quinua | F1: Kiwicha
A2: {=Mezclado!A2:C74} -> San Jose | B2: 3347 | C2: 45630 | D2: {=IF(ISNUMBER(MATCH(Mezclado!$A2, _xlfn._xlws.FILTER(Procesos!$A$2:$A$23, Procesos!B$2:B$23="Laminado"), 0)), Mezclado!E2/(1-Formula!$B$18),0)} -> 379.05669 | E2: {=IF(ISNUMBER(MATCH(Mezclado!$A2, _xlfn._xlws.FILTER(Procesos!$A$2:$A$23, Procesos!C$2:C$23="Laminado"), 0)), Mezclado!F2/(1-Formula!$B$18),0)} -> 827.33827 | F2: {=IF(ISNUMBER(MATCH(Mezclado!$A2, _xlfn._xlws.FILTER(Procesos!$A$2:$A$23, Procesos!D$2:D$23="Laminado"), 0)), Mezclado!G2/(1-Formula!$B$18),0)} -> 1241.0074
A3: Pataz - Tayabamba | B3: 9286 | C3: 45642 | D3: {=IF(ISNUMBER(MATCH(Mezclado!$A3, _xlfn._xlws.FILTER(Procesos!$A$2:$A$23, Procesos!B$2:B$23="Laminado"), 0)), Mezclado!E3/(1-Formula!$B$18),0)} -> 804.59778 | E3: {=IF(ISNUMBER(MATCH(Mezclado!$A3, _xlfn._xlws.FILTER(Procesos!$A$2:$A$23, Procesos!C$2:C$23="Laminado"), 0)), Mezclado!F3/(1-Formula!$B$18),0)} -> 0 | F3: {=IF(ISNUMBER(MATCH(Mezclado!$A3, _xlfn._xlws.FILTER(Procesos!$A$2:$A$23, Procesos!D$2:D$23="Laminado"), 0)), Mezclado!G3/(1-Formula!$B$18),0)} -> 0
A4: Viru | B4: 2810 | C4: 45653 | D4: {=IF(ISNUMBER(MATCH(Mezclado!$A4, _xlfn._xlws.FILTER(Procesos!$A$2:$A$23, Procesos!B$2:B$23="Laminado"), 0)), Mezclado!E4/(1-Formula!$B$18),0)} -> 367.33022 | E4: {=IF(ISNUMBER(MATCH(Mezclado!$A4, _xlfn._xlws.FILTER(Procesos!$A$2:$A$23, Procesos!C$2:C$23="Laminado"), 0)), Mezclado!F4/(1-Formula!$B$18),0)} -> 633.09448 | F4: {=IF(ISNUMBER(MATCH(Mezclado!$A4, _xlfn._xlws.FILTER(Procesos!$A$2:$A$23, Procesos!D$2:D$23="Laminado"), 0)), Mezclado!G4/(1-Formula!$B$18),0)} -> 1266.189
A5: Julcán | B5: 2588 | C5: 45656 | D5: {=IF(ISNUMBER(MATCH(Mezclado!$A5, _xlfn._xlws.FILTER(Procesos!$A$2:$A$23, Procesos!B$2:B$23="Laminado"), 0)), Mezclado!E5/(1-Formula!$B$18),0)} -> 142.39154 | E5: {=IF(ISNUMBER(MATCH(Mezclado!$A5, _xlfn._xlws.FILTER(Procesos!$A$2:$A$23, Procesos!C$2:C$23="Laminado"), 0)), Mezclado!F5/(1-Formula!$B$18),0)} -> 418.59994 | F5: {=IF(ISNUMBER(MATCH(Mezclado!$A5, _xlfn._xlws.FILTER(Procesos!$A$2:$A$23, Procesos!D$2:D$23="Laminado"), 0)), Mezclado!G5/(1-Formula!$B$18),0)} -> 0
A6: Olmos | B6: 5252 | C6: 45665 | D6: {=IF(ISNUMBER(MATCH(Mezclado!$A6, _xlfn._xlws.FILTER(Procesos!$A$2:$A$23, Procesos!B$2:B$23="Laminado"), 0)), Mezclado!E6/(1-Formula!$B$18),0)} -> 1889.3433 | E6: {=IF(ISNUMBER(MATCH(Mezclado!$A6, _xlfn._xlws.FILTER(Procesos!$A$2:$A$23, Procesos!C$2:C$23="Laminado"), 0)), Mezclado!F6/(1-Formula!$B$18),0)} -> 1574.5406 | F6: {=IF(ISNUMBER(MATCH(Mezclado!$A6, _xlfn._xlws.FILTER(Procesos!$A$2:$A$23, Procesos!D$2:D$23="Laminado"), 0)), Mezclado!G6/(1-Formula!$B$18),0)} -> 0
A7: Marcabal | B7: 4061.92 | C7: 45671 | D7: {=IF(ISNUMBER(MATCH(Mezclado!$A7, _xlfn._xlws.FILTER(Procesos!$A$2:$A$23, Procesos!B$2:B$23="Laminado"), 0)), Mezclado!E7/(1-Formula!$B$18),0)} -> 468.58755 | E7: {=IF(ISNUMBER(MATCH(Mezclado!$A7, _xlfn._xlws.FILTER(Procesos!$A$2:$A$23, Procesos!C$2:C$23="Laminado"), 0)), Mezclado!F7/(1-Formula!$B$18),0)} -> 0 | F7: {=IF(ISNUMBER(MATCH(Mezclado!$A7, _xlfn._xlws.FILTER(Procesos!$A$2:$A$23, Procesos!D$2:D$23="Laminado"), 0)), Mezclado!G7/(1-Formula!$B$18),0)} -> 2374.7479
A8: Julcán | B8: 2588 | C8: 45673 | D8: {=IF(ISNUMBER(MATCH(Mezclado!$A8, _xlfn._xlws.FILTER(Procesos!$A$2:$A$23, Procesos!B$2:B$23="Laminado"), 0)), Mezclado!E8/(1-Formula!$B$18),0)} -> 142.39154 | E8: {=IF(ISNUMBER(MATCH(Mezclado!$A8, _xlfn._xlws.FILTER(Procesos!$A$2:$A$23, Procesos!C$2:C$23="Laminado"), 0)), Mezclado!F8/(1-Formula!$B$18),0)} -> 418.59994 | F8: {=IF(ISNUMBER(MATCH(Mezclado!$A8, _xlfn._xlws.FILTER(Procesos!$A$2:$A$23, Procesos!D$2:D$23="Laminado"), 0)), Mezclado!G8/(1-Formula!$B$18),0)} -> 0
A9: Olmos | B9: 5840 | C9: 45691 | D9: {=IF(ISNUMBER(MATCH(Mezclado!$A9, _xlfn._xlws.FILTER(Procesos!$A$2:$A$23, Procesos!B$2:B$23="Laminado"), 0)), Mezclado!E9/(1-Formula!$B$18),0)} -> 2100.8692 | E9: {=IF(ISNUMBER(MATCH(Mezclado!$A9, _xlfn._xlws.FILTER(Procesos!$A$2:$A$23, Procesos!C$2:C$23="Laminado"), 0)), Mezclado!F9/(1-Formula!$B$18),0)} -> 1750.822 | F9: {=IF(ISNUMBER(MATCH(Mezclado!$A9, _xlfn._xlws.FILTER(Procesos!$A$2:$A$23, Procesos!D$2:D$23="Laminado"), 0)), Mezclado!G9/(1-Formula!$B$18),0)} -> 0
A10: San Pedro de Lloc | B10: 4691 | C10: 45691 | D10: {=IF(ISNUMBER(MATCH(Mezclado!$A10, _xlfn._xlws.FILTER(Procesos!$A$2:$A$23, Procesos!B$2:B$23="Laminado"), 0)), Mezclado!E10/(1-Formula!$B$18),0)} -> 300.01586 | E10: {=IF(ISNUMBER(MATCH(Mezclado!$A10, _xlfn._xlws.FILTER(Procesos!$A$2:$A$23, Procesos!C$2:C$23="Laminado"), 0)), Mezclado!F10/(1-Formula!$B$18),0)} -> 731.43585 | F10: {=IF(ISNUMBER(MATCH(Mezclado!$A10, _xlfn._xlws.FILTER(Procesos!$A$2:$A$23, Procesos!D$2:D$23="Laminado"), 0)), Mezclado!G10/(1-Formula!$B$18),0)} -> 2742.5312
A11: Marcabal | B11: 4061.92 | C11: 45700 | D11: {=IF(ISNUMBER(MATCH(Mezclado!$A11, _xlfn._xlws.FILTER(Procesos!$A$2:$A$23, Procesos!B$2:B$23="Laminado"), 0)), Mezclado!E11/(1-Formula!$B$18),0)} -> 468.58755 | E11: {=IF(ISNUMBER(MATCH(Mezclado!$A11, _xlfn._xlws.FILTER(Procesos!$A$2:$A$23, Procesos!C$2:C$23="Laminado"), 0)), Mezclado!F11/(1-Formula!$B$18),0)} -> 0 | F11: {=IF(ISNUMBER(MATCH(Mezclado!$A11, _xlfn._xlws.FILTER(Procesos!$A$2:$A$23, Procesos!D$2:D$23="Laminado"), 0)), Mezclado!G11/(1-Formula!$B$18),0)} -> 2374.7479
A12: Julcán | B12: 2600 | C12: 45702 | D12: {=IF(ISNUMBER(MATCH(Mezclado!$A12, _xlfn._xlws.FILTER(Procesos!$A$2:$A$23, Procesos!B$2:B$23="Laminado"), 0)), Mezclado!E12/(1-Formula!$B$18),0)} -> 143.05178 | E12: {=IF(ISNUMBER(MATCH(Mezclado!$A12, _xlfn._xlws.FILTER(Procesos!$A$2:$A$23, Procesos!C$2:C$23="Laminado"), 0)), Mezclado!F12/(1-Formula!$B$18),0)} -> 420.5409 | F12: {=IF(ISNUMBER(MATCH(Mezclado!$A12, _xlfn._xlws.FILTER(Procesos!$A$2:$A$23, Procesos!D$2:D$23="Laminado"), 0)), Mezclado!G12/(1-Formula!$B$18),0)} -> 0
A13: Viru | B13: 3108 | C13: 45702 | D13: {=IF(ISNUMBER(MATCH(Mezclado!$A13, _xlfn._xlws.FILTER(Procesos!$A$2:$A$23, Procesos!B$2:B$23="Laminado"), 0)), Mezclado!E13/(1-Formula!$B$18),0)} -> 406.28552 | E13: {=IF(ISNUMBER(MATCH(Mezclado!$A13, _xlfn._xlws.FILTER(Procesos!$A$2:$A$23, Procesos!C$2:C$23="Laminado"), 0)), Mezclado!F13/(1-Formula!$B$18),0)} -> 700.23404 | F13: {=IF(ISNUMBER(MATCH(Mezclado!$A13, _xlfn._xlws.FILTER(Procesos!$A$2:$A$23, Procesos!D$2:D$23="Laminado"), 0)), Mezclado!G13/(1-Formula!$B$18),0)} -> 1400.4681
A14: Olmos | B14: 5611 | C14: 45717 | D14: {=IF(ISNUMBER(MATCH(Mezclado!$A14, _xlfn._xlws.FILTER(Procesos!$A$2:$A$23, Procesos!B$2:B$23="Laminado"), 0)), Mezclado!E14/(1-Formula!$B$18),0)} -> 2018.4892 | E14: {=IF(ISNUMBER(MATCH(Mezclado!$A14, _xlfn._xlws.FILTER(Procesos!$A$2:$A$23, Procesos!C$2:C$23="Laminado"), 0)), Mezclado!F14/(1-Formula!$B$18),0)} -> 1682.1682 | F14: {=IF(ISNUMBER(MATCH(Mezclado!$A14, _xlfn._xlws.FILTER(Procesos!$A$2:$A$23, Procesos!D$2:D$23="Laminado"), 0)), Mezclado!G14/(1-Formula!$B$18),0)} -> 0
... A74: Olmos | B74: 5840 | C74: 45962 | D74: {=IF(ISNUMBER(MATCH(Mezclado!$A74, _xlfn._xlws.FILTER(Procesos!$A$2:$A$23, Procesos!B$2:B$23="Laminado"), 0)), Mezclado!E74/(1-Formula!$B$18),0)} -> 2100.8692 | E74: {=IF(ISNUMBER(MATCH(Mezclado!$A74, _xlfn._xlws.FILTER(Procesos!$A$2:$A$23, Procesos!C$2:C$23="Laminado"), 0)), Mezclado!F74/(1-Formula!$B$18),0)} -> 1750.822 | F74: {=IF(ISNUMBER(MATCH(Mezclado!$A74, _xlfn._xlws.FILTER(Procesos!$A$2:$A$23, Procesos!D$2:D$23="Laminado"), 0)), Mezclado!G74/(1-Formula!$B$18),0)} -> 0
D82: =E82*0.997 -> 2400.5756 | E82: =E55/2 -> 2407.799
F83: =F56/2 -> 0
D84: =D56/500 -> 4.0427342 | E84: =E56/500 -> 3.3691332 | F84: =F56/500/2 -> 0
D85: =D84*60 -> 242.56405 | F85: =F84-ROUNDDOWN(F84,0) -> 0
F86: =F85*60 -> 0
D89: =D38/500 -> 3.7754906 | E89: =E38/500 -> 1.6180674
D90: =D89*60 -> 226.52944 | E90: =E89*60 -> 97.084045

Sheet Molido
A1: Municipalidad | B1: Cantidad (Kg) | C1: Fecha | D1: Quinua | E1: Kiwicha | F1: Soya | G1: Maca | H1: Cebada | I1: Maiz Chufla | J1: Cañihua | K1: Pallar seco | L1: Garbanzo
A2: {=Mezclado!A2:C74} -> San Jose | B2: 3347 | C2: 45630 | D2: {=IF(ISNUMBER(MATCH(Mezclado!$A2, _xlfn._xlws.FILTER(Procesos!$A$2:$A$23, Procesos!C$2:C$23="Molido"), 0)), Mezclado!F2/(1-Formula!$B$17),0)} -> 0 | E2: {=IF(ISNUMBER(MATCH(Mezclado!$A2, _xlfn._xlws.FILTER(Procesos!$A$2:$A$23, Procesos!D$2:D$23="Molido"), 0)), Mezclado!G2/(1-Formula!$B$17),0)} -> 0 | F2: {=IF(ISNUMBER(MATCH(Mezclado!$A2, _xlfn._xlws.FILTER(Procesos!$A$2:$A$23, Procesos!E$2:E$23="Molido"), 0)), Mezclado!H2/(1-Formula!$B$17),0)} -> 70.083859 | G2: {=IF(ISNUMBER(MATCH(Mezclado!$A2, _xlfn._xlws.FILTER(Procesos!$A$2:$A$23, Procesos!F$2:F$23="Molido"), 0)), Mezclado!I2/(1-Formula!$B$17),0)} -> 701.52234 | H2: {=IF(ISNUMBER(MATCH(Mezclado!$A2, _xlfn._xlws.FILTER(Procesos!$A$2:$A$23, Procesos!H$2:H$23="Molido"), 0)), Mezclado!K2/(1-Formula!$B$17),0)} -> 0 | I2: {=IF(ISNUMBER(MATCH(Mezclado!$A2, _xlfn._xlws.FILTER(Procesos!$A$2:$A$23, Procesos!I$2:I$23="Molido"), 0)), Mezclado!L2/(1-Formula!$B$17),0)} -> 0 | J2: {=IF(ISNUMBER(MATCH(Mezclado!$A2, _xlfn._xlws.FILTER(Procesos!$A$2:$A$23, Procesos!K$2:K$23="Molido"), 0)), Mezclado!N2/(1-Formula!$B$17),0)} -> 0 | K2: {=IF(ISNUMBER(MATCH(Mezclado!$A2, _xlfn._xlws.FILTER(Procesos!$A$2:$A$23, Procesos!M$2:M$23="Molido"), 0)), Mezclado!P2/(1-Formula!$B$17),0)} -> 0 | L2: {=Mezclado!V2:V74/(1-Formula!$B$17)} -> 0
A3: Pataz - Tayabamba | B3: 9286 | C3: 45642 | D3: {=IF(ISNUMBER(MATCH(Mezclado!$A3, _xlfn._xlws.FILTER(Procesos!$A$2:$A$23, Procesos!C$2:C$23="Molido"), 0)), Mezclado!F3/(1-Formula!$B$17),0)} -> 2529.6482 | E3: {=IF(ISNUMBER(MATCH(Mezclado!$A3, _xlfn._xlws.FILTER(Procesos!$A$2:$A$23, Procesos!D$2:D$23="Molido"), 0)), Mezclado!G3/(1-Formula!$B$17),0)} -> 2678.5626 | F3: {=IF(ISNUMBER(MATCH(Mezclado!$A3, _xlfn._xlws.FILTER(Procesos!$A$2:$A$23, Procesos!E$2:E$23="Molido"), 0)), Mezclado!H3/(1-Formula!$B$17),0)} -> 743.62362 | G3: {=IF(ISNUMBER(MATCH(Mezclado!$A3, _xlfn._xlws.FILTER(Procesos!$A$2:$A$23, Procesos!F$2:F$23="Molido"), 0)), Mezclado!I3/(1-Formula!$B$17),0)} -> 0 | H3: {=IF(ISNUMBER(MATCH(Mezclado!$A3, _xlfn._xlws.FILTER(Procesos!$A$2:$A$23, Procesos!H$2:H$23="Molido"), 0)), Mezclado!K3/(1-Formula!$B$17),0)} -> 0 | I3: {=IF(ISNUMBER(MATCH(Mezclado!$A3, _xlfn._xlws.FILTER(Procesos!$A$2:$A$23, Procesos!I$2:I$23="Molido"), 0)), Mezclado!L3/(1-Formula!$B$17),0)} -> 0 | J3: {=IF(ISNUMBER(MATCH(Mezclado!$A3, _xlfn._xlws.FILTER(Procesos!$A$2:$A$23, Procesos!K$2:K$23="Molido"), 0)), Mezclado!N3/(1-Formula!$B$17),0)} -> 1339.2813 | K3: {=IF(ISNUMBER(MATCH(Mezclado!$A3, _xlfn._xlws.FILTER(Procesos!$A$2:$A$23, Procesos!M$2:M$23="Molido"), 0)), Mezclado!P3/(1-Formula!$B$17),0)} -> 0 | L3: 0
A4: Viru | B4: 2810 | C4: 45653 | D4: {=IF(ISNUMBER(MATCH(Mezclado!$A4, _xlfn._xlws.FILTER(Procesos!$A$2:$A$23, Procesos!C$2:C$23="Molido"), 0)), Mezclado!F4/(1-Formula!$B$17),0)} -> 0 | E4: {=IF(ISNUMBER(MATCH(Mezclado!$A4, _xlfn._xlws.FILTER(Procesos!$A$2:$A$23, Procesos!D$2:D$23="Molido"), 0)), Mezclado!G4/(1-Formula!$B$17),0)} -> 0 | F4: {=IF(ISNUMBER(MATCH(Mezclado!$A4, _xlfn._xlws.FILTER(Procesos!$A$2:$A$23, Procesos!E$2:E$23="Molido"), 0)), Mezclado!H4/(1-Formula!$B$17),0)} -> 0 | G4: {=IF(ISNUMBER(MATCH(Mezclado!$A4, _xlfn._xlws.FILTER(Procesos!$A$2:$A$23, Procesos!F$2:F$23="Molido"), 0)), Mezclado!I4/(1-Formula!$B$17),0)} -> 292.76215 | H4: {=IF(ISNUMBER(MATCH(Mezclado!$A4, _xlfn._xlws.FILTER(Procesos!$A$2:$A$23, Procesos!H$2:H$23="Molido"), 0)), Mezclado!K4/(1-Formula!$B$17),0)} -> 0 | I4: {=IF(ISNUMBER(MATCH(Mezclado!$A4, _xlfn._xlws.FILTER(Procesos!$A$2:$A$23, Procesos!I$2:I$23="Molido"), 0)), Mezclado!L4/(1-Formula!$B$17),0)} -> 0 | J4: {=IF(ISNUMBER(MATCH(Mezclado!$A4, _xlfn._xlws.FILTER(Procesos!$A$2:$A$23, Procesos!K$2:K$23="Molido"), 0)), Mezclado!N4/(1-Formula!$B$17),0)} -> 0 | K4: {=IF(ISNUMBER(MATCH(Mezclado!$A4, _xlfn._xlws.FILTER(Procesos!$A$2:$A$23, Procesos!M$2:M$23="Molido"), 0)), Mezclado!P4/(1-Formula!$B$17),0)} -> 0 | L4: 0
A5: Julcán | B5: 2588 | C5: 45656 | D5: {=IF(ISNUMBER(MATCH(Mezclado!$A5, _xlfn._xlws.FILTER(Procesos!$A$2:$A$23, Procesos!C$2:C$23="Molido"), 0)), Mezclado!F5/(1-Formula!$B$17),0)} -> 0 | E5: {=IF(ISNUMBER(MATCH(Mezclado!$A5, _xlfn._xlws.FILTER(Procesos!$A$2:$A$23, Procesos!D$2:D$23="Molido"), 0)), Mezclado!G5/(1-Formula!$B$17),0)} -> 0 | F5: {=IF(ISNUMBER(MATCH(Mezclado!$A5, _xlfn._xlws.FILTER(Procesos!$A$2:$A$23, Procesos!E$2:E$23="Molido"), 0)), Mezclado!H5/(1-Formula!$B$17),0)} -> 254.30083 | G5: {=IF(ISNUMBER(MATCH(Mezclado!$A5, _xlfn._xlws.FILTER(Procesos!$A$2:$A$23, Procesos!F$2:F$23="Molido"), 0)), Mezclado!I5/(1-Formula!$B$17),0)} -> 1704.2385 | H5: {=IF(ISNUMBER(MATCH(Mezclado!$A5, _xlfn._xlws.FILTER(Procesos!$A$2:$A$23, Procesos!H$2:H$23="Molido"), 0)), Mezclado!K5/(1-Formula!$B$17),0)} -> 0 | I5: {=IF(ISNUMBER(MATCH(Mezclado!$A5, _xlfn._xlws.FILTER(Procesos!$A$2:$A$23, Procesos!I$2:I$23="Molido"), 0)), Mezclado!L5/(1-Formula!$B$17),0)} -> 0 | J5: {=IF(ISNUMBER(MATCH(Mezclado!$A5, _xlfn._xlws.FILTER(Procesos!$A$2:$A$23, Procesos!K$2:K$23="Molido"), 0)), Mezclado!N5/(1-Formula!$B$17),0)} -> 0 | K5: {=IF(ISNUMBER(MATCH(Mezclado!$A5, _xlfn._xlws.FILTER(Procesos!$A$2:$A$23, Procesos!M$2:M$23="Molido"), 0)), Mezclado!P5/(1-Formula!$B$17),0)} -> 0 | L5: 0
A6: Olmos | B6: 5252 | C6: 45665 | D6: {=IF(ISNUMBER(MATCH(Mezclado!$A6, _xlfn._xlws.FILTER(Procesos!$A$2:$A$23, Procesos!C$2:C$23="Molido"), 0)), Mezclado!F6/(1-Formula!$B$17),0)} -> 0 | E6: {=IF(ISNUMBER(MATCH(Mezclado!$A6, _xlfn._xlws.FILTER(Procesos!$A$2:$A$23, Procesos!D$2:D$23="Molido"), 0)), Mezclado!G6/(1-Formula!$B$17),0)} -> 640.52706 | F6: {=IF(ISNUMBER(MATCH(Mezclado!$A6, _xlfn._xlws.FILTER(Procesos!$A$2:$A$23, Procesos!E$2:E$23="Molido"), 0)), Mezclado!H6/(1-Formula!$B$17),0)} -> 47.208024 | G6: {=IF(ISNUMBER(MATCH(Mezclado!$A6, _xlfn._xlws.FILTER(Procesos!$A$2:$A$23, Procesos!F$2:F$23="Molido"), 0)), Mezclado!I6/(1-Formula!$B$17),0)} -> 0 | H6: {=IF(ISNUMBER(MATCH(Mezclado!$A6, _xlfn._xlws.FILTER(Procesos!$A$2:$A$23, Procesos!H$2:H$23="Molido"), 0)), Mezclado!K6/(1-Formula!$B$17),0)} -> 0 | I6: {=IF(ISNUMBER(MATCH(Mezclado!$A6, _xlfn._xlws.FILTER(Procesos!$A$2:$A$23, Procesos!I$2:I$23="Molido"), 0)), Mezclado!L6/(1-Formula!$B$17),0)} -> 0 | J6: {=IF(ISNUMBER(MATCH(Mezclado!$A6, _xlfn._xlws.FILTER(Procesos!$A$2:$A$23, Procesos!K$2:K$23="Molido"), 0)), Mezclado!N6/(1-Formula!$B$17),0)} -> 0 | K6: {=IF(ISNUMBER(MATCH(Mezclado!$A6, _xlfn._xlws.FILTER(Procesos!$A$2:$A$23, Procesos!M$2:M$23="Molido"), 0)), Mezclado!P6/(1-Formula!$B$17),0)} -> 0 | L6: 0
A7: Marcabal | B7: 4061.92 | C7: 45671 | D7: {=IF(ISNUMBER(MATCH(Mezclado!$A7, _xlfn._xlws.FILTER(Procesos!$A$2:$A$23, Procesos!C$2:C$23="Molido"), 0)), Mezclado!F7/(1-Formula!$B$17),0)} -> 0 | E7: {=IF(ISNUMBER(MATCH(Mezclado!$A7, _xlfn._xlws.FILTER(Procesos!$A$2:$A$23, Procesos!D$2:D$23="Molido"), 0)), Mezclado!G7/(1-Formula!$B$17),0)} -> 0 | F7: {=IF(ISNUMBER(MATCH(Mezclado!$A7, _xlfn._xlws.FILTER(Procesos!$A$2:$A$23, Procesos!E$2:E$23="Molido"), 0)), Mezclado!H7/(1-Formula!$B$17),0)} -> 335.2364 | G7: {=IF(ISNUMBER(MATCH(Mezclado!$A7, _xlfn._xlws.FILTER(Procesos!$A$2:$A$23, Procesos!F$2:F$23="Molido"), 0)), Mezclado!I7/(1-Formula!$B$17),0)} -> 0 | H7: {=IF(ISNUMBER(MATCH(Mezclado!$A7, _xlfn._xlws.FILTER(Procesos!$A$2:$A$23, Procesos!H$2:H$23="Molido"), 0)), Mezclado!K7/(1-Formula!$B$17),0)} -> 0 | I7: {=IF(ISNUMBER(MATCH(Mezclado!$A7, _xlfn._xlws.FILTER(Procesos!$A$2:$A$23, Procesos!I$2:I$23="Molido"), 0)), Mezclado!L7/(1-Formula!$B$17),0)} -> 458.87556 | J7: {=IF(ISNUMBER(MATCH(Mezclado!$A7, _xlfn._xlws.FILTER(Procesos!$A$2:$A$23, Procesos!K$2:K$23="Molido"), 0)), Mezclado!N7/(1-Formula!$B$17),0)} -> 0 | K7: {=IF(ISNUMBER(MATCH(Mezclado!$A7, _xlfn._xlws.FILTER(Procesos!$A$2:$A$23, Procesos!M$2:M$23="Molido"), 0)), Mezclado!P7/(1-Formula!$B$17),0)} -> 7.8830341 | L7: 0
A8: Julcán | B8: 2588 | C8: 45673 | D8: {=IF(ISNUMBER(MATCH(Mezclado!$A8, _xlfn._xlws.FILTER(Procesos!$A$2:$A$23, Procesos!C$2:C$23="Molido"), 0)), Mezclado!F8/(1-Formula!$B$17),0)} -> 0 | E8: {=IF(ISNUMBER(MATCH(Mezclado!$A8, _xlfn._xlws.FILTER(Procesos!$A$2:$A$23, Procesos!D$2:D$23="Molido"), 0)), Mezclado!G8/(1-Formula!$B$17),0)} -> 0 | F8: {=IF(ISNUMBER(MATCH(Mezclado!$A8, _xlfn._xlws.FILTER(Procesos!$A$2:$A$23, Procesos!E$2:E$23="Molido"), 0)), Mezclado!H8/(1-Formula!$B$17),0)} -> 254.30083 | G8: {=IF(ISNUMBER(MATCH(Mezclado!$A8, _xlfn._xlws.FILTER(Procesos!$A$2:$A$23, Procesos!F$2:F$23="Molido"), 0)), Mezclado!I8/(1-Formula!$B$17),0)} -> 1704.2385 | H8: {=IF(ISNUMBER(MATCH(Mezclado!$A8, _xlfn._xlws.FILTER(Procesos!$A$2:$A$23, Procesos!H$2:H$23="Molido"), 0)), Mezclado!K8/(1-Formula!$B$17),0)} -> 0 | I8: {=IF(ISNUMBER(MATCH(Mezclado!$A8, _xlfn._xlws.FILTER(Procesos!$A$2:$A$23, Procesos!I$2:I$23="Molido"), 0)), Mezclado!L8/(1-Formula!$B$17),0)} -> 0 | J8: {=IF(ISNUMBER(MATCH(Mezclado!$A8, _xlfn._xlws.FILTER(Procesos!$A$2:$A$23, Procesos!K$2:K$23="Molido"), 0)), Mezclado!N8/(1-Formula!$B$17),0)} -> 0 | K8: {=IF(ISNUMBER(MATCH(Mezclado!$A8, _xlfn._xlws.FILTER(Procesos!$A$2:$A$23, Procesos!M$2:M$23="Molido"), 0)), Mezclado!P8/(1-Formula!$B$17),0)} -> 0 | L8: 0
A9: Olmos | B9: 5840 | C9: 45691 | D9: {=IF(ISNUMBER(MATCH(Mezclado!$A9, _xlfn._xlws.FILTER(Procesos!$A$2:$A$23, Procesos!C$2:C$23="Molido"), 0)), Mezclado!F9/(1-Formula!$B$17),0)} -> 0 | E9: {=IF(ISNUMBER(MATCH(Mezclado!$A9, _xlfn._xlws.FILTER(Procesos!$A$2:$A$23, Procesos!D$2:D$23="Molido"), 0)), Mezclado!G9/(1-Formula!$B$17),0)} -> 712.23877 | F9: {=IF(ISNUMBER(MATCH(Mezclado!$A9, _xlfn._xlws.FILTER(Procesos!$A$2:$A$23, Procesos!E$2:E$23="Molido"), 0)), Mezclado!H9/(1-Formula!$B$17),0)} -> 52.49331 | G9: {=IF(ISNUMBER(MATCH(Mezclado!$A9, _xlfn._xlws.FILTER(Procesos!$A$2:$A$23, Procesos!F$2:F$23="Molido"), 0)), Mezclado!I9/(1-Formula!$B$17),0)} -> 0 | H9: {=IF(ISNUMBER(MATCH(Mezclado!$A9, _xlfn._xlws.FILTER(Procesos!$A$2:$A$23, Procesos!H$2:H$23="Molido"), 0)), Mezclado!K9/(1-Formula!$B$17),0)} -> 0 | I9: {=IF(ISNUMBER(MATCH(Mezclado!$A9, _xlfn._xlws.FILTER(Procesos!$A$2:$A$23, Procesos!I$2:I$23="Molido"), 0)), Mezclado!L9/(1-Formula!$B$17),0)} -> 0 | J9: {=IF(ISNUMBER(MATCH(Mezclado!$A9, _xlfn._xlws.FILTER(Procesos!$A$2:$A$23, Procesos!K$2:K$23="Molido"), 0)), Mezclado!N9/(1-Formula!$B$17),0)} -> 0 | K9: {=IF(ISNUMBER(MATCH(Mezclado!$A9, _xlfn._xlws.FILTER(Procesos!$A$2:$A$23, Procesos!M$2:M$23="Molido"), 0)), Mezclado!P9/(1-Formula!$B$17),0)} -> 0 | L9: 0
A10: San Pedro de Lloc | B10: 4691 | C10: 45691 | D10: {=IF(ISNUMBER(MATCH(Mezclado!$A10, _xlfn._xlws.FILTER(Procesos!$A$2:$A$23, Procesos!C$2:C$23="Molido"), 0)), Mezclado!F10/(1-Formula!$B$17),0)} -> 0 | E10: {=IF(ISNUMBER(MATCH(Mezclado!$A10, _xlfn._xlws.FILTER(Procesos!$A$2:$A$23, Procesos!D$2:D$23="Molido"), 0)), Mezclado!G10/(1-Formula!$B$17),0)} -> 0 | F10: {=IF(ISNUMBER(MATCH(Mezclado!$A10, _xlfn._xlws.FILTER(Procesos!$A$2:$A$23, Procesos!E$2:E$23="Molido"), 0)), Mezclado!H10/(1-Formula!$B$17),0)} -> 74.268656 | G10: {=IF(ISNUMBER(MATCH(Mezclado!$A10, _xlfn._xlws.FILTER(Procesos!$A$2:$A$23, Procesos!F$2:F$23="Molido"), 0)), Mezclado!I10/(1-Formula!$B$17),0)} -> 558.2128 | H10: {=IF(ISNUMBER(MATCH(Mezclado!$A10, _xlfn._xlws.FILTER(Procesos!$A$2:$A$23, Procesos!H$2:H$23="Molido"), 0)), Mezclado!K10/(1-Formula!$B$17),0)} -> 0 | I10: {=IF(ISNUMBER(MATCH(Mezclado!$A10, _xlfn._xlws.FILTER(Procesos!$A$2:$A$23, Procesos!I$2:I$23="Molido"), 0)), Mezclado!L10/(1-Formula!$B$17),0)} -> 0 | J10: {=IF(ISNUMBER(MATCH(Mezclado!$A10, _xlfn._xlws.FILTER(Procesos!$A$2:$A$23, Procesos!K$2:K$23="Molido"), 0)), Mezclado!N10/(1-Formula!$B$17),0)} -> 0 | K10: {=IF(ISNUMBER(MATCH(Mezclado!$A10, _xlfn._xlws.FILTER(Procesos!$A$2:$A$23, Procesos!M$2:M$23="Molido"), 0)), Mezclado!P10/(1-Formula!$B$17),0)} -> 0 | L10: 18.686952
A11: Marcabal | B11: 4061.92 | C11: 45700 | D11: {=IF(ISNUMBER(MATCH(Mezclado!$A11, _xlfn._xlws.FILTER(Procesos!$A$2:$A$23, Procesos!C$2:C$23="Molido"), 0)), Mezclado!F11/(1-Formula!$B$17),0)} -> 0 | E11: {=IF(ISNUMBER(MATCH(Mezclado!$A11, _xlfn._xlws.FILTER(Procesos!$A$2:$A$23, Procesos!D$2:D$23="Molido"), 0)), Mezclado!G11/(1-Formula!$B$17),0)} -> 0 | F11: {=IF(ISNUMBER(MATCH(Mezclado!$A11, _xlfn._xlws.FILTER(Procesos!$A$2:$A$23, Procesos!E$2:E$23="Molido"), 0)), Mezclado!H11/(1-Formula!$B$17),0)} -> 335.2364 | G11: {=IF(ISNUMBER(MATCH(Mezclado!$A11, _xlfn._xlws.FILTER(Procesos!$A$2:$A$23, Procesos!F$2:F$23="Molido"), 0)), Mezclado!I11/(1-Formula!$B$17),0)} -> 0 | H11: {=IF(ISNUMBER(MATCH(Mezclado!$A11, _xlfn._xlws.FILTER(Procesos!$A$2:$A$23, Procesos!H$2:H$23="Molido"), 0)), Mezclado!K11/(1-Formula!$B$17),0)} -> 0 | I11: {=IF(ISNUMBER(MATCH(Mezclado!$A11, _xlfn._xlws.FILTER(Procesos!$A$2:$A$23, Procesos!I$2:I$23="Molido"), 0)), Mezclado!L11/(1-Formula!$B$17),0)} -> 458.87556 | J11: {=IF(ISNUMBER(MATCH(Mezclado!$A11, _xlfn._xlws.FILTER(Procesos!$A$2:$A$23, Procesos!K$2:K$23="Molido"), 0)), Mezclado!N11/(1-Formula!$B$17),0)} -> 0 | K11: {=IF(ISNUMBER(MATCH(Mezclado!$A11, _xlfn._xlws.FILTER(Procesos!$A$2:$A$23, Procesos!M$2:M$23="Molido"), 0)), Mezclado!P11/(1-Formula!$B$17),0)} -> 7.8830341 | L11: 0
A12: Julcán | B12: 2600 | C12: 45702 | D12: {=IF(ISNUMBER(MATCH(Mezclado!$A12, _xlfn._xlws.FILTER(Procesos!$A$2:$A$23, Procesos!C$2:C$23="Molido"), 0)), Mezclado!F12/(1-Formula!$B$17),0)} -> 0 | E12: {=IF(ISNUMBER(MATCH(Mezclado!$A12, _xlfn._xlws.FILTER(Procesos!$A$2:$A$23, Procesos!D$2:D$23="Molido"), 0)), Mezclado!G12/(1-Formula!$B$17),0)} -> 0 | F12: {=IF(ISNUMBER(MATCH(Mezclado!$A12, _xlfn._xlws.FILTER(Procesos!$A$2:$A$23, Procesos!E$2:E$23="Molido"), 0)), Mezclado!H12/(1-Formula!$B$17),0)} -> 255.47997 | G12: {=IF(ISNUMBER(MATCH(Mezclado!$A12, _xlfn._xlws.FILTER(Procesos!$A$2:$A$23, Procesos!F$2:F$23="Molido"), 0)), Mezclado!I12/(1-Formula!$B$17),0)} -> 1712.1407 | H12: {=IF(ISNUMBER(MATCH(Mezclado!$A12, _xlfn._xlws.FILTER(Procesos!$A$2:$A$23, Procesos!H$2:H$23="Molido"), 0)), Mezclado!K12/(1-Formula!$B$17),0)} -> 0 | I12: {=IF(ISNUMBER(MATCH(Mezclado!$A12, _xlfn._xlws.FILTER(Procesos!$A$2:$A$23, Procesos!I$2:I$23="Molido"), 0)), Mezclado!L12/(1-Formula!$B$17),0)} -> 0 | J12: {=IF(ISNUMBER(MATCH(Mezclado!$A12, _xlfn._xlws.FILTER(Procesos!$A$2:$A$23, Procesos!K$2:K$23="Molido"), 0)), Mezclado!N12/(1-Formula!$B$17),0)} -> 0 | K12: {=IF(ISNUMBER(MATCH(Mezclado!$A12, _xlfn._xlws.FILTER(Procesos!$A$2:$A$23, Procesos!M$2:M$23="Molido"), 0)), Mezclado!P12/(1-Formula!$B$17),0)} -> 0 | L12: 0
A13: Viru | B13: 3108 | C13: 45702 | D13: {=IF(ISNUMBER(MATCH(Mezclado!$A13, _xlfn._xlws.FILTER(Procesos!$A$2:$A$23, Procesos!C$2:C$23="Molido"), 0)), Mezclado!F13/(1-Formula!$B$17),0)} -> 0 | E13: {=IF(ISNUMBER(MATCH(Mezclado!$A13, _xlfn._xlws.FILTER(Procesos!$A$2:$A$23, Procesos!D$2:D$23="Molido"), 0)), Mezclado!G13/(1-Formula!$B$17),0)} -> 0 | F13: {=IF(ISNUMBER(MATCH(Mezclado!$A13, _xlfn._xlws.FILTER(Procesos!$A$2:$A$23, Procesos!E$2:E$23="Molido"), 0)), Mezclado!H13/(1-Formula!$B$17),0)} -> 0 | G13: {=IF(ISNUMBER(MATCH(Mezclado!$A13, _xlfn._xlws.FILTER(Procesos!$A$2:$A$23, Procesos!F$2:F$23="Molido"), 0)), Mezclado!I13/(1-Formula!$B$17),0)} -> 323.80952 | H13: {=IF(ISNUMBER(MATCH(Mezclado!$A13, _xlfn._xlws.FILTER(Procesos!$A$2:$A$23, Procesos!H$2:H$23="Molido"), 0)), Mezclado!K13/(1-Formula!$B$17),0)} -> 0 | I13: {=IF(ISNUMBER(MATCH(Mezclado!$A13, _xlfn._xlws.FILTER(Procesos!$A$2:$A$23, Procesos!I$2:I$23="Molido"), 0)), Mezclado!L13/(1-Formula!$B$17),0)} -> 0 | J13: {=IF(ISNUMBER(MATCH(Mezclado!$A13, _xlfn._xlws.FILTER(Procesos!$A$2:$A$23, Procesos!K$2:K$23="Molido"), 0)), Mezclado!N13/(1-Formula!$B$17),0)} -> 0 | K13: {=IF(ISNUMBER(MATCH(Mezclado!$A13, _xlfn._xlws.FILTER(Procesos!$A$2:$A$23, Procesos!M$2:M$23="Molido"), 0)), Mezclado!P13/(1-Formula!$B$17),0)} -> 0 | L13: 0
A14: Olmos | B14: 5611 | C14: 45717 | D14: {=IF(ISNUMBER(MATCH(Mezclado!$A14, _xlfn._xlws.FILTER(Procesos!$A$2:$A$23, Procesos!C$2:C$23="Molido"), 0)), Mezclado!F14/(1-Formula!$B$17),0)} -> 0 | E14: {=IF(ISNUMBER(MATCH(Mezclado!$A14, _xlfn._xlws.FILTER(Procesos!$A$2:$A$23, Procesos!D$2:D$23="Molido"), 0)), Mezclado!G14/(1-Formula!$B$17),0)} -> 684.31023 | F14: {=IF(ISNUMBER(MATCH(Mezclado!$A14, _xlfn._xlws.FILTER(Procesos!$A$2:$A$23, Procesos!E$2:E$23="Molido"), 0)), Mezclado!H14/(1-Formula!$B$17),0)} -> 50.434925 | G14: {=IF(ISNUMBER(MATCH(Mezclado!$A14, _xlfn._xlws.FILTER(Procesos!$A$2:$A$23, Procesos!F$2:F$23="Molido"), 0)), Mezclado!I14/(1-Formula!$B$17),0)} -> 0 | H14: {=IF(ISNUMBER(MATCH(Mezclado!$A14, _xlfn._xlws.FILTER(Procesos!$A$2:$A$23, Procesos!H$2:H$23="Molido"), 0)), Mezclado!K14/(1-Formula!$B$17),0)} -> 0 | I14: {=IF(ISNUMBER(MATCH(Mezclado!$A14, _xlfn._xlws.FILTER(Procesos!$A$2:$A$23, Procesos!I$2:I$23="Molido"), 0)), Mezclado!L14/(1-Formula!$B$17),0)} -> 0 | J14: {=IF(ISNUMBER(MATCH(Mezclado!$A14, _xlfn._xlws.FILTER(Procesos!$A$2:$A$23, Procesos!K$2:K$23="Molido"), 0)), Mezclado!N14/(1-Formula!$B$17),0)} -> 0 | K14: {=IF(ISNUMBER(MATCH(Mezclado!$A14, _xlfn._xlws.FILTER(Procesos!$A$2:$A$23, Procesos!M$2:M$23="Molido"), 0)), Mezclado!P14/(1-Formula!$B$17),0)} -> 0 | L14: 0
... A74: Olmos | B74: 5840 | C74: 45962 | D74: {=IF(ISNUMBER(MATCH(Mezclado!$A74, _xlfn._xlws.FILTER(Procesos!$A$2:$A$23, Procesos!C$2:C$23="Molido"), 0)), Mezclado!F74/(1-Formula!$B$17),0)} -> 0 | E74: {=IF(ISNUMBER(MATCH(Mezclado!$A74, _xlfn._xlws.FILTER(Procesos!$A$2:$A$23, Procesos!D$2:D$23="Molido"), 0)), Mezclado!G74/(1-Formula!$B$17),0)} -> 712.23877 | F74: {=IF(ISNUMBER(MATCH(Mezclado!$A74, _xlfn._xlws.FILTER(Procesos!$A$2:$A$23, Procesos!E$2:E$23="Molido"), 0)), Mezclado!H74/(1-Formula!$B$17),0)} -> 52.49331 | G74: {=IF(ISNUMBER(MATCH(Mezclado!$A74, _xlfn._xlws.FILTER(Procesos!$A$2:$A$23, Procesos!F$2:F$23="Molido"), 0)), Mezclado!I74/(1-Formula!$B$17),0)} -> 0 | H74: {=IF(ISNUMBER(MATCH(Mezclado!$A74, _xlfn._xlws.FILTER(Procesos!$A$2:$A$23, Procesos!H$2:H$23="Molido"), 0)), Mezclado!K74/(1-Formula!$B$17),0)} -> 0 | I74: {=IF(ISNUMBER(MATCH(Mezclado!$A74, _xlfn._xlws.FILTER(Procesos!$A$2:$A$23, Procesos!I$2:I$23="Molido"), 0)), Mezclado!L74/(1-Formula!$B$17),0)} -> 0 | J74: {=IF(ISNUMBER(MATCH(Mezclado!$A74, _xlfn._xlws.FILTER(Procesos!$A$2:$A$23, Procesos!K$2:K$23="Molido"), 0)), Mezclado!N74/(1-Formula!$B$17),0)} -> 0 | K74: {=IF(ISNUMBER(MATCH(Mezclado!$A74, _xlfn._xlws.FILTER(Procesos!$A$2:$A$23, Procesos!M$2:M$23="Molido"), 0)), Mezclado!P74/(1-Formula!$B$17),0)} -> 0 | L74: 0

Sheet Tostado
A1: Municipalidad | B1: Cantidad (Kg) | C1: Fecha | D1: Quinua | E1: Kiwicha | F1: Soya | G1: Cebada | H1: Maiz Chufla | I1: Cañihua | J1: Pallar seco | K1: Garbanzo
A2: {=Mezclado!A2:C74} -> San Jose | B2: 3347 | C2: 45630 | D2: =SUM(Laminado!E2+Molido!D2)/(1-Formula!$B$16) -> 852.92605 | E2: =SUM(Laminado!F2+Molido!E2)/(1-Formula!$B$16) -> 1279.3891 | F2: {=Molido!F2:F74/(1-Formula!$B$16)} -> 72.251401 | G2: {=_xlfn.ANCHORARRAY(Limpieza!D3)/(1-Formula!$B$16)} -> 0 | H2: {=Molido!I2:L74/(1-Formula!$B$16)} -> 0 | I2: 0 | J2: 0 | K2: 0
A3: Pataz - Tayabamba | B3: 9286 | C3: 45642 | D3: =SUM(Laminado!E3+Molido!D3)/(1-Formula!$B$16) -> 2607.8848 | E3: =SUM(Laminado!F3+Molido!E3)/(1-Formula!$B$16) -> 2761.4048 | F3: 766.62229 | G3: 0 | H3: 0 | I3: 1380.7024 | J3: 0 | K3: 0
A4: Viru | B4: 2810 | C4: 45653 | D4: =SUM(Laminado!E4+Molido!D4)/(1-Formula!$B$16) -> 652.67472 | E4: =SUM(Laminado!F4+Molido!E4)/(1-Formula!$B$16) -> 1305.3494 | F4: 0 | G4: 0 | H4: 0 | I4: 0 | J4: 0 | K4: 0
A5: Julcán | B5: 2588 | C5: 45656 | D5: =SUM(Laminado!E5+Molido!D5)/(1-Formula!$B$16) -> 431.54633 | E5: =SUM(Laminado!F5+Molido!E5)/(1-Formula!$B$16) -> 0 | F5: 262.16581 | G5: 0 | H5: 0 | I5: 0 | J5: 0 | K5: 0
A6: Olmos | B6: 5252 | C6: 45665 | D6: =SUM(Laminado!E6+Molido!D6)/(1-Formula!$B$16) -> 1623.2378 | E6: =SUM(Laminado!F6+Molido!E6)/(1-Formula!$B$16) -> 660.33717 | F6: 48.668066 | G6: 0 | H6: 0 | I6: 0 | J6: 0 | K6: 0
A7: Marcabal | B7: 4061.92 | C7: 45671 | D7: =SUM(Laminado!E7+Molido!D7)/(1-Formula!$B$16) -> 0 | E7: =SUM(Laminado!F7+Molido!E7)/(1-Formula!$B$16) -> 2448.1937 | F7: 345.60453 | G7: 0 | H7: 473.06759 | I7: 0 | J7: 8.1268392 | K7: 0
A8: Julcán | B8: 2588 | C8: 45673 | D8: =SUM(Laminado!E8+Molido!D8)/(1-Formula!$B$16) -> 431.54633 | E8: =SUM(Laminado!F8+Molido!E8)/(1-Formula!$B$16) -> 0 | F8: 262.16581 | G8: 0 | H8: 0 | I8: 0 | J8: 0 | K8: 0
A9: Olmos | B9: 5840 | C9: 45691 | D9: 0 | E9: 0 | F9: 54.116814 | G9: 0 | H9: 0 | I9: 0 | J9: 0 | K9: 0
A10: San Pedro de Lloc | B10: 4691 | C10: 45691 | D10: 0 | E10: 0 | F10: 76.565625 | G10: 0 | H10: 0 | I10: 0 | J10: 0 | K10: 19.264899
A11: Marcabal | B11: 4061.92 | C11: 45700 | D11: =SUM(Laminado!E11+Molido!D11)/(1-Formula!$B$16) -> 0 | E11: =SUM(Laminado!F11+Molido!E11)/(1-Formula!$B$16) -> 2448.1937 | F11: 345.60453 | G11: 0 | H11: 473.06759 | I11: 0 | J11: 8.1268392 | K11: 0
A12: Julcán | B12: 2600 | C12: 45702 | D12: =SUM(Laminado!E12+Molido!D12)/(1-Formula!$B$16) -> 433.54732 | E12: =SUM(Laminado!F12+Molido!E12)/(1-Formula!$B$16) -> 0 | F12: 263.38141 | G12: 0 | H12: 0 | I12: 0 | J12: 0 | K12: 0
A13: Viru | B13: 3108 | C13: 45702 | D13: =SUM(Laminado!E13+Molido!D13)/(1-Formula!$B$16) -> 721.89076 | E13: =SUM(Laminado!F13+Molido!E13)/(1-Formula!$B$16) -> 1443.7815 | F13: 0 | G13: 0 | H13: 0 | I13: 0 | J13: 0 | K13: 0
A14: Olmos | B14: 5611 | C14: 45717 | D14: 0 | E14: 0 | F14: 51.994768 | G14: 0 | H14: 0 | I14: 0 | J14: 0 | K14: 0
A15: Chongoyape | B15: 2626 | C15: 45727 | D15: =SUM(Laminado!E15+Molido!D15)/(1-Formula!$B$16) -> 426.46686 | E15: =SUM(Laminado!F15+Molido!E15)/(1-Formula!$B$16) -> 1409.7148 | F15: 141.02678 | G15: 0 | H15: 0 | I15: 0 | J15: 0 | K15: 0
A16: Marcabal | B16: 4061.92 | C16: 45728 | D16: =SUM(Laminado!E16+Molido!D16)/(1-Formula!$B$16) -> 0 | E16: =SUM(Laminado!F16+Molido!E16)/(1-Formula!$B$16) -> 2448.1937 | F16: 345.60453 | G16: 0 | H16: 473.06759 | I16: 0 | J16: 8.1268392 | K16: 0
A17: Julcán | B17: 2588 | C17: 45733 | D17: =SUM(Laminado!E17+Molido!D17)/(1-Formula!$B$16) -> 431.54633 | E17: =SUM(Laminado!F17+Molido!E17)/(1-Formula!$B$16) -> 0 | F17: 262.16581 | G17: 0 | H17: 0 | I17: 0 | J17: 0 | K17: 0
A18: San Jose | B18: 4570 | C18: 45733 | D18: =SUM(Laminado!E18+Molido!D18)/(1-Formula!$B$16) -> 1164.5868 | E18: =SUM(Laminado!F18+Molido!E18)/(1-Formula!$B$16) -> 1746.8802 | F18: 98.652197 | G18: 0 | H18: 0 | I18: 0 | J18: 0 | K18: 0
A19: San Pedro de Lloc | B19: 4742 | C19: 45733 | D19: =SUM(Laminado!E19+Molido!D19)/(1-Formula!$B$16) -> 762.2556 | E19: =SUM(Laminado!F19+Molido!E19)/(1-Formula!$B$16) -> 2858.0904 | F19: 77.398038 | G19: 0 | H19: 0 | I19: 0 | J19: 0 | K19: 19.474345
A20: Viru | B20: 3006 | C20: 45733 | D20: =SUM(Laminado!E20+Molido!D20)/(1-Formula!$B$16) -> 698.19936 | E20: =SUM(Laminado!F20+Molido!E20)/(1-Formula!$B$16) -> 1396.3987 | F20: 0 | G20: 0 | H20: 0 | I20: 0 | J20: 0 | K20: 0
A21: Pataz - Tayabamba | B21: 9268 | C21: 45739 | D21: =SUM(Laminado!E21+Molido!D21)/(1-Formula!$B$16) -> 2602.8296 | E21: =SUM(Laminado!F21+Molido!E21)/(1-Formula!$B$16) -> 2756.0521 | F21: 765.13627 | G21: 0 | H21: 0 | I21: 1378.026 | J21: 0 | K21: 0
A22: Chiclayo | B22: 30058 | C22: 45751 | D22: 0 | E22: =SUM(Laminado!F22+Molido!E22)/(1-Formula!$B$16) -> 0 | F22: 0 | G22: 8962.4735 | H22: 0 | I22: 0 | J22: 0 | K22: 0
A23: Olmos | B23: 5840 | C23: 45751 | D23: 0 | E23: 0 | F23: 54.116814 | G23: 0 | H23: 0 | I23: 0 | J23: 0 | K23: 0
A24: Marcabal | B24: 4061.92 | C24: 45756 | D24: =SUM(Laminado!E24+Molido!D24)/(1-Formula!$B$16) -> 0 | E24: 0 | F24: 345.60453 | G24: 0 | H24: 473.06759 | I24: 0 | J24: 8.1268392 | K24: 0
A25: Cajamarca | B25: 10671.72 | C25: 45763 | D25: =SUM(Laminado!E25+Molido!D25)/(1-Formula!$B$16) -> 2071.1107 | E25: =SUM(Laminado!F25+Molido!E25)/(1-Formula!$B$16) -> 4142.2214 | F25: 421.40763 | G25: 0 | H25: 0 | I25: 0 | J25: 0 | K25: 0
A26: Cajamarca | B26: 11433.6 | C26: 45763 | D26: =SUM(Laminado!E26+Molido!D26)/(1-Formula!$B$16) -> 2218.9723 | E26: =SUM(Laminado!F26+Molido!E26)/(1-Formula!$B$16) -> 4437.9447 | F26: 451.49294 | G26: 0 | H26: 0 | I26: 0 | J26: 0 | K26: 0
A27: Cajamarca | B27: 23470.72 | C27: 45763 | D27: =SUM(Laminado!E27+Molido!D27)/(1-Formula!$B$16) -> 4555.0726 | E27: =SUM(Laminado!F27+Molido!E27)/(1-Formula!$B$16) -> 9110.1452 | F27: 926.81783 | G27: 0 | H27: 0 | I27: 0 | J27: 0 | K27: 0
A28: Julcán | B28: 2588 | C28: 45763 | D28: =SUM(Laminado!E28+Molido!D28)/(1-Formula!$B$16) -> 431.54633 | E28: =SUM(Laminado!F28+Molido!E28)/(1-Formula!$B$16) -> 0 | F28: 262.16581 | G28: 0 | H28: 0 | I28: 0 | J28: 0 | K28: 0
A29: Viru | B29: 3104 | C29: 45763 | D29: =SUM(Laminado!E29+Molido!D29)/(1-Formula!$B$16) -> 720.96168 | E29: =SUM(Laminado!F29+Molido!E29)/(1-Formula!$B$16) -> 1441.9234 | F29: 0 | G29: 0 | H29: 0 | I29: 0 | J29: 0 | K29: 0
A30: Chongoyape | B30: 1771 | C30: 45764 | D30: =SUM(Laminado!E30+Molido!D30)/(1-Formula!$B$16) -> 287.61341 | E30: =SUM(Laminado!F30+Molido!E30)/(1-Formula!$B$16) -> 950.72539 | F30: 95.109837 | G30: 0 | H30: 0 | I30: 0 | J30: 0 | K30: 0
A31: Olmos | B31: 5611 | C31: 45779 | D31: 0 | E31: 0 | F31: 51.994768 | G31: 0 | H31: 0 | I31: 0 | J31: 0 | K31: 0
A32: Cajamarca | B32: 11448 | C32: 45782 | D32: 0 | E32: 0 | F32: 452.06157 | G32: 0 | H32: 0 | I32: 0 | J32: 0 | K32: 0
A33: Cajamarca | B33: 11829.6 | C33: 45782 | D33: 0 | E33: 0 | F33: 467.13029 | G33: 0 | H33: 0 | I33: 0 | J33: 0 | K33: 0
A34: Marcabal | B34: 4061.92 | C34: 45786 | D34: =SUM(Laminado!E34+Molido!D34)/(1-Formula!$B$16) -> 0 | E34: 0 | F34: 345.60453 | G34: 0 | H34: 473.06759 | I34: 0 | J34: 8.1268392 | K34: 0
A35: Chongoyape | B35: 1771 | C35: 45793 | D35: =SUM(Laminado!E35+Molido!D35)/(1-Formula!$B$16) -> 287.61341 | E35: =SUM(Laminado!F35+Molido!E35)/(1-Formula!$B$16) -> 950.72539 | F35: 95.109837 | G35: 0 | H35: 0 | I35: 0 | J35: 0 | K35: 0
A36: Viru | B36: 3006 | C36: 45793 | D36: =SUM(Laminado!E36+Molido!D36)/(1-Formula!$B$16) -> 698.19936 | E36: =SUM(Laminado!F36+Molido!E36)/(1-Formula!$B$16) -> 1396.3987 | F36: 0 | G36: 0 | H36: 0 | I36: 0 | J36: 0 | K36: 0
A37: Julcán | B37: 2588 | C37: 45796 | D37: =SUM(Laminado!E37+Molido!D37)/(1-Formula!$B$16) -> 431.54633 | E37: =SUM(Laminado!F37+Molido!E37)/(1-Formula!$B$16) -> 0 | F37: 262.16581 | G37: 0 | H37: 0 | I37: 0 | J37: 0 | K37: 0
A38: Cajatambo | B38: 2686 | C38: 45800 | D38: =SUM(Laminado!E38+Molido!D38)/(1-Formula!$B$16) -> 834.05537 | E38: =SUM(Laminado!F38+Molido!E38)/(1-Formula!$B$16) -> 0 | F38: 0 | G38: 0 | H38: 0 | I38: 0 | J38: 0 | K38: 0
A39: Olmos | B39: 5840 | C39: 45810 | D39: 0 | E39: 0 | F39: 54.116814 | G39: 0 | H39: 0 | I39: 0 | J39: 0 | K39: 0
A40: Marcabal | B40: 4061.92 | C40: 45817 | D40: =SUM(Laminado!E40+Molido!D40)/(1-Formula!$B$16) -> 0 | E40: 0 | F40: 345.60453 | G40: 0 | H40: 473.06759 | I40: 0 | J40: 8.1268392 | K40: 0
...

Sheet Limpieza
A1: Municipalidad | B1: Cantidad (Kg) | C1: Fecha | D1: Chancado | E1: Pilado | F1: Despredado
D2: Cebada
A3: {=Mezclado!A2:C74} -> San Jose | B3: 3347 | C3: 45630 | D3: {=Molido!H2:H74/(1-0.003)} -> 0 | E3: {=Tostado!G2:G74/(1-0.28)} -> 0 | F3: {=_xlfn.ANCHORARRAY(E3)/(1-0.005)} -> 0
A4: Pataz - Tayabamba | B4: 9286 | C4: 45642 | D4: 0 | E4: 0 | F4: 0
A5: Viru | B5: 2810 | C5: 45653 | D5: 0 | E5: 0 | F5: 0
A6: Julcán | B6: 2588 | C6: 45656 | D6: 0 | E6: 0 | F6: 0
A7: Olmos | B7: 5252 | C7: 45665 | D7: 0 | E7: 0 | F7: 0
A8: Marcabal | B8: 4061.92 | C8: 45671 | D8: 0 | E8: 0 | F8: 0
A9: Julcán | B9: 2588 | C9: 45673 | D9: 0 | E9: 0 | F9: 0
A10: Olmos | B10: 5840 | C10: 45691 | D10: 0 | E10: 0 | F10: 0
A11: San Pedro de Lloc | B11: 4691 | C11: 45691 | D11: 0 | E11: 0 | F11: 0
A12: Marcabal | B12: 4061.92 | C12: 45700 | D12: 0 | E12: 0 | F12: 0
A13: Julcán | B13: 2600 | C13: 45702 | D13: 0 | E13: 0 | F13: 0
A14: Viru | B14: 3108 | C14: 45702 | D14: 0 | E14: 0 | F14: 0
A15: Olmos | B15: 5611 | C15: 45717 | D15: 0 | E15: 0 | F15: 0
... A75: Olmos | B75: 5840 | C75: 45962 | D75: 0 | E75: 0 | F75: 0
D81: =194*3 -> 582 | E81: =D81/800*60 -> 43.65
D82: =D43-D81 -> 2951.2028 | E82: =D82/800 -> 3.6890035 | F82: =E82-3 -> 0.68900348 | G82: =F82*60 -> 41.340209
D84: =551.2*0.997 -> 549.5464

Sheet Deshidratado
A1: Municipalidad | B1: Cantidad (Kg) | C1: Fecha | D1: Maca Deshidratada | E1: Maca
A2: {=Mezclado!A2:C74} -> San Jose | B2: 3347 | C2: 45630 | D2: {=IF(Molido!G2:G74>300, Molido!G2:G74, 0)} -> 701.52234 | E2: {=IF(Molido!G2:G74>300, 0, Molido!G2:G74/(1-Formula!$B$15))} -> 0
A3: Pataz - Tayabamba | B3: 9286 | C3: 45642 | D3: 0 | E3: 0
A4: Viru | B4: 2810 | C4: 45653 | D4: 0 | E4: 975.87383
A5: Julcán | B5: 2588 | C5: 45656 | D5: 1704.2385 | E5: 0
A6: Olmos | B6: 5252 | C6: 45665 | D6: 0 | E6: 0
A7: Marcabal | B7: 4061.92 | C7: 45671 | D7: 0 | E7: 0
A8: Julcán | B8: 2588 | C8: 45673 | D8: 1704.2385 | E8: 0
A9: Olmos | B9: 5840 | C9: 45691 | D9: 0 | E9: 0
A10: San Pedro de Lloc | B10: 4691 | C10: 45691 | D10: 558.2128 | E10: 0
A11: Marcabal | B11: 4061.92 | C11: 45700 | D11: 0 | E11: 0
A12: Julcán | B12: 2600 | C12: 45702 | D12: 1712.1407 | E12: 0
A13: Viru | B13: 3108 | C13: 45702 | D13: 323.80952 | E13: 0
A14: Olmos | B14: 5611 | C14: 45717 | D14: 0 | E14: 0
... A74: Olmos | B74: 5840 | C74: 45962 | D74: 0 | E74: 0
E78: =E35/40 -> 14.773106
E79: =E78-14 -> 0.77310644
E80: =E79*240 -> 185.54555

Sheet Materia Prima
A1: Municipalidad | B1: Cantidad (Kg) | C1: Fecha | D1: Avena | E1: Quinua Tostada | F1: Quinua Desaponificada | G1: Quinua | H1: Kiwicha Tostada | I1: Kiwicha | J1: Soya | K1: Maca Deshidratada | L1: Maca | M1: Azucar | N1: Cebada Tostada | O1: Cebada | P1: Maiz Chufla | Q1: Leche Polvo | R1: Cañihua | S1: Aceite Girasol | T1: Pallar seco | U1: Almidon maca | V1: Linaza | W1: Ajonjoli | X1: Proteina aislada soya | Y1: Frejol tarhui | Z1: Garbanzo | AA1: Fosfato Tricálcio | AB1: Mix vitaminico
A2: {=General!A2:A74} -> San Jose | B2: {=General!F2:G74} -> 3347 | C2: 45630 | D2: {=Laminado!D2:D74} -> 379.05669 | E2: 0 | F2: {=Tostado!D2:D51} -> 852.92605 | G2: 0 | H2: 0 | I2: {=Tostado!E2:F74} -> 1279.3891 | J2: 72.251401 | K2: {=_xlfn.ANCHORARRAY(Deshidratado!D2)} -> 701.52234 | L2: {=_xlfn.ANCHORARRAY(Deshidratado!E2)} -> 0 | M2: {=Mezclado!J2:J74} -> 0 | N2: 0 | O2: {=Limpieza!F3:F22} -> 0 | P2: {=Molido!I2:I74} -> 0 | Q2: {=Mezclado!M2:M74} -> 0 | R2: {=Mezclado!N2:O74} -> 0 | S2: 0 | T2: {=Tostado!J2:J74} -> 0 | U2: {=Mezclado!Q2:X74} -> 0 | V2: 0 | W2: 0 | X2: 0 | Y2: 0 | Z2: 0 | AA2: 145.74024 | AB2: 8.3758759
A3: Pataz - Tayabamba | B3: 9286 | C3: 45642 | D3: 804.59778 | E3: 0 | F3: 2607.8848 | G3: 0 | H3: 0 | I3: 2761.4048 | J3: 766.62229 | K3: 0 | L3: 0 | M3: 0 | N3: 0 | O3: 0 | P3: 0 | Q3: 0 | R3: 1312.4957 | S3: 0 | T3: 0 | U3: 1020.6234 | V3: 0 | W3: 0 | X3: 0 | Y3: 0 | Z3: 0 | AA3: 309.53333 | AB3: 17.661061
A4: Viru | B4: 2810 | C4: 45653 | D4: 367.33022 | E4: 0 | F4: 652.67472 | G4: 0 | H4: 0 | I4: 1305.3494 | J4: 0 | K4: 0 | L4: 975.87383 | M4: 0 | N4: 0 | O4: 0 | P4: 0 | Q4: 0 | R4: 0 | S4: 51.755756 | T4: 0 | U4: 0 | V4: 28.690691 | W4: 28.690691 | X4: 28.690691 | Y4: 0 | Z4: 0 | AA4: 121.51351 | AB4: 6.7507508
A5: Julcán | B5: 2588 | C5: 45656 | D5: 142.39154 | E5: 0 | F5: 431.54633 | G5: 0 | H5: 0 | I5: 0 | J5: 262.16581 | K5: 1704.2385 | L5: 0 | M5: 0 | N5: 0 | O5: 0 | P5: 0 | Q5: 0 | R5: 0 | S5: 0 | T5: 0 | U5: 0 | V5: 0 | W5: 0 | X5: 0 | Y5: 0 | Z5: 0 | AA5: 105.95516 | AB5: 5.9583584
A6: Olmos | B6: 5252 | C6: 45665 | D6: 1889.3433 | E6: 0 | F6: 1623.2378 | G6: 0 | H6: 0 | I6: 660.33717 | J6: 48.668066 | K6: 0 | L6: 0 | M6: 0 | N6: 0 | O6: 0 | P6: 0 | Q6: 923.17437 | R6: 0 | S6: 0 | T6: 0 | U6: 0 | V6: 0 | W6: 0 | X6: 0 | Y6: 0 | Z6: 0 | AA6: 195.56997 | AB6: 11.04024
A7: Marcabal | B7: 4061.92 | C7: 45671 | D7: 468.58755 | E7: 0 | F7: 0 | G7: 0 | H7: 0 | I7: 2448.1937 | J7: 345.60453 | K7: 0 | L7: 0 | M7: 260.6297 | N7: 0 | O7: 0 | P7: 458.87556 | Q7: 0 | R7: 0 | S7: 0 | T7: 8.1268392 | U7: 7.7253734 | V7: 0 | W7: 0 | X7: 0 | Y7: 0 | Z7: 0 | AA7: 167.51862 | AB7: 9.3517678
A8: Julcán | B8: 2588 | C8: 45673 | D8: 142.39154 | E8: 0 | F8: 431.54633 | G8: 0 | H8: 0 | I8: 0 | J8: 262.16581 | K8: 1704.2385 | L8: 0 | M8: 0 | N8: 0 | O8: 0 | P8: 0 | Q8: 0 | R8: 0 | S8: 0 | T8: 0 | U8: 0 | V8: 0 | W8: 0 | X8: 0 | Y8: 0 | Z8: 0 | AA8: 105.95516 | AB8: 5.9583584
A9: Olmos | B9: 5840 | C9: 45691 | D9: 2100.8692 | E9: {=Laminado!E9:E10} -> 1750.822 | F9: 0 | G9: 0 | H9: =Molido!E9 -> 712.23877 | I9: 0 | J9: 54.116814 | K9: 0 | L9: 0 | M9: 0 | N9: 0 | O9: 0 | P9: 0 | Q9: 1026.5305 | R9: 0 | S9: 0 | T9: 0 | U9: 0 | V9: 0 | W9: 0 | X9: 0 | Y9: 0 | Z9: 0 | AA9: 217.46547 | AB9: 12.276276
A10: San Pedro de Lloc | B10: 4691 | C10: 45691 | D10: 300.01586 | E10: 731.43585 | F10: 0 | G10: 0 | H10: =Laminado!F10 -> 2742.5312 | I10: 0 | J10: 76.565625 | K10: 558.2128 | L10: 0 | M10: 0 | N10: 0 | O10: 0 | P10: 0 | Q10: 0 | R10: 0 | S10: 0 | T10: 0 | U10: 0 | V10: 0 | W10: 0 | X10: 0 | Y10: 91.096496 | Z10: 18.313213 | AA10: 192.99309 | AB10: 10.8001
A11: Marcabal | B11: 4061.92 | C11: 45700 | D11: 468.58755 | E11: 0 | F11: 0 | G11: 0 | H11: 0 | I11: 2448.1937 | J11: 345.60453 | K11: 0 | L11: 0 | M11: 260.6297 | N11: 0 | O11: 0 | P11: 458.87556 | Q11: 0 | R11: 0 | S11: 0 | T11: 8.1268392 | U11: 7.7253734 | V11: 0 | W11: 0 | X11: 0 | Y11: 0 | Z11: 0 | AA11: 167.51862 | AB11: 9.3517678
A12: Julcán | B12: 2600 | C12: 45702 | D12: 143.05178 | E12: 0 | F12: 433.54732 | G12: 0 | H12: 0 | I12: 0 | J12: 263.38141 | K12: 1712.1407 | L12: 0 | M12: 0 | N12: 0 | O12: 0 | P12: 0 | Q12: 0 | R12: 0 | S12: 0 | T12: 0 | U12: 0 | V12: 0 | W12: 0 | X12: 0 | Y12: 0 | Z12: 0 | AA12: 106.44645 | AB12: 5.985986
A13: Viru | B13: 3108 | C13: 45702 | D13: 406.28552 | E13: 0 | F13: 721.89076 | G13: 0 | H13: 0 | I13: 1443.7815 | J13: 0 | K13: 323.80952 | L13: 0 | M13: 0 | N13: 0 | O13: 0 | P13: 0 | Q13: 0 | R13: 0 | S13: 57.244444 | T13: 0 | U13: 0 | V13: 31.733333 | W13: 31.733333 | X13: 31.733333 | Y13: 0 | Z13: 0 | AA13: 134.4 | AB13: 7.4666667
A14: Olmos | B14: 5611 | C14: 45717 | D14: 2018.4892 | E14: =Laminado!E14 -> 1682.1682 | F14: 0 | G14: 0 | H14: =Molido!E14 -> 684.31023 | I14: 0 | J14: 51.994768 | K14: 0 | L14: 0 | M14: 0 | N14: 0 | O14: 0 | P14: 0 | Q14: 986.27788 | R14: 0 | S14: 0 | T14: 0 | U14: 0 | V14: 0 | W14: 0 | X14: 0 | Y14: 0 | Z14: 0 | AA14: 208.93814 | AB14: 11.794895
