Workbook

Sheet General
A1: Municipalidad | B1: F.P. | C1: F.V. | D1: N° Lote | E1: Bolsa (g) | F1: Cantidad (Kg) | G1: Fecha | H1: Fecha Env. | I1: Marca | J1: Producto
A2: 1 | F2: 20 | G2: 45902 | I2: FACLAC | J2: MEZCLA DE HARINAS DE SIETE SEMILLAS (TRIGO, HABAS, ARVEJAS, KIWICHA, CAÑIHUA, CEBADA, QUINUA) CON HARINA DE PLATANO ENRIQUECIDA CON VITAMINAS Y MINERALES
A3: 2 | F3: 20 | G3: 45903 | I3: FACLAC | J3: MEZCLA DE HOJUELAS DE QUINUA, KIWICHA Y AVENA CON HARINAS DE MACA, SOYA Y AJONJOLI ENRIQUECIDOS CON VITAMINAS Y MINERALES
A4: 3 | F4: 20 | G4: 45909 | I4: FACLAC | J4: MEZCLA DE HOJUELAS PRECOCIDAS DE AVENA, QUINUA Y KIWICHA CON HARINAS DE MACA Y LINAZA ENRIQUECIDA CON VITAMINAS Y MINERALES
A5: 4 | F5: 20 | G5: 45925 | I5: FACLAC | J5: MEZCLA DE HOJUELAS PRECOCIDAS DE AVENA, QUINUA Y KIWICHA CON HARINAS DE MACA Y LENTEJA, PROTEINA AISLADO DE SOYA, ACEITE VEGETAL SACHA INCHI ENRIQUECIDA CON VITAMINAS Y MINERALES
A6: 5 | F6: 20 | G6: 45926 | I6: FACLAC | J6: MEZCLA DE HOJUELAS DE AVENA CON HARINA DE KIWICHA Y HARINA DE MACA ENRIQUECIDA CON VITAMINAS Y MINERALES
A7: 6 | F7: 20 | G7: 45926 | I7: FACLAC | J7: MEZCLA DE HOJUELAS PRECOCIDAS DE AVENA Y QUINUA CON HARINAS DE KIWICHA, MACA Y LUCUMA ENRIQUECIDA CON VITAMINAS Y MINERALES
A8: 7 | F8: 20 | G8: 45938 | I8: FACLAC | J8: MEZCLA PRECOCIDA DE HOJUELAS DE KIWICHA, QUINUA, AVENA Y CAÑIHUA CON HARINAS DE CEBADA, TRIGO Y MACA FORTIFICADA CON VITAMINAS Y MINERALES
A9: 8 | F9: 20 | G9: 45938 | I9: FACLAC | J9: TRIGO MOLIDO TOSTADO
A10: 9 | F10: 20 | G10: 45938 | I10: - | J10: MEZCLA DE HARINA DE TRIGO Y HARINA DE CAÑIHUA FORTIFICADA CON HIERRO
A11: 10 | F11: 20 | G11: 45956 | I11: FACLAC | J11: MEZCLA DE HOJUELAS PRECOCIDAS DE AVENA Y QUINUA CON HARINAS DE CEBADA TOSTADA MOLIDA (CHAQUEPA) Y MACA ENRIQUECIDA CON VITAMINAS Y MINERALES.
A12: 11 | F12: 20 | G12: 45987 | I12: FACLAC | J12: MEZCLA PRECOCIDA DE HOJUELAS DE AVENA, CAÑIHUA, QUINUA, TRIGO CON MAIZENA, AJONJOLI Y MACA FORTIFICADA CON VITAMINAS Y MINERALES
A13: 12 | F13: 20 | G13: 46019 | I13: FACLAC | J13: MEZCLA DE HOJUELAS DE AVENA CON HARINAS DE CHUFLA, SOYA INTEGRAL TOSTADA Y PLÁTANO FORTIFICADA CON VITAMINAS Y MINERALES

Sheet Mezclado
A1: Municipalidad | B1: Cantidad (Kg) | C1: Fecha | D1: Mezclado | E1: {=Formula!B1:Z1} -> Avena | F1: Quinua | G1: Kiwicha | H1: Maca | I1: Soya | J1: Trigo | K1: Cebada | L1: Cañihua | M1: Habas | N1: Arveja | O1: Harina de plátano | P1: Harina de lucuma | Q1: Ajonjoli | R1: Linaza | S1: Aceite Soya | T1: Aceite Girasol | U1: Lenteja | V1: Arroz | W1: Maizena | X1: Almidon Maca | Y1: Maiz | Z1: Sulfato ferroso | AA1: Proteina soya | AB1: Fosfato Tricálcio | AC1: Mix vitaminico
A2: {=General!A2:A13} -> 1 | B2: {=General!F2:G13} -> 20 | C2: 45902 | D2: =B2*1/(1-Formula!$B$21) -> 20.02002 | E2: {=_xlfn._xlws.FILTER(Formula!$B$2:$Z$13,Formula!$A$2:$A$13=A2,0)*D2} -> 0 | F2: 1.1851852 | G2: 0.23623624 | H2: 0 | I2: 0 | J2: 11.683684 | K2: 0.54454454 | L2: 0.71071071 | M2: 1.1851852 | N2: 1.043043 | O2: 2.3703704 | P2: 0 | Q2: 0 | R2: 0 | S2: 0 | T2: 0 | U2: 0 | V2: 0 | W2: 0 | X2: 0 | Y2: 0 | Z2: 0 | AA2: 0 | AB2: 1.005005 | AC2: 0.056056056
A3: 2 | B3: 20 | C3: 45903 | D3: =B3*1/(1-Formula!$B$21) -> 20.02002 | E3: {=_xlfn._xlws.FILTER(Formula!$B$2:$Z$13,Formula!$A$2:$A$13=A3,0)*D3} -> 3.6596597 | F3: 3.6596597 | G3: 4.0660661 | H3: 6.0980981 | I3: 0.61061061 | J3: 0 | K3: 0 | L3: 0 | M3: 0 | N3: 0 | O3: 0 | P3: 0 | Q3: 1.015015 | R3: 0 | S3: 0 | T3: 0 | U3: 0 | V3: 0 | W3: 0 | X3: 0 | Y3: 0 | Z3: 0 | AA3: 0 | AB3: 0.86286286 | AC3: 0.048048048
A4: 3 | B4: 20 | C4: 45909 | D4: =B4*1/(1-Formula!$B$21) -> 20.02002 | E4: {=_xlfn._xlws.FILTER(Formula!$B$2:$Z$13,Formula!$A$2:$A$13=A4,0)*D4} -> 13.246801 | F4: 2.0835315 | G4: 1.8953865 | H4: 0.75954827 | I4: 0 | J4: 0 | K4: 0 | L4: 0 | M4: 0 | N4: 0 | O4: 0 | P4: 0 | Q4: 0 | R4: 0.47384663 | S4: 0 | T4: 0 | U4: 0 | V4: 0 | W4: 0 | X4: 0 | Y4: 0 | Z4: 0 | AA4: 0 | AB4: 1.4772865 | AC4: 0.083619993
A5: 4 | B5: 20 | C5: 45925 | D5: =B5*1/(1-Formula!$B$21) -> 20.02002 | E5: {=_xlfn._xlws.FILTER(Formula!$B$2:$Z$13,Formula!$A$2:$A$13=A5,0)*D5} -> 2.8488488 | F5: 2.5645646 | G5: 0 | H5: 0 | I5: 0 | J5: 5.1271271 | K5: 0 | L5: 0 | M5: 0 | N5: 0 | O5: 0 | P5: 0 | Q5: 0 | R5: 0 | S5: 0 | T5: 1.4334334 | U5: 2.5645646 | V5: 4.2742743 | W5: 0 | X5: 0 | Y5: 0 | Z5: 0 | AA5: 0.57057057 | AB5: 0.6046046 | AC5: 0.032032032
A6: 5 | B6: 20 | C6: 45926 | D6: =B6*1/(1-Formula!$B$21) -> 20.02002 | E6: {=_xlfn._xlws.FILTER(Formula!$B$2:$Z$13,Formula!$A$2:$A$13=A6,0)*D6} -> 9.4814815 | F6: 0 | G6: 4.7387387 | H6: 4.7387387 | I6: 0 | J6: 0 | K6: 0 | L6: 0 | M6: 0 | N6: 0 | O6: 0 | P6: 0 | Q6: 0 | R6: 0 | S6: 0 | T6: 0 | U6: 0 | V6: 0 | W6: 0 | X6: 0 | Y6: 0 | Z6: 0 | AA6: 0 | AB6: 1.005005 | AC6: 0.056056056
A7: 6 | B7: 20 | C7: 45926 | D7: =B7*1/(1-Formula!$B$21) -> 20.02002 | E7: {=_xlfn._xlws.FILTER(Formula!$B$2:$Z$13,Formula!$A$2:$A$13=A7,0)*D7} -> 8.0540541 | F7: 5.0850851 | G7: 2.5425425 | H7: 1.2712713 | I7: 0 | J7: 0 | K7: 0 | L7: 0 | M7: 0 | N7: 0 | O7: 0 | P7: 2.1181181 | Q7: 0 | R7: 0 | S7: 0 | T7: 0 | U7: 0 | V7: 0 | W7: 0 | X7: 0 | Y7: 0 | Z7: 0 | AA7: 0 | AB7: 0.8968969 | AC7: 0.052052052
A8: 7 | B8: 20 | C8: 45938 | D8: =B8*1/(1-Formula!$B$21) -> 20.02002 | E8: {=_xlfn._xlws.FILTER(Formula!$B$2:$Z$13,Formula!$A$2:$A$13=A8,0)*D8} -> 2.7287287 | F8: 3.9159159 | G8: 4.7867868 | H8: 1.7397397 | I8: 0 | J8: 2.1761762 | K8: 2.6106106 | L8: 1.0870871 | M8: 0 | N8: 0 | O8: 0 | P8: 0 | Q8: 0 | R8: 0 | S8: 0 | T8: 0 | U8: 0 | V8: 0 | W8: 0 | X8: 0 | Y8: 0 | Z8: 0 | AA8: 0 | AB8: 0.92292292 | AC8: 0.052052052
A9: 8 | B9: 20 | C9: 45938 | D9: =B9*1/(1-Formula!$B$21) -> 20.02002 | E9: {=_xlfn._xlws.FILTER(Formula!$B$2:$Z$13,Formula!$A$2:$A$13=A9,0)*D9} -> 0 | F9: 0 | G9: 0 | H9: 0 | I9: 0 | J9: 20.02002 | K9: 0 | L9: 0 | M9: 0 | N9: 0 | O9: 0 | P9: 0 | Q9: 0 | R9: 0 | S9: 0 | T9: 0 | U9: 0 | V9: 0 | W9: 0 | X9: 0 | Y9: 0 | Z9: 0 | AA9: 0 | AB9: 0 | AC9: 0
A10: 9 | B10: 20 | C10: 45938 | D10: =B10*1/(1-Formula!$B$21) -> 20.02002 | E10: {=_xlfn._xlws.FILTER(Formula!$B$2:$Z$13,Formula!$A$2:$A$13=A10,0)*D10} -> 0 | F10: 0 | G10: 0 | H10: 0 | I10: 0 | J10: 17.385385 | K10: 0 | L10: 2.6346346 | M10: 0 | N10: 0 | O10: 0 | P10: 0 | Q10: 0 | R10: 0 | S10: 0 | T10: 0 | U10: 0 | V10: 0 | W10: 0 | X10: 0 | Y10: 0 | Z10: 0.036736737 | AA10: 0 | AB10: 0 | AC10: 0
A11: 10 | B11: 20 | C11: 45956 | D11: =B11*1/(1-Formula!$B$21) -> 20.02002 | E11: {=_xlfn._xlws.FILTER(Formula!$B$2:$Z$13,Formula!$A$2:$A$13=A11,0)*D11} -> 0.77977978 | F11: 0.77977978 | G11: 0 | H11: 1.6956957 | I11: 0 | J11: 0 | K11: 15.5996 | L11: 0 | M11: 0 | N11: 0 | O11: 0 | P11: 0 | Q11: 0 | R11: 0 | S11: 0 | T11: 0 | U11: 0 | V11: 0 | W11: 0 | X11: 0 | Y11: 0 | Z11: 0 | AA11: 0 | AB11: 1.1031031 | AC11: 0.062062062
A12: 11 | B12: 20 | C12: 45987 | D12: =B12*1/(1-Formula!$B$21) -> 20.02002 | E12: {=_xlfn._xlws.FILTER(Formula!$B$2:$Z$13,Formula!$A$2:$A$13=A12,0)*D12} -> 5.3393393 | F12: 2.2242242 | G12: 0 | H12: 0 | I12: 0 | J12: 4.4484484 | K12: 0 | L12: 1.7797798 | M12: 0 | N12: 0 | O12: 0 | P12: 0 | Q12: 0.78278278 | R12: 0 | S12: 0 | T12: 0 | U12: 0 | V12: 0 | W12: 2.2242242 | X12: 2.2242242 | Y12: 0 | Z12: 0 | AA12: 0 | AB12: 0.94294294 | AC12: 0.054054054
A13: 12 | B13: 20 | C13: 46019 | D13: =B13*1/(1-Formula!$B$21) -> 20.02002 | E13: {=_xlfn._xlws.FILTER(Formula!$B$2:$Z$13,Formula!$A$2:$A$13=A13,0)*D13} -> 2.2882883 | F13: 0 | G13: 0 | H13: 0 | I13: 1.6336336 | J13: 0 | K13: 0 | L13: 0 | M13: 0 | N13: 0 | O13: 4.9029029 | P13: 0 | Q13: 0 | R13: 0 | S13: 0.002002002 | T13: 0 | U13: 0 | V13: 0 | W13: 0 | X13: 0 | Y13: 10.46046 | Z13: 0 | AA13: 0 | AB13: 0.69269269 | AC13: 0.04004004

Sheet Laminado
A1: Municipalidad | B1: Cantidad (Kg) | C1: Fecha | D1: {=_xlfn._xlws.FILTER(Procesos!B1:V1, MMULT(TRANSPOSE(ROW(Procesos!B2:B25)^0), --(Procesos!B2:V25="Laminado")) > 0)} -> Avena | E1: Quinua | F1: Kiwicha | G1: Trigo | H1: Cañihua
A2: {=Mezclado!A2:C13} -> 1 | B2: 20 | C2: 45902 | D2: {=IF(ISNUMBER(MATCH($A2, _xlfn._xlws.FILTER(Procesos!$A$2:$A$25, Procesos!B$2:B$25="Laminado"), 0)), INDEX(Formula!$B$2:$Z$14, MATCH(VALUE($A2), VALUE(Formula!$A$2:$A$14), 0), MATCH(D$1, Formula!$B$1:$Z$1, 0)) * Mezclado!$D2/(1-Formula!$B$20), 0)} -> 0 | E2: {=IF(ISNUMBER(MATCH($A2, _xlfn._xlws.FILTER(Procesos!$A$2:$A$25, Procesos!C$2:C$25="Laminado"), 0)), INDEX(Formula!$B$2:$Z$14, MATCH(VALUE($A2), VALUE(Formula!$A$2:$A$14), 0), MATCH(E$1, Formula!$B$1:$Z$1, 0)) * Mezclado!$D2/(1-Formula!$B$20), 0)} -> 0 | F2: {=IF(ISNUMBER(MATCH($A2, _xlfn._xlws.FILTER(Procesos!$A$2:$A$25, Procesos!D$2:D$25="Laminado"), 0)), INDEX(Formula!$B$2:$Z$14, MATCH(VALUE($A2), VALUE(Formula!$A$2:$A$14), 0), MATCH(F$1, Formula!$B$1:$Z$1, 0)) * Mezclado!$D2/(1-Formula!$B$20), 0)} -> 0 | G2: {=IF(ISNUMBER(MATCH($A2, _xlfn._xlws.FILTER(Procesos!$A$2:$A$25, Procesos!G$2:G$25="Laminado"), 0)), INDEX(Formula!$B$2:$Z$14, MATCH(VALUE($A2), VALUE(Formula!$A$2:$A$14), 0), MATCH(G$1, Formula!$B$1:$Z$1, 0)) * Mezclado!$D2/(1-Formula!$B$20), 0)} -> 0 | H2: {=IF(ISNUMBER(MATCH($A2, _xlfn._xlws.FILTER(Procesos!$A$2:$A$25, Procesos!I$2:I$25="Laminado"), 0)), INDEX(Formula!$B$2:$Z$14, MATCH(VALUE($A2), VALUE(Formula!$A$2:$A$14), 0), MATCH(H$1, Formula!$B$1:$Z$1, 0)) * Mezclado!$D2/(1-Formula!$B$20), 0)} -> 0
A3: 2 | B3: 20 | C3: 45903 | D3: {=IF(ISNUMBER(MATCH($A3, _xlfn._xlws.FILTER(Procesos!$A$2:$A$25, Procesos!B$2:B$25="Laminado"), 0)), INDEX(Formula!$B$2:$Z$14, MATCH(VALUE($A3), VALUE(Formula!$A$2:$A$14), 0), MATCH(D$1, Formula!$B$1:$Z$1, 0)) * Mezclado!$D3/(1-Formula!$B$20), 0)} -> 3.6706717 | E3: {=IF(ISNUMBER(MATCH($A3, _xlfn._xlws.FILTER(Procesos!$A$2:$A$25, Procesos!C$2:C$25="Laminado"), 0)), INDEX(Formula!$B$2:$Z$14, MATCH(VALUE($A3), VALUE(Formula!$A$2:$A$14), 0), MATCH(E$1, Formula!$B$1:$Z$1, 0)) * Mezclado!$D3/(1-Formula!$B$20), 0)} -> 3.6706717 | F3: {=IF(ISNUMBER(MATCH($A3, _xlfn._xlws.FILTER(Procesos!$A$2:$A$25, Procesos!D$2:D$25="Laminado"), 0)), INDEX(Formula!$B$2:$Z$14, MATCH(VALUE($A3), VALUE(Formula!$A$2:$A$14), 0), MATCH(F$1, Formula!$B$1:$Z$1, 0)) * Mezclado!$D3/(1-Formula!$B$20), 0)} -> 4.078301 | G3: {=IF(ISNUMBER(MATCH($A3, _xlfn._xlws.FILTER(Procesos!$A$2:$A$25, Procesos!G$2:G$25="Laminado"), 0)), INDEX(Formula!$B$2:$Z$14, MATCH(VALUE($A3), VALUE(Formula!$A$2:$A$14), 0), MATCH(G$1, Formula!$B$1:$Z$1, 0)) * Mezclado!$D3/(1-Formula!$B$20), 0)} -> 0 | H3: {=IF(ISNUMBER(MATCH($A3, _xlfn._xlws.FILTER(Procesos!$A$2:$A$25, Procesos!I$2:I$25="Laminado"), 0)), INDEX(Formula!$B$2:$Z$14, MATCH(VALUE($A3), VALUE(Formula!$A$2:$A$14), 0), MATCH(H$1, Formula!$B$1:$Z$1, 0)) * Mezclado!$D3/(1-Formula!$B$20), 0)} -> 0
A4: 3 | B4: 20 | C4: 45909 | D4: {=IF(ISNUMBER(MATCH($A4, _xlfn._xlws.FILTER(Procesos!$A$2:$A$25, Procesos!B$2:B$25="Laminado"), 0)), INDEX(Formula!$B$2:$Z$14, MATCH(VALUE($A4), VALUE(Formula!$A$2:$A$14), 0), MATCH(D$1, Formula!$B$1:$Z$1, 0)) * Mezclado!$D4/(1-Formula!$B$20), 0)} -> 13.286661 | E4: {=IF(ISNUMBER(MATCH($A4, _xlfn._xlws.FILTER(Procesos!$A$2:$A$25, Procesos!C$2:C$25="Laminado"), 0)), INDEX(Formula!$B$2:$Z$14, MATCH(VALUE($A4), VALUE(Formula!$A$2:$A$14), 0), MATCH(E$1, Formula!$B$1:$Z$1, 0)) * Mezclado!$D4/(1-Formula!$B$20), 0)} -> 2.0898009 | F4: {=IF(ISNUMBER(MATCH($A4, _xlfn._xlws.FILTER(Procesos!$A$2:$A$25, Procesos!D$2:D$25="Laminado"), 0)), INDEX(Formula!$B$2:$Z$14, MATCH(VALUE($A4), VALUE(Formula!$A$2:$A$14), 0), MATCH(F$1, Formula!$B$1:$Z$1, 0)) * Mezclado!$D4/(1-Formula!$B$20), 0)} -> 1.9010898 | G4: {=IF(ISNUMBER(MATCH($A4, _xlfn._xlws.FILTER(Procesos!$A$2:$A$25, Procesos!G$2:G$25="Laminado"), 0)), INDEX(Formula!$B$2:$Z$14, MATCH(VALUE($A4), VALUE(Formula!$A$2:$A$14), 0), MATCH(G$1, Formula!$B$1:$Z$1, 0)) * Mezclado!$D4/(1-Formula!$B$20), 0)} -> 0 | H4: {=IF(ISNUMBER(MATCH($A4, _xlfn._xlws.FILTER(Procesos!$A$2:$A$25, Procesos!I$2:I$25="Laminado"), 0)), INDEX(Formula!$B$2:$Z$14, MATCH(VALUE($A4), VALUE(Formula!$A$2:$A$14), 0), MATCH(H$1, Formula!$B$1:$Z$1, 0)) * Mezclado!$D4/(1-Formula!$B$20), 0)} -> 0
A5: 4 | B5: 20 | C5: 45925 | D5: {=IF(ISNUMBER(MATCH($A5, _xlfn._xlws.FILTER(Procesos!$A$2:$A$25, Procesos!B$2:B$25="Laminado"), 0)), INDEX(Formula!$B$2:$Z$14, MATCH(VALUE($A5), VALUE(Formula!$A$2:$A$14), 0), MATCH(D$1, Formula!$B$1:$Z$1, 0)) * Mezclado!$D5/(1-Formula!$B$20), 0)} -> 2.8574211 | E5: {=IF(ISNUMBER(MATCH($A5, _xlfn._xlws.FILTER(Procesos!$A$2:$A$25, Procesos!C$2:C$25="Laminado"), 0)), INDEX(Formula!$B$2:$Z$14, MATCH(VALUE($A5), VALUE(Formula!$A$2:$A$14), 0), MATCH(E$1, Formula!$B$1:$Z$1, 0)) * Mezclado!$D5/(1-Formula!$B$20), 0)} -> 2.5722814 | F5: {=IF(ISNUMBER(MATCH($A5, _xlfn._xlws.FILTER(Procesos!$A$2:$A$25, Procesos!D$2:D$25="Laminado"), 0)), INDEX(Formula!$B$2:$Z$14, MATCH(VALUE($A5), VALUE(Formula!$A$2:$A$14), 0), MATCH(F$1, Formula!$B$1:$Z$1, 0)) * Mezclado!$D5/(1-Formula!$B$20), 0)} -> 0 | G5: {=IF(ISNUMBER(MATCH($A5, _xlfn._xlws.FILTER(Procesos!$A$2:$A$25, Procesos!G$2:G$25="Laminado"), 0)), INDEX(Formula!$B$2:$Z$14, MATCH(VALUE($A5), VALUE(Formula!$A$2:$A$14), 0), MATCH(G$1, Formula!$B$1:$Z$1, 0)) * Mezclado!$D5/(1-Formula!$B$20), 0)} -> 0 | H5: {=IF(ISNUMBER(MATCH($A5, _xlfn._xlws.FILTER(Procesos!$A$2:$A$25, Procesos!I$2:I$25="Laminado"), 0)), INDEX(Formula!$B$2:$Z$14, MATCH(VALUE($A5), VALUE(Formula!$A$2:$A$14), 0), MATCH(H$1, Formula!$B$1:$Z$1, 0)) * Mezclado!$D5/(1-Formula!$B$20), 0)} -> 0
A6: 5 | B6: 20 | C6: 45926 | D6: {=IF(ISNUMBER(MATCH($A6, _xlfn._xlws.FILTER(Procesos!$A$2:$A$25, Procesos!B$2:B$25="Laminado"), 0)), INDEX(Formula!$B$2:$Z$14, MATCH(VALUE($A6), VALUE(Formula!$A$2:$A$14), 0), MATCH(D$1, Formula!$B$1:$Z$1, 0)) * Mezclado!$D6/(1-Formula!$B$20), 0)} -> 9.5100115 | E6: {=IF(ISNUMBER(MATCH($A6, _xlfn._xlws.FILTER(Procesos!$A$2:$A$25, Procesos!C$2:C$25="Laminado"), 0)), INDEX(Formula!$B$2:$Z$14, MATCH(VALUE($A6), VALUE(Formula!$A$2:$A$14), 0), MATCH(E$1, Formula!$B$1:$Z$1, 0)) * Mezclado!$D6/(1-Formula!$B$20), 0)} -> 0 | F6: {=IF(ISNUMBER(MATCH($A6, _xlfn._xlws.FILTER(Procesos!$A$2:$A$25, Procesos!D$2:D$25="Laminado"), 0)), INDEX(Formula!$B$2:$Z$14, MATCH(VALUE($A6), VALUE(Formula!$A$2:$A$14), 0), MATCH(F$1, Formula!$B$1:$Z$1, 0)) * Mezclado!$D6/(1-Formula!$B$20), 0)} -> 0 | G6: {=IF(ISNUMBER(MATCH($A6, _xlfn._xlws.FILTER(Procesos!$A$2:$A$25, Procesos!G$2:G$25="Laminado"), 0)), INDEX(Formula!$B$2:$Z$14, MATCH(VALUE($A6), VALUE(Formula!$A$2:$A$14), 0), MATCH(G$1, Formula!$B$1:$Z$1, 0)) * Mezclado!$D6/(1-Formula!$B$20), 0)} -> 0 | H6: {=IF(ISNUMBER(MATCH($A6, _xlfn._xlws.FILTER(Procesos!$A$2:$A$25, Procesos!I$2:I$25="Laminado"), 0)), INDEX(Formula!$B$2:$Z$14, MATCH(VALUE($A6), VALUE(Formula!$A$2:$A$14), 0), MATCH(H$1, Formula!$B$1:$Z$1, 0)) * Mezclado!$D6/(1-Formula!$B$20), 0)} -> 0
A7: 6 | B7: 20 | C7: 45926 | D7: {=IF(ISNUMBER(MATCH($A7, _xlfn._xlws.FILTER(Procesos!$A$2:$A$25, Procesos!B$2:B$25="Laminado"), 0)), INDEX(Formula!$B$2:$Z$14, MATCH(VALUE($A7), VALUE(Formula!$A$2:$A$14), 0), MATCH(D$1, Formula!$B$1:$Z$1, 0)) * Mezclado!$D7/(1-Formula!$B$20), 0)} -> 8.0782889 | E7: {=IF(ISNUMBER(MATCH($A7, _xlfn._xlws.FILTER(Procesos!$A$2:$A$25, Procesos!C$2:C$25="Laminado"), 0)), INDEX(Formula!$B$2:$Z$14, MATCH(VALUE($A7), VALUE(Formula!$A$2:$A$14), 0), MATCH(E$1, Formula!$B$1:$Z$1, 0)) * Mezclado!$D7/(1-Formula!$B$20), 0)} -> 5.1003862 | F7: {=IF(ISNUMBER(MATCH($A7, _xlfn._xlws.FILTER(Procesos!$A$2:$A$25, Procesos!D$2:D$25="Laminado"), 0)), INDEX(Formula!$B$2:$Z$14, MATCH(VALUE($A7), VALUE(Formula!$A$2:$A$14), 0), MATCH(F$1, Formula!$B$1:$Z$1, 0)) * Mezclado!$D7/(1-Formula!$B$20), 0)} -> 0 | G7: {=IF(ISNUMBER(MATCH($A7, _xlfn._xlws.FILTER(Procesos!$A$2:$A$25, Procesos!G$2:G$25="Laminado"), 0)), INDEX(Formula!$B$2:$Z$14, MATCH(VALUE($A7), VALUE(Formula!$A$2:$A$14), 0), MATCH(G$1, Formula!$B$1:$Z$1, 0)) * Mezclado!$D7/(1-Formula!$B$20), 0)} -> 0 | H7: {=IF(ISNUMBER(MATCH($A7, _xlfn._xlws.FILTER(Procesos!$A$2:$A$25, Procesos!I$2:I$25="Laminado"), 0)), INDEX(Formula!$B$2:$Z$14, MATCH(VALUE($A7), VALUE(Formula!$A$2:$A$14), 0), MATCH(H$1, Formula!$B$1:$Z$1, 0)) * Mezclado!$D7/(1-Formula!$B$20), 0)} -> 0
A8: 7 | B8: 20 | C8: 45938 | D8: {=IF(ISNUMBER(MATCH($A8, _xlfn._xlws.FILTER(Procesos!$A$2:$A$25, Procesos!B$2:B$25="Laminado"), 0)), INDEX(Formula!$B$2:$Z$14, MATCH(VALUE($A8), VALUE(Formula!$A$2:$A$14), 0), MATCH(D$1, Formula!$B$1:$Z$1, 0)) * Mezclado!$D8/(1-Formula!$B$20), 0)} -> 2.7369395 | E8: {=IF(ISNUMBER(MATCH($A8, _xlfn._xlws.FILTER(Procesos!$A$2:$A$25, Procesos!C$2:C$25="Laminado"), 0)), INDEX(Formula!$B$2:$Z$14, MATCH(VALUE($A8), VALUE(Formula!$A$2:$A$14), 0), MATCH(E$1, Formula!$B$1:$Z$1, 0)) * Mezclado!$D8/(1-Formula!$B$20), 0)} -> 3.927699 | F8: {=IF(ISNUMBER(MATCH($A8, _xlfn._xlws.FILTER(Procesos!$A$2:$A$25, Procesos!D$2:D$25="Laminado"), 0)), INDEX(Formula!$B$2:$Z$14, MATCH(VALUE($A8), VALUE(Formula!$A$2:$A$14), 0), MATCH(F$1, Formula!$B$1:$Z$1, 0)) * Mezclado!$D8/(1-Formula!$B$20), 0)} -> 4.8011904 | G8: {=IF(ISNUMBER(MATCH($A8, _xlfn._xlws.FILTER(Procesos!$A$2:$A$25, Procesos!G$2:G$25="Laminado"), 0)), INDEX(Formula!$B$2:$Z$14, MATCH(VALUE($A8), VALUE(Formula!$A$2:$A$14), 0), MATCH(G$1, Formula!$B$1:$Z$1, 0)) * Mezclado!$D8/(1-Formula!$B$20), 0)} -> 0 | H8: {=IF(ISNUMBER(MATCH($A8, _xlfn._xlws.FILTER(Procesos!$A$2:$A$25, Procesos!I$2:I$25="Laminado"), 0)), INDEX(Formula!$B$2:$Z$14, MATCH(VALUE($A8), VALUE(Formula!$A$2:$A$14), 0), MATCH(H$1, Formula!$B$1:$Z$1, 0)) * Mezclado!$D8/(1-Formula!$B$20), 0)} -> 1.0903582
A9: 8 | B9: 20 | C9: 45938 | D9: {=IF(ISNUMBER(MATCH($A9, _xlfn._xlws.FILTER(Procesos!$A$2:$A$25, Procesos!B$2:B$25="Laminado"), 0)), INDEX(Formula!$B$2:$Z$14, MATCH(VALUE($A9), VALUE(Formula!$A$2:$A$14), 0), MATCH(D$1, Formula!$B$1:$Z$1, 0)) * Mezclado!$D9/(1-Formula!$B$20), 0)} -> 0 | E9: {=IF(ISNUMBER(MATCH($A9, _xlfn._xlws.FILTER(Procesos!$A$2:$A$25, Procesos!C$2:C$25="Laminado"), 0)), INDEX(Formula!$B$2:$Z$14, MATCH(VALUE($A9), VALUE(Formula!$A$2:$A$14), 0), MATCH(E$1, Formula!$B$1:$Z$1, 0)) * Mezclado!$D9/(1-Formula!$B$20), 0)} -> 0 | F9: {=IF(ISNUMBER(MATCH($A9, _xlfn._xlws.FILTER(Procesos!$A$2:$A$25, Procesos!D$2:D$25="Laminado"), 0)), INDEX(Formula!$B$2:$Z$14, MATCH(VALUE($A9), VALUE(Formula!$A$2:$A$14), 0), MATCH(F$1, Formula!$B$1:$Z$1, 0)) * Mezclado!$D9/(1-Formula!$B$20), 0)} -> 0 | G9: {=IF(ISNUMBER(MATCH($A9, _xlfn._xlws.FILTER(Procesos!$A$2:$A$25, Procesos!G$2:G$25="Laminado"), 0)), INDEX(Formula!$B$2:$Z$14, MATCH(VALUE($A9), VALUE(Formula!$A$2:$A$14), 0), MATCH(G$1, Formula!$B$1:$Z$1, 0)) * Mezclado!$D9/(1-Formula!$B$20), 0)} -> 0 | H9: {=IF(ISNUMBER(MATCH($A9, _xlfn._xlws.FILTER(Procesos!$A$2:$A$25, Procesos!I$2:I$25="Laminado"), 0)), INDEX(Formula!$B$2:$Z$14, MATCH(VALUE($A9), VALUE(Formula!$A$2:$A$14), 0), MATCH(H$1, Formula!$B$1:$Z$1, 0)) * Mezclado!$D9/(1-Formula!$B$20), 0)} -> 0
A10: 9 | B10: 20 | C10: 45938 | D10: {=IF(ISNUMBER(MATCH($A10, _xlfn._xlws.FILTER(Procesos!$A$2:$A$25, Procesos!B$2:B$25="Laminado"), 0)), INDEX(Formula!$B$2:$Z$14, MATCH(VALUE($A10), VALUE(Formula!$A$2:$A$14), 0), MATCH(D$1, Formula!$B$1:$Z$1, 0)) * Mezclado!$D10/(1-Formula!$B$20), 0)} -> 0 | E10: {=IF(ISNUMBER(MATCH($A10, _xlfn._xlws.FILTER(Procesos!$A$2:$A$25, Procesos!C$2:C$25="Laminado"), 0)), INDEX(Formula!$B$2:$Z$14, MATCH(VALUE($A10), VALUE(Formula!$A$2:$A$14), 0), MATCH(E$1, Formula!$B$1:$Z$1, 0)) * Mezclado!$D10/(1-Formula!$B$20), 0)} -> 0 | F10: {=IF(ISNUMBER(MATCH($A10, _xlfn._xlws.FILTER(Procesos!$A$2:$A$25, Procesos!D$2:D$25="Laminado"), 0)), INDEX(Formula!$B$2:$Z$14, MATCH(VALUE($A10), VALUE(Formula!$A$2:$A$14), 0), MATCH(F$1, Formula!$B$1:$Z$1, 0)) * Mezclado!$D10/(1-Formula!$B$20), 0)} -> 0 | G10: {=IF(ISNUMBER(MATCH($A10, _xlfn._xlws.FILTER(Procesos!$A$2:$A$25, Procesos!G$2:G$25="Laminado"), 0)), INDEX(Formula!$B$2:$Z$14, MATCH(VALUE($A10), VALUE(Formula!$A$2:$A$14), 0), MATCH(G$1, Formula!$B$1:$Z$1, 0)) * Mezclado!$D10/(1-Formula!$B$20), 0)} -> 0 | H10: {=IF(ISNUMBER(MATCH($A10, _xlfn._xlws.FILTER(Procesos!$A$2:$A$25, Procesos!I$2:I$25="Laminado"), 0)), INDEX(Formula!$B$2:$Z$14, MATCH(VALUE($A10), VALUE(Formula!$A$2:$A$14), 0), MATCH(H$1, Formula!$B$1:$Z$1, 0)) * Mezclado!$D10/(1-Formula!$B$20), 0)} -> 0
A11: 10 | B11: 20 | C11: 45956 | D11: {=IF(ISNUMBER(MATCH($A11, _xlfn._xlws.FILTER(Procesos!$A$2:$A$25, Procesos!B$2:B$25="Laminado"), 0)), INDEX(Formula!$B$2:$Z$14, MATCH(VALUE($A11), VALUE(Formula!$A$2:$A$14), 0), MATCH(D$1, Formula!$B$1:$Z$1, 0)) * Mezclado!$D11/(1-Formula!$B$20), 0)} -> 0.78212616 | E11: {=IF(ISNUMBER(MATCH($A11, _xlfn._xlws.FILTER(Procesos!$A$2:$A$25, Procesos!C$2:C$25="Laminado"), 0)), INDEX(Formula!$B$2:$Z$14, MATCH(VALUE($A11), VALUE(Formula!$A$2:$A$14), 0), MATCH(E$1, Formula!$B$1:$Z$1, 0)) * Mezclado!$D11/(1-Formula!$B$20), 0)} -> 0.78212616 | F11: {=IF(ISNUMBER(MATCH($A11, _xlfn._xlws.FILTER(Procesos!$A$2:$A$25, Procesos!D$2:D$25="Laminado"), 0)), INDEX(Formula!$B$2:$Z$14, MATCH(VALUE($A11), VALUE(Formula!$A$2:$A$14), 0), MATCH(F$1, Formula!$B$1:$Z$1, 0)) * Mezclado!$D11/(1-Formula!$B$20), 0)} -> 0 | G11: {=IF(ISNUMBER(MATCH($A11, _xlfn._xlws.FILTER(Procesos!$A$2:$A$25, Procesos!G$2:G$25="Laminado"), 0)), INDEX(Formula!$B$2:$Z$14, MATCH(VALUE($A11), VALUE(Formula!$A$2:$A$14), 0), MATCH(G$1, Formula!$B$1:$Z$1, 0)) * Mezclado!$D11/(1-Formula!$B$20), 0)} -> 0 | H11: {=IF(ISNUMBER(MATCH($A11, _xlfn._xlws.FILTER(Procesos!$A$2:$A$25, Procesos!I$2:I$25="Laminado"), 0)), INDEX(Formula!$B$2:$Z$14, MATCH(VALUE($A11), VALUE(Formula!$A$2:$A$14), 0), MATCH(H$1, Formula!$B$1:$Z$1, 0)) * Mezclado!$D11/(1-Formula!$B$20), 0)} -> 0
A12: 11 | B12: 20 | C12: 45987 | D12: {=IF(ISNUMBER(MATCH($A12, _xlfn._xlws.FILTER(Procesos!$A$2:$A$25, Procesos!B$2:B$25="Laminado"), 0)), INDEX(Formula!$B$2:$Z$14, MATCH(VALUE($A12), VALUE(Formula!$A$2:$A$14), 0), MATCH(D$1, Formula!$B$1:$Z$1, 0)) * Mezclado!$D12/(1-Formula!$B$20), 0)} -> 5.3554056 | E12: {=IF(ISNUMBER(MATCH($A12, _xlfn._xlws.FILTER(Procesos!$A$2:$A$25, Procesos!C$2:C$25="Laminado"), 0)), INDEX(Formula!$B$2:$Z$14, MATCH(VALUE($A12), VALUE(Formula!$A$2:$A$14), 0), MATCH(E$1, Formula!$B$1:$Z$1, 0)) * Mezclado!$D12/(1-Formula!$B$20), 0)} -> 2.230917 | F12: {=IF(ISNUMBER(MATCH($A12, _xlfn._xlws.FILTER(Procesos!$A$2:$A$25, Procesos!D$2:D$25="Laminado"), 0)), INDEX(Formula!$B$2:$Z$14, MATCH(VALUE($A12), VALUE(Formula!$A$2:$A$14), 0), MATCH(F$1, Formula!$B$1:$Z$1, 0)) * Mezclado!$D12/(1-Formula!$B$20), 0)} -> 0 | G12: {=IF(ISNUMBER(MATCH($A12, _xlfn._xlws.FILTER(Procesos!$A$2:$A$25, Procesos!G$2:G$25="Laminado"), 0)), INDEX(Formula!$B$2:$Z$14, MATCH(VALUE($A12), VALUE(Formula!$A$2:$A$14), 0), MATCH(G$1, Formula!$B$1:$Z$1, 0)) * Mezclado!$D12/(1-Formula!$B$20), 0)} -> 4.461834 | H12: {=IF(ISNUMBER(MATCH($A12, _xlfn._xlws.FILTER(Procesos!$A$2:$A$25, Procesos!I$2:I$25="Laminado"), 0)), INDEX(Formula!$B$2:$Z$14, MATCH(VALUE($A12), VALUE(Formula!$A$2:$A$14), 0), MATCH(H$1, Formula!$B$1:$Z$1, 0)) * Mezclado!$D12/(1-Formula!$B$20), 0)} -> 1.7851352
A13: 12 | B13: 20 | C13: 46019 | D13: {=IF(ISNUMBER(MATCH($A13, _xlfn._xlws.FILTER(Procesos!$A$2:$A$25, Procesos!B$2:B$25="Laminado"), 0)), INDEX(Formula!$B$2:$Z$14, MATCH(VALUE($A13), VALUE(Formula!$A$2:$A$14), 0), MATCH(D$1, Formula!$B$1:$Z$1, 0)) * Mezclado!$D13/(1-Formula!$B$20), 0)} -> 2.2951738 | E13: {=IF(ISNUMBER(MATCH($A13, _xlfn._xlws.FILTER(Procesos!$A$2:$A$25, Procesos!C$2:C$25="Laminado"), 0)), INDEX(Formula!$B$2:$Z$14, MATCH(VALUE($A13), VALUE(Formula!$A$2:$A$14), 0), MATCH(E$1, Formula!$B$1:$Z$1, 0)) * Mezclado!$D13/(1-Formula!$B$20), 0)} -> 0 | F13: {=IF(ISNUMBER(MATCH($A13, _xlfn._xlws.FILTER(Procesos!$A$2:$A$25, Procesos!D$2:D$25="Laminado"), 0)), INDEX(Formula!$B$2:$Z$14, MATCH(VALUE($A13), VALUE(Formula!$A$2:$A$14), 0), MATCH(F$1, Formula!$B$1:$Z$1, 0)) * Mezclado!$D13/(1-Formula!$B$20), 0)} -> 0 | G13: {=IF(ISNUMBER(MATCH($A13, _xlfn._xlws.FILTER(Procesos!$A$2:$A$25, Procesos!G$2:G$25="Laminado"), 0)), INDEX(Formula!$B$2:$Z$14, MATCH(VALUE($A13), VALUE(Formula!$A$2:$A$14), 0), MATCH(G$1, Formula!$B$1:$Z$1, 0)) * Mezclado!$D13/(1-Formula!$B$20), 0)} -> 0 | H13: {=IF(ISNUMBER(MATCH($A13, _xlfn._xlws.FILTER(Procesos!$A$2:$A$25, Procesos!I$2:I$25="Laminado"), 0)), INDEX(Formula!$B$2:$Z$14, MATCH(VALUE($A13), VALUE(Formula!$A$2:$A$14), 0), MATCH(H$1, Formula!$B$1:$Z$1, 0)) * Mezclado!$D13/(1-Formula!$B$20), 0)} -> 0
D66: =D25/500*60 -> 0 | E66: =E25/500*60 -> 0 | F66: =F25-2000 -> -2000
F67: =F66*0.997 -> -1994

Sheet Molido
A1: Municipalidad | B1: Cantidad (Kg) | C1: Fecha | D1: {=_xlfn._xlws.FILTER(Procesos!B1:V1, MMULT(TRANSPOSE(ROW(Procesos!B2:B25)^0), --(Procesos!B2:V25="Molido")) > 0)} -> Quinua | E1: Kiwicha | F1: Soya | G1: Trigo | H1: Cebada | I1: Cañihua | J1: Habas | K1: Arveja | L1: Ajonjoli | M1: Linaza | N1: Lenteja | O1: Arroz | P1: Maiz
A2: {=Mezclado!A2:C13} -> 1 | B2: 20 | C2: 45902 | D2: {=IF(ISNUMBER(MATCH($A2, _xlfn._xlws.FILTER(Procesos!$A$2:$A$25, Procesos!C$2:C$25="Molido"), 0)), INDEX(Formula!$B$2:$Z$14, MATCH(VALUE($A2), VALUE(Formula!$A$2:$A$14), 0), MATCH(D$1, Formula!$B$1:$Z$1, 0)) * Mezclado!$D2/(1-Formula!$B$19), 0)} -> 1.2093726 | E2: {=IF(ISNUMBER(MATCH($A2, _xlfn._xlws.FILTER(Procesos!$A$2:$A$25, Procesos!D$2:D$25="Molido"), 0)), INDEX(Formula!$B$2:$Z$14, MATCH(VALUE($A2), VALUE(Formula!$A$2:$A$14), 0), MATCH(E$1, Formula!$B$1:$Z$1, 0)) * Mezclado!$D2/(1-Formula!$B$19), 0)} -> 0.24105738 | F2: {=IF(ISNUMBER(MATCH($A2, _xlfn._xlws.FILTER(Procesos!$A$2:$A$25, Procesos!F$2:F$25="Molido"), 0)), INDEX(Formula!$B$2:$Z$14, MATCH(VALUE($A2), VALUE(Formula!$A$2:$A$14), 0), MATCH(F$1, Formula!$B$1:$Z$1, 0)) * Mezclado!$D2/(1-Formula!$B$19), 0)} -> 0 | G2: {=IF(ISNUMBER(MATCH($A2, _xlfn._xlws.FILTER(Procesos!$A$2:$A$25, Procesos!G$2:G$25="Molido"), 0)), INDEX(Formula!$B$2:$Z$14, MATCH(VALUE($A2), VALUE(Formula!$A$2:$A$14), 0), MATCH(G$1, Formula!$B$1:$Z$1, 0)) * Mezclado!$D2/(1-Formula!$B$19), 0)} -> 0 | H2: {=IF(ISNUMBER(MATCH($A2, _xlfn._xlws.FILTER(Procesos!$A$2:$A$25, Procesos!H$2:H$25="Molido"), 0)), INDEX(Formula!$B$2:$Z$14, MATCH(VALUE($A2), VALUE(Formula!$A$2:$A$14), 0), MATCH(H$1, Formula!$B$1:$Z$1, 0)) * Mezclado!$D2/(1-Formula!$B$19), 0)} -> 0.5556577 | I2: {=IF(ISNUMBER(MATCH($A2, _xlfn._xlws.FILTER(Procesos!$A$2:$A$25, Procesos!I$2:I$25="Molido"), 0)), INDEX(Formula!$B$2:$Z$14, MATCH(VALUE($A2), VALUE(Formula!$A$2:$A$14), 0), MATCH(I$1, Formula!$B$1:$Z$1, 0)) * Mezclado!$D2/(1-Formula!$B$19), 0)} -> 0.72521501 | J2: {=IF(ISNUMBER(MATCH($A2, _xlfn._xlws.FILTER(Procesos!$A$2:$A$25, Procesos!J$2:J$25="Molido"), 0)), INDEX(Formula!$B$2:$Z$14, MATCH(VALUE($A2), VALUE(Formula!$A$2:$A$14), 0), MATCH(J$1, Formula!$B$1:$Z$1, 0)) * Mezclado!$D2/(1-Formula!$B$19), 0)} -> 1.2093726 | K2: {=IF(ISNUMBER(MATCH($A2, _xlfn._xlws.FILTER(Procesos!$A$2:$A$25, Procesos!K$2:K$25="Molido"), 0)), INDEX(Formula!$B$2:$Z$14, MATCH(VALUE($A2), VALUE(Formula!$A$2:$A$14), 0), MATCH(K$1, Formula!$B$1:$Z$1, 0)) * Mezclado!$D2/(1-Formula!$B$19), 0)} -> 1.0643296 | L2: {=IF(ISNUMBER(MATCH($A2, _xlfn._xlws.FILTER(Procesos!$A$2:$A$25, Procesos!N$2:N$25="Molido"), 0)), INDEX(Formula!$B$2:$Z$14, MATCH(VALUE($A2), VALUE(Formula!$A$2:$A$14), 0), MATCH(L$1, Formula!$B$1:$Z$1, 0)) * Mezclado!$D2/(1-Formula!$B$19), 0)} -> 0 | M2: {=IF(ISNUMBER(MATCH($A2, _xlfn._xlws.FILTER(Procesos!$A$2:$A$25, Procesos!O$2:O$25="Molido"), 0)), INDEX(Formula!$B$2:$Z$14, MATCH(VALUE($A2), VALUE(Formula!$A$2:$A$14), 0), MATCH(M$1, Formula!$B$1:$Z$1, 0)) * Mezclado!$D2/(1-Formula!$B$19), 0)} -> 0 | N2: {=IF(ISNUMBER(MATCH($A2, _xlfn._xlws.FILTER(Procesos!$A$2:$A$25, Procesos!R$2:R$25="Molido"), 0)), INDEX(Formula!$B$2:$Z$14, MATCH(VALUE($A2), VALUE(Formula!$A$2:$A$14), 0), MATCH(N$1, Formula!$B$1:$Z$1, 0)) * Mezclado!$D2/(1-Formula!$B$19), 0)} -> 0 | O2: {=IF(ISNUMBER(MATCH($A2, _xlfn._xlws.FILTER(Procesos!$A$2:$A$25, Procesos!S$2:S$25="Molido"), 0)), INDEX(Formula!$B$2:$Z$14, MATCH(VALUE($A2), VALUE(Formula!$A$2:$A$14), 0), MATCH(O$1, Formula!$B$1:$Z$1, 0)) * Mezclado!$D2/(1-Formula!$B$19), 0)} -> 0 | P2: {=IF(ISNUMBER(MATCH($A2, _xlfn._xlws.FILTER(Procesos!$A$2:$A$25, Procesos!V$2:V$25="Molido"), 0)), INDEX(Formula!$B$2:$Z$14, MATCH(VALUE($A2), VALUE(Formula!$A$2:$A$14), 0), MATCH(P$1, Formula!$B$1:$Z$1, 0)) * Mezclado!$D2/(1-Formula!$B$19), 0)} -> 0
A3: 2 | B3: 20 | C3: 45903 | D3: {=IF(ISNUMBER(MATCH($A3, _xlfn._xlws.FILTER(Procesos!$A$2:$A$25, Procesos!C$2:C$25="Molido"), 0)), INDEX(Formula!$B$2:$Z$14, MATCH(VALUE($A3), VALUE(Formula!$A$2:$A$14), 0), MATCH(D$1, Formula!$B$1:$Z$1, 0)) * Mezclado!$D3/(1-Formula!$B$19), 0)} -> 0 | E3: {=IF(ISNUMBER(MATCH($A3, _xlfn._xlws.FILTER(Procesos!$A$2:$A$25, Procesos!D$2:D$25="Molido"), 0)), INDEX(Formula!$B$2:$Z$14, MATCH(VALUE($A3), VALUE(Formula!$A$2:$A$14), 0), MATCH(E$1, Formula!$B$1:$Z$1, 0)) * Mezclado!$D3/(1-Formula!$B$19), 0)} -> 0 | F3: {=IF(ISNUMBER(MATCH($A3, _xlfn._xlws.FILTER(Procesos!$A$2:$A$25, Procesos!F$2:F$25="Molido"), 0)), INDEX(Formula!$B$2:$Z$14, MATCH(VALUE($A3), VALUE(Formula!$A$2:$A$14), 0), MATCH(F$1, Formula!$B$1:$Z$1, 0)) * Mezclado!$D3/(1-Formula!$B$19), 0)} -> 0.62307205 | G3: {=IF(ISNUMBER(MATCH($A3, _xlfn._xlws.FILTER(Procesos!$A$2:$A$25, Procesos!G$2:G$25="Molido"), 0)), INDEX(Formula!$B$2:$Z$14, MATCH(VALUE($A3), VALUE(Formula!$A$2:$A$14), 0), MATCH(G$1, Formula!$B$1:$Z$1, 0)) * Mezclado!$D3/(1-Formula!$B$19), 0)} -> 0 | H3: {=IF(ISNUMBER(MATCH($A3, _xlfn._xlws.FILTER(Procesos!$A$2:$A$25, Procesos!H$2:H$25="Molido"), 0)), INDEX(Formula!$B$2:$Z$14, MATCH(VALUE($A3), VALUE(Formula!$A$2:$A$14), 0), MATCH(H$1, Formula!$B$1:$Z$1, 0)) * Mezclado!$D3/(1-Formula!$B$19), 0)} -> 0 | I3: {=IF(ISNUMBER(MATCH($A3, _xlfn._xlws.FILTER(Procesos!$A$2:$A$25, Procesos!I$2:I$25="Molido"), 0)), INDEX(Formula!$B$2:$Z$14, MATCH(VALUE($A3), VALUE(Formula!$A$2:$A$14), 0), MATCH(I$1, Formula!$B$1:$Z$1, 0)) * Mezclado!$D3/(1-Formula!$B$19), 0)} -> 0 | J3: {=IF(ISNUMBER(MATCH($A3, _xlfn._xlws.FILTER(Procesos!$A$2:$A$25, Procesos!J$2:J$25="Molido"), 0)), INDEX(Formula!$B$2:$Z$14, MATCH(VALUE($A3), VALUE(Formula!$A$2:$A$14), 0), MATCH(J$1, Formula!$B$1:$Z$1, 0)) * Mezclado!$D3/(1-Formula!$B$19), 0)} -> 0 | K3: {=IF(ISNUMBER(MATCH($A3, _xlfn._xlws.FILTER(Procesos!$A$2:$A$25, Procesos!K$2:K$25="Molido"), 0)), INDEX(Formula!$B$2:$Z$14, MATCH(VALUE($A3), VALUE(Formula!$A$2:$A$14), 0), MATCH(K$1, Formula!$B$1:$Z$1, 0)) * Mezclado!$D3/(1-Formula!$B$19), 0)} -> 0 | L3: {=IF(ISNUMBER(MATCH($A3, _xlfn._xlws.FILTER(Procesos!$A$2:$A$25, Procesos!N$2:N$25="Molido"), 0)), INDEX(Formula!$B$2:$Z$14, MATCH(VALUE($A3), VALUE(Formula!$A$2:$A$14), 0), MATCH(L$1, Formula!$B$1:$Z$1, 0)) * Mezclado!$D3/(1-Formula!$B$19), 0)} -> 1.0357296 | M3: {=IF(ISNUMBER(MATCH($A3, _xlfn._xlws.FILTER(Procesos!$A$2:$A$25, Procesos!O$2:O$25="Molido"), 0)), INDEX(Formula!$B$2:$Z$14, MATCH(VALUE($A3), VALUE(Formula!$A$2:$A$14), 0), MATCH(M$1, Formula!$B$1:$Z$1, 0)) * Mezclado!$D3/(1-Formula!$B$19), 0)} -> 0 | N3: {=IF(ISNUMBER(MATCH($A3, _xlfn._xlws.FILTER(Procesos!$A$2:$A$25, Procesos!R$2:R$25="Molido"), 0)), INDEX(Formula!$B$2:$Z$14, MATCH(VALUE($A3), VALUE(Formula!$A$2:$A$14), 0), MATCH(N$1, Formula!$B$1:$Z$1, 0)) * Mezclado!$D3/(1-Formula!$B$19), 0)} -> 0 | O3: {=IF(ISNUMBER(MATCH($A3, _xlfn._xlws.FILTER(Procesos!$A$2:$A$25, Procesos!S$2:S$25="Molido"), 0)), INDEX(Formula!$B$2:$Z$14, MATCH(VALUE($A3), VALUE(Formula!$A$2:$A$14), 0), MATCH(O$1, Formula!$B$1:$Z$1, 0)) * Mezclado!$D3/(1-Formula!$B$19), 0)} -> 0 | P3: {=IF(ISNUMBER(MATCH($A3, _xlfn._xlws.FILTER(Procesos!$A$2:$A$25, Procesos!V$2:V$25="Molido"), 0)), INDEX(Formula!$B$2:$Z$14, MATCH(VALUE($A3), VALUE(Formula!$A$2:$A$14), 0), MATCH(P$1, Formula!$B$1:$Z$1, 0)) * Mezclado!$D3/(1-Formula!$B$19), 0)} -> 0
A4: 3 | B4: 20 | C4: 45909 | D4: {=IF(ISNUMBER(MATCH($A4, _xlfn._xlws.FILTER(Procesos!$A$2:$A$25, Procesos!C$2:C$25="Molido"), 0)), INDEX(Formula!$B$2:$Z$14, MATCH(VALUE($A4), VALUE(Formula!$A$2:$A$14), 0), MATCH(D$1, Formula!$B$1:$Z$1, 0)) * Mezclado!$D4/(1-Formula!$B$19), 0)} -> 0 | E4: {=IF(ISNUMBER(MATCH($A4, _xlfn._xlws.FILTER(Procesos!$A$2:$A$25, Procesos!D$2:D$25="Molido"), 0)), INDEX(Formula!$B$2:$Z$14, MATCH(VALUE($A4), VALUE(Formula!$A$2:$A$14), 0), MATCH(E$1, Formula!$B$1:$Z$1, 0)) * Mezclado!$D4/(1-Formula!$B$19), 0)} -> 0 | F4: {=IF(ISNUMBER(MATCH($A4, _xlfn._xlws.FILTER(Procesos!$A$2:$A$25, Procesos!F$2:F$25="Molido"), 0)), INDEX(Formula!$B$2:$Z$14, MATCH(VALUE($A4), VALUE(Formula!$A$2:$A$14), 0), MATCH(F$1, Formula!$B$1:$Z$1, 0)) * Mezclado!$D4/(1-Formula!$B$19), 0)} -> 0 | G4: {=IF(ISNUMBER(MATCH($A4, _xlfn._xlws.FILTER(Procesos!$A$2:$A$25, Procesos!G$2:G$25="Molido"), 0)), INDEX(Formula!$B$2:$Z$14, MATCH(VALUE($A4), VALUE(Formula!$A$2:$A$14), 0), MATCH(G$1, Formula!$B$1:$Z$1, 0)) * Mezclado!$D4/(1-Formula!$B$19), 0)} -> 0 | H4: {=IF(ISNUMBER(MATCH($A4, _xlfn._xlws.FILTER(Procesos!$A$2:$A$25, Procesos!H$2:H$25="Molido"), 0)), INDEX(Formula!$B$2:$Z$14, MATCH(VALUE($A4), VALUE(Formula!$A$2:$A$14), 0), MATCH(H$1, Formula!$B$1:$Z$1, 0)) * Mezclado!$D4/(1-Formula!$B$19), 0)} -> 0 | I4: {=IF(ISNUMBER(MATCH($A4, _xlfn._xlws.FILTER(Procesos!$A$2:$A$25, Procesos!I$2:I$25="Molido"), 0)), INDEX(Formula!$B$2:$Z$14, MATCH(VALUE($A4), VALUE(Formula!$A$2:$A$14), 0), MATCH(I$1, Formula!$B$1:$Z$1, 0)) * Mezclado!$D4/(1-Formula!$B$19), 0)} -> 0 | J4: {=IF(ISNUMBER(MATCH($A4, _xlfn._xlws.FILTER(Procesos!$A$2:$A$25, Procesos!J$2:J$25="Molido"), 0)), INDEX(Formula!$B$2:$Z$14, MATCH(VALUE($A4), VALUE(Formula!$A$2:$A$14), 0), MATCH(J$1, Formula!$B$1:$Z$1, 0)) * Mezclado!$D4/(1-Formula!$B$19), 0)} -> 0 | K4: {=IF(ISNUMBER(MATCH($A4, _xlfn._xlws.FILTER(Procesos!$A$2:$A$25, Procesos!K$2:K$25="Molido"), 0)), INDEX(Formula!$B$2:$Z$14, MATCH(VALUE($A4), VALUE(Formula!$A$2:$A$14), 0), MATCH(K$1, Formula!$B$1:$Z$1, 0)) * Mezclado!$D4/(1-Formula!$B$19), 0)} -> 0 | L4: {=IF(ISNUMBER(MATCH($A4, _xlfn._xlws.FILTER(Procesos!$A$2:$A$25, Procesos!N$2:N$25="Molido"), 0)), INDEX(Formula!$B$2:$Z$14, MATCH(VALUE($A4), VALUE(Formula!$A$2:$A$14), 0), MATCH(L$1, Formula!$B$1:$Z$1, 0)) * Mezclado!$D4/(1-Formula!$B$19), 0)} -> 0 | M4: {=IF(ISNUMBER(MATCH($A4, _xlfn._xlws.FILTER(Procesos!$A$2:$A$25, Procesos!O$2:O$25="Molido"), 0)), INDEX(Formula!$B$2:$Z$14, MATCH(VALUE($A4), VALUE(Formula!$A$2:$A$14), 0), MATCH(M$1, Formula!$B$1:$Z$1, 0)) * Mezclado!$D4/(1-Formula!$B$19), 0)} -> 0.48351697 | N4: {=IF(ISNUMBER(MATCH($A4, _xlfn._xlws.FILTER(Procesos!$A$2:$A$25, Procesos!R$2:R$25="Molido"), 0)), INDEX(Formula!$B$2:$Z$14, MATCH(VALUE($A4), VALUE(Formula!$A$2:$A$14), 0), MATCH(N$1, Formula!$B$1:$Z$1, 0)) * Mezclado!$D4/(1-Formula!$B$19), 0)} -> 0 | O4: {=IF(ISNUMBER(MATCH($A4, _xlfn._xlws.FILTER(Procesos!$A$2:$A$25, Procesos!S$2:S$25="Molido"), 0)), INDEX(Formula!$B$2:$Z$14, MATCH(VALUE($A4), VALUE(Formula!$A$2:$A$14), 0), MATCH(O$1, Formula!$B$1:$Z$1, 0)) * Mezclado!$D4/(1-Formula!$B$19), 0)} -> 0 | P4: {=IF(ISNUMBER(MATCH($A4, _xlfn._xlws.FILTER(Procesos!$A$2:$A$25, Procesos!V$2:V$25="Molido"), 0)), INDEX(Formula!$B$2:$Z$14, MATCH(VALUE($A4), VALUE(Formula!$A$2:$A$14), 0), MATCH(P$1, Formula!$B$1:$Z$1, 0)) * Mezclado!$D4/(1-Formula!$B$19), 0)} -> 0
A5: 4 | B5: 20 | C5: 45925 | D5: {=IF(ISNUMBER(MATCH($A5, _xlfn._xlws.FILTER(Procesos!$A$2:$A$25, Procesos!C$2:C$25="Molido"), 0)), INDEX(Formula!$B$2:$Z$14, MATCH(VALUE($A5), VALUE(Formula!$A$2:$A$14), 0), MATCH(D$1, Formula!$B$1:$Z$1, 0)) * Mezclado!$D5/(1-Formula!$B$19), 0)} -> 0 | E5: {=IF(ISNUMBER(MATCH($A5, _xlfn._xlws.FILTER(Procesos!$A$2:$A$25, Procesos!D$2:D$25="Molido"), 0)), INDEX(Formula!$B$2:$Z$14, MATCH(VALUE($A5), VALUE(Formula!$A$2:$A$14), 0), MATCH(E$1, Formula!$B$1:$Z$1, 0)) * Mezclado!$D5/(1-Formula!$B$19), 0)} -> 0 | F5: {=IF(ISNUMBER(MATCH($A5, _xlfn._xlws.FILTER(Procesos!$A$2:$A$25, Procesos!F$2:F$25="Molido"), 0)), INDEX(Formula!$B$2:$Z$14, MATCH(VALUE($A5), VALUE(Formula!$A$2:$A$14), 0), MATCH(F$1, Formula!$B$1:$Z$1, 0)) * Mezclado!$D5/(1-Formula!$B$19), 0)} -> 0 | G5: {=IF(ISNUMBER(MATCH($A5, _xlfn._xlws.FILTER(Procesos!$A$2:$A$25, Procesos!G$2:G$25="Molido"), 0)), INDEX(Formula!$B$2:$Z$14, MATCH(VALUE($A5), VALUE(Formula!$A$2:$A$14), 0), MATCH(G$1, Formula!$B$1:$Z$1, 0)) * Mezclado!$D5/(1-Formula!$B$19), 0)} -> 5.2317624 | H5: {=IF(ISNUMBER(MATCH($A5, _xlfn._xlws.FILTER(Procesos!$A$2:$A$25, Procesos!H$2:H$25="Molido"), 0)), INDEX(Formula!$B$2:$Z$14, MATCH(VALUE($A5), VALUE(Formula!$A$2:$A$14), 0), MATCH(H$1, Formula!$B$1:$Z$1, 0)) * Mezclado!$D5/(1-Formula!$B$19), 0)} -> 0 | I5: {=IF(ISNUMBER(MATCH($A5, _xlfn._xlws.FILTER(Procesos!$A$2:$A$25, Procesos!I$2:I$25="Molido"), 0)), INDEX(Formula!$B$2:$Z$14, MATCH(VALUE($A5), VALUE(Formula!$A$2:$A$14), 0), MATCH(I$1, Formula!$B$1:$Z$1, 0)) * Mezclado!$D5/(1-Formula!$B$19), 0)} -> 0 | J5: {=IF(ISNUMBER(MATCH($A5, _xlfn._xlws.FILTER(Procesos!$A$2:$A$25, Procesos!J$2:J$25="Molido"), 0)), INDEX(Formula!$B$2:$Z$14, MATCH(VALUE($A5), VALUE(Formula!$A$2:$A$14), 0), MATCH(J$1, Formula!$B$1:$Z$1, 0)) * Mezclado!$D5/(1-Formula!$B$19), 0)} -> 0 | K5: {=IF(ISNUMBER(MATCH($A5, _xlfn._xlws.FILTER(Procesos!$A$2:$A$25, Procesos!K$2:K$25="Molido"), 0)), INDEX(Formula!$B$2:$Z$14, MATCH(VALUE($A5), VALUE(Formula!$A$2:$A$14), 0), MATCH(K$1, Formula!$B$1:$Z$1, 0)) * Mezclado!$D5/(1-Formula!$B$19), 0)} -> 0 | L5: {=IF(ISNUMBER(MATCH($A5, _xlfn._xlws.FILTER(Procesos!$A$2:$A$25, Procesos!N$2:N$25="Molido"), 0)), INDEX(Formula!$B$2:$Z$14, MATCH(VALUE($A5), VALUE(Formula!$A$2:$A$14), 0), MATCH(L$1, Formula!$B$1:$Z$1, 0)) * Mezclado!$D5/(1-Formula!$B$19), 0)} -> 0 | M5: {=IF(ISNUMBER(MATCH($A5, _xlfn._xlws.FILTER(Procesos!$A$2:$A$25, Procesos!O$2:O$25="Molido"), 0)), INDEX(Formula!$B$2:$Z$14, MATCH(VALUE($A5), VALUE(Formula!$A$2:$A$14), 0), MATCH(M$1, Formula!$B$1:$Z$1, 0)) * Mezclado!$D5/(1-Formula!$B$19), 0)} -> 0 | N5: {=IF(ISNUMBER(MATCH($A5, _xlfn._xlws.FILTER(Procesos!$A$2:$A$25, Procesos!R$2:R$25="Molido"), 0)), INDEX(Formula!$B$2:$Z$14, MATCH(VALUE($A5), VALUE(Formula!$A$2:$A$14), 0), MATCH(N$1, Formula!$B$1:$Z$1, 0)) * Mezclado!$D5/(1-Formula!$B$19), 0)} -> 2.6169026 | O5: {=IF(ISNUMBER(MATCH($A5, _xlfn._xlws.FILTER(Procesos!$A$2:$A$25, Procesos!S$2:S$25="Molido"), 0)), INDEX(Formula!$B$2:$Z$14, MATCH(VALUE($A5), VALUE(Formula!$A$2:$A$14), 0), MATCH(O$1, Formula!$B$1:$Z$1, 0)) * Mezclado!$D5/(1-Formula!$B$19), 0)} -> 4.3615044 | P5: {=IF(ISNUMBER(MATCH($A5, _xlfn._xlws.FILTER(Procesos!$A$2:$A$25, Procesos!V$2:V$25="Molido"), 0)), INDEX(Formula!$B$2:$Z$14, MATCH(VALUE($A5), VALUE(Formula!$A$2:$A$14), 0), MATCH(P$1, Formula!$B$1:$Z$1, 0)) * Mezclado!$D5/(1-Formula!$B$19), 0)} -> 0
A6: 5 | B6: 20 | C6: 45926 | D6: {=IF(ISNUMBER(MATCH($A6, _xlfn._xlws.FILTER(Procesos!$A$2:$A$25, Procesos!C$2:C$25="Molido"), 0)), INDEX(Formula!$B$2:$Z$14, MATCH(VALUE($A6), VALUE(Formula!$A$2:$A$14), 0), MATCH(D$1, Formula!$B$1:$Z$1, 0)) * Mezclado!$D6/(1-Formula!$B$19), 0)} -> 0 | E6: {=IF(ISNUMBER(MATCH($A6, _xlfn._xlws.FILTER(Procesos!$A$2:$A$25, Procesos!D$2:D$25="Molido"), 0)), INDEX(Formula!$B$2:$Z$14, MATCH(VALUE($A6), VALUE(Formula!$A$2:$A$14), 0), MATCH(E$1, Formula!$B$1:$Z$1, 0)) * Mezclado!$D6/(1-Formula!$B$19), 0)} -> 4.8354477 | F6: {=IF(ISNUMBER(MATCH($A6, _xlfn._xlws.FILTER(Procesos!$A$2:$A$25, Procesos!F$2:F$25="Molido"), 0)), INDEX(Formula!$B$2:$Z$14, MATCH(VALUE($A6), VALUE(Formula!$A$2:$A$14), 0), MATCH(F$1, Formula!$B$1:$Z$1, 0)) * Mezclado!$D6/(1-Formula!$B$19), 0)} -> 0 | G6: {=IF(ISNUMBER(MATCH($A6, _xlfn._xlws.FILTER(Procesos!$A$2:$A$25, Procesos!G$2:G$25="Molido"), 0)), INDEX(Formula!$B$2:$Z$14, MATCH(VALUE($A6), VALUE(Formula!$A$2:$A$14), 0), MATCH(G$1, Formula!$B$1:$Z$1, 0)) * Mezclado!$D6/(1-Formula!$B$19), 0)} -> 0 | H6: {=IF(ISNUMBER(MATCH($A6, _xlfn._xlws.FILTER(Procesos!$A$2:$A$25, Procesos!H$2:H$25="Molido"), 0)), INDEX(Formula!$B$2:$Z$14, MATCH(VALUE($A6), VALUE(Formula!$A$2:$A$14), 0), MATCH(H$1, Formula!$B$1:$Z$1, 0)) * Mezclado!$D6/(1-Formula!$B$19), 0)} -> 0 | I6: {=IF(ISNUMBER(MATCH($A6, _xlfn._xlws.FILTER(Procesos!$A$2:$A$25, Procesos!I$2:I$25="Molido"), 0)), INDEX(Formula!$B$2:$Z$14, MATCH(VALUE($A6), VALUE(Formula!$A$2:$A$14), 0), MATCH(I$1, Formula!$B$1:$Z$1, 0)) * Mezclado!$D6/(1-Formula!$B$19), 0)} -> 0 | J6: {=IF(ISNUMBER(MATCH($A6, _xlfn._xlws.FILTER(Procesos!$A$2:$A$25, Procesos!J$2:J$25="Molido"), 0)), INDEX(Formula!$B$2:$Z$14, MATCH(VALUE($A6), VALUE(Formula!$A$2:$A$14), 0), MATCH(J$1, Formula!$B$1:$Z$1, 0)) * Mezclado!$D6/(1-Formula!$B$19), 0)} -> 0 | K6: {=IF(ISNUMBER(MATCH($A6, _xlfn._xlws.FILTER(Procesos!$A$2:$A$25, Procesos!K$2:K$25="Molido"), 0)), INDEX(Formula!$B$2:$Z$14, MATCH(VALUE($A6), VALUE(Formula!$A$2:$A$14), 0), MATCH(K$1, Formula!$B$1:$Z$1, 0)) * Mezclado!$D6/(1-Formula!$B$19), 0)} -> 0 | L6: {=IF(ISNUMBER(MATCH($A6, _xlfn._xlws.FILTER(Procesos!$A$2:$A$25, Procesos!N$2:N$25="Molido"), 0)), INDEX(Formula!$B$2:$Z$14, MATCH(VALUE($A6), VALUE(Formula!$A$2:$A$14), 0), MATCH(L$1, Formula!$B$1:$Z$1, 0)) * Mezclado!$D6/(1-Formula!$B$19), 0)} -> 0 | M6: {=IF(ISNUMBER(MATCH($A6, _xlfn._xlws.FILTER(Procesos!$A$2:$A$25, Procesos!O$2:O$25="Molido"), 0)), INDEX(Formula!$B$2:$Z$14, MATCH(VALUE($A6), VALUE(Formula!$A$2:$A$14), 0), MATCH(M$1, Formula!$B$1:$Z$1, 0)) * Mezclado!$D6/(1-Formula!$B$19), 0)} -> 0 | N6: {=IF(ISNUMBER(MATCH($A6, _xlfn._xlws.FILTER(Procesos!$A$2:$A$25, Procesos!R$2:R$25="Molido"), 0)), INDEX(Formula!$B$2:$Z$14, MATCH(VALUE($A6), VALUE(Formula!$A$2:$A$14), 0), MATCH(N$1, Formula!$B$1:$Z$1, 0)) * Mezclado!$D6/(1-Formula!$B$19), 0)} -> 0 | O6: {=IF(ISNUMBER(MATCH($A6, _xlfn._xlws.FILTER(Procesos!$A$2:$A$25, Procesos!S$2:S$25="Molido"), 0)), INDEX(Formula!$B$2:$Z$14, MATCH(VALUE($A6), VALUE(Formula!$A$2:$A$14), 0), MATCH(O$1, Formula!$B$1:$Z$1, 0)) * Mezclado!$D6/(1-Formula!$B$19), 0)} -> 0 | P6: {=IF(ISNUMBER(MATCH($A6, _xlfn._xlws.FILTER(Procesos!$A$2:$A$25, Procesos!V$2:V$25="Molido"), 0)), INDEX(Formula!$B$2:$Z$14, MATCH(VALUE($A6), VALUE(Formula!$A$2:$A$14), 0), MATCH(P$1, Formula!$B$1:$Z$1, 0)) * Mezclado!$D6/(1-Formula!$B$19), 0)} -> 0
A7: 6 | B7: 20 | C7: 45926 | D7: {=IF(ISNUMBER(MATCH($A7, _xlfn._xlws.FILTER(Procesos!$A$2:$A$25, Procesos!C$2:C$25="Molido"), 0)), INDEX(Formula!$B$2:$Z$14, MATCH(VALUE($A7), VALUE(Formula!$A$2:$A$14), 0), MATCH(D$1, Formula!$B$1:$Z$1, 0)) * Mezclado!$D7/(1-Formula!$B$19), 0)} -> 0 | E7: {=IF(ISNUMBER(MATCH($A7, _xlfn._xlws.FILTER(Procesos!$A$2:$A$25, Procesos!D$2:D$25="Molido"), 0)), INDEX(Formula!$B$2:$Z$14, MATCH(VALUE($A7), VALUE(Formula!$A$2:$A$14), 0), MATCH(E$1, Formula!$B$1:$Z$1, 0)) * Mezclado!$D7/(1-Formula!$B$19), 0)} -> 2.5944312 | F7: {=IF(ISNUMBER(MATCH($A7, _xlfn._xlws.FILTER(Procesos!$A$2:$A$25, Procesos!F$2:F$25="Molido"), 0)), INDEX(Formula!$B$2:$Z$14, MATCH(VALUE($A7), VALUE(Formula!$A$2:$A$14), 0), MATCH(F$1, Formula!$B$1:$Z$1, 0)) * Mezclado!$D7/(1-Formula!$B$19), 0)} -> 0 | G7: {=IF(ISNUMBER(MATCH($A7, _xlfn._xlws.FILTER(Procesos!$A$2:$A$25, Procesos!G$2:G$25="Molido"), 0)), INDEX(Formula!$B$2:$Z$14, MATCH(VALUE($A7), VALUE(Formula!$A$2:$A$14), 0), MATCH(G$1, Formula!$B$1:$Z$1, 0)) * Mezclado!$D7/(1-Formula!$B$19), 0)} -> 0 | H7: {=IF(ISNUMBER(MATCH($A7, _xlfn._xlws.FILTER(Procesos!$A$2:$A$25, Procesos!H$2:H$25="Molido"), 0)), INDEX(Formula!$B$2:$Z$14, MATCH(VALUE($A7), VALUE(Formula!$A$2:$A$14), 0), MATCH(H$1, Formula!$B$1:$Z$1, 0)) * Mezclado!$D7/(1-Formula!$B$19), 0)} -> 0 | I7: {=IF(ISNUMBER(MATCH($A7, _xlfn._xlws.FILTER(Procesos!$A$2:$A$25, Procesos!I$2:I$25="Molido"), 0)), INDEX(Formula!$B$2:$Z$14, MATCH(VALUE($A7), VALUE(Formula!$A$2:$A$14), 0), MATCH(I$1, Formula!$B$1:$Z$1, 0)) * Mezclado!$D7/(1-Formula!$B$19), 0)} -> 0 | J7: {=IF(ISNUMBER(MATCH($A7, _xlfn._xlws.FILTER(Procesos!$A$2:$A$25, Procesos!J$2:J$25="Molido"), 0)), INDEX(Formula!$B$2:$Z$14, MATCH(VALUE($A7), VALUE(Formula!$A$2:$A$14), 0), MATCH(J$1, Formula!$B$1:$Z$1, 0)) * Mezclado!$D7/(1-Formula!$B$19), 0)} -> 0 | K7: {=IF(ISNUMBER(MATCH($A7, _xlfn._xlws.FILTER(Procesos!$A$2:$A$25, Procesos!K$2:K$25="Molido"), 0)), INDEX(Formula!$B$2:$Z$14, MATCH(VALUE($A7), VALUE(Formula!$A$2:$A$14), 0), MATCH(K$1, Formula!$B$1:$Z$1, 0)) * Mezclado!$D7/(1-Formula!$B$19), 0)} -> 0 | L7: {=IF(ISNUMBER(MATCH($A7, _xlfn._xlws.FILTER(Procesos!$A$2:$A$25, Procesos!N$2:N$25="Molido"), 0)), INDEX(Formula!$B$2:$Z$14, MATCH(VALUE($A7), VALUE(Formula!$A$2:$A$14), 0), MATCH(L$1, Formula!$B$1:$Z$1, 0)) * Mezclado!$D7/(1-Formula!$B$19), 0)} -> 0 | M7: {=IF(ISNUMBER(MATCH($A7, _xlfn._xlws.FILTER(Procesos!$A$2:$A$25, Procesos!O$2:O$25="Molido"), 0)), INDEX(Formula!$B$2:$Z$14, MATCH(VALUE($A7), VALUE(Formula!$A$2:$A$14), 0), MATCH(M$1, Formula!$B$1:$Z$1, 0)) * Mezclado!$D7/(1-Formula!$B$19), 0)} -> 0 | N7: {=IF(ISNUMBER(MATCH($A7, _xlfn._xlws.FILTER(Procesos!$A$2:$A$25, Procesos!R$2:R$25="Molido"), 0)), INDEX(Formula!$B$2:$Z$14, MATCH(VALUE($A7), VALUE(Formula!$A$2:$A$14), 0), MATCH(N$1, Formula!$B$1:$Z$1, 0)) * Mezclado!$D7/(1-Formula!$B$19), 0)} -> 0 | O7: {=IF(ISNUMBER(MATCH($A7, _xlfn._xlws.FILTER(Procesos!$A$2:$A$25, Procesos!S$2:S$25="Molido"), 0)), INDEX(Formula!$B$2:$Z$14, MATCH(VALUE($A7), VALUE(Formula!$A$2:$A$14), 0), MATCH(O$1, Formula!$B$1:$Z$1, 0)) * Mezclado!$D7/(1-Formula!$B$19), 0)} -> 0 | P7: {=IF(ISNUMBER(MATCH($A7, _xlfn._xlws.FILTER(Procesos!$A$2:$A$25, Procesos!V$2:V$25="Molido"), 0)), INDEX(Formula!$B$2:$Z$14, MATCH(VALUE($A7), VALUE(Formula!$A$2:$A$14), 0), MATCH(P$1, Formula!$B$1:$Z$1, 0)) * Mezclado!$D7/(1-Formula!$B$19), 0)} -> 0
A8: 7 | B8: 20 | C8: 45938 | D8: {=IF(ISNUMBER(MATCH($A8, _xlfn._xlws.FILTER(Procesos!$A$2:$A$25, Procesos!C$2:C$25="Molido"), 0)), INDEX(Formula!$B$2:$Z$14, MATCH(VALUE($A8), VALUE(Formula!$A$2:$A$14), 0), MATCH(D$1, Formula!$B$1:$Z$1, 0)) * Mezclado!$D8/(1-Formula!$B$19), 0)} -> 0 | E8: {=IF(ISNUMBER(MATCH($A8, _xlfn._xlws.FILTER(Procesos!$A$2:$A$25, Procesos!D$2:D$25="Molido"), 0)), INDEX(Formula!$B$2:$Z$14, MATCH(VALUE($A8), VALUE(Formula!$A$2:$A$14), 0), MATCH(E$1, Formula!$B$1:$Z$1, 0)) * Mezclado!$D8/(1-Formula!$B$19), 0)} -> 0 | F8: {=IF(ISNUMBER(MATCH($A8, _xlfn._xlws.FILTER(Procesos!$A$2:$A$25, Procesos!F$2:F$25="Molido"), 0)), INDEX(Formula!$B$2:$Z$14, MATCH(VALUE($A8), VALUE(Formula!$A$2:$A$14), 0), MATCH(F$1, Formula!$B$1:$Z$1, 0)) * Mezclado!$D8/(1-Formula!$B$19), 0)} -> 0 | G8: {=IF(ISNUMBER(MATCH($A8, _xlfn._xlws.FILTER(Procesos!$A$2:$A$25, Procesos!G$2:G$25="Molido"), 0)), INDEX(Formula!$B$2:$Z$14, MATCH(VALUE($A8), VALUE(Formula!$A$2:$A$14), 0), MATCH(G$1, Formula!$B$1:$Z$1, 0)) * Mezclado!$D8/(1-Formula!$B$19), 0)} -> 2.2205879 | H8: {=IF(ISNUMBER(MATCH($A8, _xlfn._xlws.FILTER(Procesos!$A$2:$A$25, Procesos!H$2:H$25="Molido"), 0)), INDEX(Formula!$B$2:$Z$14, MATCH(VALUE($A8), VALUE(Formula!$A$2:$A$14), 0), MATCH(H$1, Formula!$B$1:$Z$1, 0)) * Mezclado!$D8/(1-Formula!$B$19), 0)} -> 2.6638884 | I8: {=IF(ISNUMBER(MATCH($A8, _xlfn._xlws.FILTER(Procesos!$A$2:$A$25, Procesos!I$2:I$25="Molido"), 0)), INDEX(Formula!$B$2:$Z$14, MATCH(VALUE($A8), VALUE(Formula!$A$2:$A$14), 0), MATCH(I$1, Formula!$B$1:$Z$1, 0)) * Mezclado!$D8/(1-Formula!$B$19), 0)} -> 0 | J8: {=IF(ISNUMBER(MATCH($A8, _xlfn._xlws.FILTER(Procesos!$A$2:$A$25, Procesos!J$2:J$25="Molido"), 0)), INDEX(Formula!$B$2:$Z$14, MATCH(VALUE($A8), VALUE(Formula!$A$2:$A$14), 0), MATCH(J$1, Formula!$B$1:$Z$1, 0)) * Mezclado!$D8/(1-Formula!$B$19), 0)} -> 0 | K8: {=IF(ISNUMBER(MATCH($A8, _xlfn._xlws.FILTER(Procesos!$A$2:$A$25, Procesos!K$2:K$25="Molido"), 0)), INDEX(Formula!$B$2:$Z$14, MATCH(VALUE($A8), VALUE(Formula!$A$2:$A$14), 0), MATCH(K$1, Formula!$B$1:$Z$1, 0)) * Mezclado!$D8/(1-Formula!$B$19), 0)} -> 0 | L8: {=IF(ISNUMBER(MATCH($A8, _xlfn._xlws.FILTER(Procesos!$A$2:$A$25, Procesos!N$2:N$25="Molido"), 0)), INDEX(Formula!$B$2:$Z$14, MATCH(VALUE($A8), VALUE(Formula!$A$2:$A$14), 0), MATCH(L$1, Formula!$B$1:$Z$1, 0)) * Mezclado!$D8/(1-Formula!$B$19), 0)} -> 0 | M8: {=IF(ISNUMBER(MATCH($A8, _xlfn._xlws.FILTER(Procesos!$A$2:$A$25, Procesos!O$2:O$25="Molido"), 0)), INDEX(Formula!$B$2:$Z$14, MATCH(VALUE($A8), VALUE(Formula!$A$2:$A$14), 0), MATCH(M$1, Formula!$B$1:$Z$1, 0)) * Mezclado!$D8/(1-Formula!$B$19), 0)} -> 0 | N8: {=IF(ISNUMBER(MATCH($A8, _xlfn._xlws.FILTER(Procesos!$A$2:$A$25, Procesos!R$2:R$25="Molido"), 0)), INDEX(Formula!$B$2:$Z$14, MATCH(VALUE($A8), VALUE(Formula!$A$2:$A$14), 0), MATCH(N$1, Formula!$B$1:$Z$1, 0)) * Mezclado!$D8/(1-Formula!$B$19), 0)} -> 0 | O8: {=IF(ISNUMBER(MATCH($A8, _xlfn._xlws.FILTER(Procesos!$A$2:$A$25, Procesos!S$2:S$25="Molido"), 0)), INDEX(Formula!$B$2:$Z$14, MATCH(VALUE($A8), VALUE(Formula!$A$2:$A$14), 0), MATCH(O$1, Formula!$B$1:$Z$1, 0)) * Mezclado!$D8/(1-Formula!$B$19), 0)} -> 0 | P8: {=IF(ISNUMBER(MATCH($A8, _xlfn._xlws.FILTER(Procesos!$A$2:$A$25, Procesos!V$2:V$25="Molido"), 0)), INDEX(Formula!$B$2:$Z$14, MATCH(VALUE($A8), VALUE(Formula!$A$2:$A$14), 0), MATCH(P$1, Formula!$B$1:$Z$1, 0)) * Mezclado!$D8/(1-Formula!$B$19), 0)} -> 0
A9: 8 | B9: 20 | C9: 45938 | D9: {=IF(ISNUMBER(MATCH($A9, _xlfn._xlws.FILTER(Procesos!$A$2:$A$25, Procesos!C$2:C$25="Molido"), 0)), INDEX(Formula!$B$2:$Z$14, MATCH(VALUE($A9), VALUE(Formula!$A$2:$A$14), 0), MATCH(D$1, Formula!$B$1:$Z$1, 0)) * Mezclado!$D9/(1-Formula!$B$19), 0)} -> 0 | E9: {=IF(ISNUMBER(MATCH($A9, _xlfn._xlws.FILTER(Procesos!$A$2:$A$25, Procesos!D$2:D$25="Molido"), 0)), INDEX(Formula!$B$2:$Z$14, MATCH(VALUE($A9), VALUE(Formula!$A$2:$A$14), 0), MATCH(E$1, Formula!$B$1:$Z$1, 0)) * Mezclado!$D9/(1-Formula!$B$19), 0)} -> 0 | F9: {=IF(ISNUMBER(MATCH($A9, _xlfn._xlws.FILTER(Procesos!$A$2:$A$25, Procesos!F$2:F$25="Molido"), 0)), INDEX(Formula!$B$2:$Z$14, MATCH(VALUE($A9), VALUE(Formula!$A$2:$A$14), 0), MATCH(F$1, Formula!$B$1:$Z$1, 0)) * Mezclado!$D9/(1-Formula!$B$19), 0)} -> 0 | G9: {=IF(ISNUMBER(MATCH($A9, _xlfn._xlws.FILTER(Procesos!$A$2:$A$25, Procesos!G$2:G$25="Molido"), 0)), INDEX(Formula!$B$2:$Z$14, MATCH(VALUE($A9), VALUE(Formula!$A$2:$A$14), 0), MATCH(G$1, Formula!$B$1:$Z$1, 0)) * Mezclado!$D9/(1-Formula!$B$19), 0)} -> 20.428592 | H9: {=IF(ISNUMBER(MATCH($A9, _xlfn._xlws.FILTER(Procesos!$A$2:$A$25, Procesos!H$2:H$25="Molido"), 0)), INDEX(Formula!$B$2:$Z$14, MATCH(VALUE($A9), VALUE(Formula!$A$2:$A$14), 0), MATCH(H$1, Formula!$B$1:$Z$1, 0)) * Mezclado!$D9/(1-Formula!$B$19), 0)} -> 0 | I9: {=IF(ISNUMBER(MATCH($A9, _xlfn._xlws.FILTER(Procesos!$A$2:$A$25, Procesos!I$2:I$25="Molido"), 0)), INDEX(Formula!$B$2:$Z$14, MATCH(VALUE($A9), VALUE(Formula!$A$2:$A$14), 0), MATCH(I$1, Formula!$B$1:$Z$1, 0)) * Mezclado!$D9/(1-Formula!$B$19), 0)} -> 0 | J9: {=IF(ISNUMBER(MATCH($A9, _xlfn._xlws.FILTER(Procesos!$A$2:$A$25, Procesos!J$2:J$25="Molido"), 0)), INDEX(Formula!$B$2:$Z$14, MATCH(VALUE($A9), VALUE(Formula!$A$2:$A$14), 0), MATCH(J$1, Formula!$B$1:$Z$1, 0)) * Mezclado!$D9/(1-Formula!$B$19), 0)} -> 0 | K9: {=IF(ISNUMBER(MATCH($A9, _xlfn._xlws.FILTER(Procesos!$A$2:$A$25, Procesos!K$2:K$25="Molido"), 0)), INDEX(Formula!$B$2:$Z$14, MATCH(VALUE($A9), VALUE(Formula!$A$2:$A$14), 0), MATCH(K$1, Formula!$B$1:$Z$1, 0)) * Mezclado!$D9/(1-Formula!$B$19), 0)} -> 0 | L9: {=IF(ISNUMBER(MATCH($A9, _xlfn._xlws.FILTER(Procesos!$A$2:$A$25, Procesos!N$2:N$25="Molido"), 0)), INDEX(Formula!$B$2:$Z$14, MATCH(VALUE($A9), VALUE(Formula!$A$2:$A$14), 0), MATCH(L$1, Formula!$B$1:$Z$1, 0)) * Mezclado!$D9/(1-Formula!$B$19), 0)} -> 0 | M9: {=IF(ISNUMBER(MATCH($A9, _xlfn._xlws.FILTER(Procesos!$A$2:$A$25, Procesos!O$2:O$25="Molido"), 0)), INDEX(Formula!$B$2:$Z$14, MATCH(VALUE($A9), VALUE(Formula!$A$2:$A$14), 0), MATCH(M$1, Formula!$B$1:$Z$1, 0)) * Mezclado!$D9/(1-Formula!$B$19), 0)} -> 0 | N9: {=IF(ISNUMBER(MATCH($A9, _xlfn._xlws.FILTER(Procesos!$A$2:$A$25, Procesos!R$2:R$25="Molido"), 0)), INDEX(Formula!$B$2:$Z$14, MATCH(VALUE($A9), VALUE(Formula!$A$2:$A$14), 0), MATCH(N$1, Formula!$B$1:$Z$1, 0)) * Mezclado!$D9/(1-Formula!$B$19), 0)} -> 0 | O9: {=IF(ISNUMBER(MATCH($A9, _xlfn._xlws.FILTER(Procesos!$A$2:$A$25, Procesos!S$2:S$25="Molido"), 0)), INDEX(Formula!$B$2:$Z$14, MATCH(VALUE($A9), VALUE(Formula!$A$2:$A$14), 0), MATCH(O$1, Formula!$B$1:$Z$1, 0)) * Mezclado!$D9/(1-Formula!$B$19), 0)} -> 0 | P9: {=IF(ISNUMBER(MATCH($A9, _xlfn._xlws.FILTER(Procesos!$A$2:$A$25, Procesos!V$2:V$25="Molido"), 0)), INDEX(Formula!$B$2:$Z$14, MATCH(VALUE($A9), VALUE(Formula!$A$2:$A$14), 0), MATCH(P$1, Formula!$B$1:$Z$1, 0)) * Mezclado!$D9/(1-Formula!$B$19), 0)} -> 0
A10: 9 | B10: 20 | C10: 45938 | D10: {=IF(ISNUMBER(MATCH($A10, _xlfn._xlws.FILTER(Procesos!$A$2:$A$25, Procesos!C$2:C$25="Molido"), 0)), INDEX(Formula!$B$2:$Z$14, MATCH(VALUE($A10), VALUE(Formula!$A$2:$A$14), 0), MATCH(D$1, Formula!$B$1:$Z$1, 0)) * Mezclado!$D10/(1-Formula!$B$19), 0)} -> 0 | E10: {=IF(ISNUMBER(MATCH($A10, _xlfn._xlws.FILTER(Procesos!$A$2:$A$25, Procesos!D$2:D$25="Molido"), 0)), INDEX(Formula!$B$2:$Z$14, MATCH(VALUE($A10), VALUE(Formula!$A$2:$A$14), 0), MATCH(E$1, Formula!$B$1:$Z$1, 0)) * Mezclado!$D10/(1-Formula!$B$19), 0)} -> 0 | F10: {=IF(ISNUMBER(MATCH($A10, _xlfn._xlws.FILTER(Procesos!$A$2:$A$25, Procesos!F$2:F$25="Molido"), 0)), INDEX(Formula!$B$2:$Z$14, MATCH(VALUE($A10), VALUE(Formula!$A$2:$A$14), 0), MATCH(F$1, Formula!$B$1:$Z$1, 0)) * Mezclado!$D10/(1-Formula!$B$19), 0)} -> 0 | G10: {=IF(ISNUMBER(MATCH($A10, _xlfn._xlws.FILTER(Procesos!$A$2:$A$25, Procesos!G$2:G$25="Molido"), 0)), INDEX(Formula!$B$2:$Z$14, MATCH(VALUE($A10), VALUE(Formula!$A$2:$A$14), 0), MATCH(G$1, Formula!$B$1:$Z$1, 0)) * Mezclado!$D10/(1-Formula!$B$19), 0)} -> 17.740189 | H10: {=IF(ISNUMBER(MATCH($A10, _xlfn._xlws.FILTER(Procesos!$A$2:$A$25, Procesos!H$2:H$25="Molido"), 0)), INDEX(Formula!$B$2:$Z$14, MATCH(VALUE($A10), VALUE(Formula!$A$2:$A$14), 0), MATCH(H$1, Formula!$B$1:$Z$1, 0)) * Mezclado!$D10/(1-Formula!$B$19), 0)} -> 0 | I10: {=IF(ISNUMBER(MATCH($A10, _xlfn._xlws.FILTER(Procesos!$A$2:$A$25, Procesos!I$2:I$25="Molido"), 0)), INDEX(Formula!$B$2:$Z$14, MATCH(VALUE($A10), VALUE(Formula!$A$2:$A$14), 0), MATCH(I$1, Formula!$B$1:$Z$1, 0)) * Mezclado!$D10/(1-Formula!$B$19), 0)} -> 2.6884027 | J10: {=IF(ISNUMBER(MATCH($A10, _xlfn._xlws.FILTER(Procesos!$A$2:$A$25, Procesos!J$2:J$25="Molido"), 0)), INDEX(Formula!$B$2:$Z$14, MATCH(VALUE($A10), VALUE(Formula!$A$2:$A$14), 0), MATCH(J$1, Formula!$B$1:$Z$1, 0)) * Mezclado!$D10/(1-Formula!$B$19), 0)} -> 0 | K10: {=IF(ISNUMBER(MATCH($A10, _xlfn._xlws.FILTER(Procesos!$A$2:$A$25, Procesos!K$2:K$25="Molido"), 0)), INDEX(Formula!$B$2:$Z$14, MATCH(VALUE($A10), VALUE(Formula!$A$2:$A$14), 0), MATCH(K$1, Formula!$B$1:$Z$1, 0)) * Mezclado!$D10/(1-Formula!$B$19), 0)} -> 0 | L10: {=IF(ISNUMBER(MATCH($A10, _xlfn._xlws.FILTER(Procesos!$A$2:$A$25, Procesos!N$2:N$25="Molido"), 0)), INDEX(Formula!$B$2:$Z$14, MATCH(VALUE($A10), VALUE(Formula!$A$2:$A$14), 0), MATCH(L$1, Formula!$B$1:$Z$1, 0)) * Mezclado!$D10/(1-Formula!$B$19), 0)} -> 0 | M10: {=IF(ISNUMBER(MATCH($A10, _xlfn._xlws.FILTER(Procesos!$A$2:$A$25, Procesos!O$2:O$25="Molido"), 0)), INDEX(Formula!$B$2:$Z$14, MATCH(VALUE($A10), VALUE(Formula!$A$2:$A$14), 0), MATCH(M$1, Formula!$B$1:$Z$1, 0)) * Mezclado!$D10/(1-Formula!$B$19), 0)} -> 0 | N10: {=IF(ISNUMBER(MATCH($A10, _xlfn._xlws.FILTER(Procesos!$A$2:$A$25, Procesos!R$2:R$25="Molido"), 0)), INDEX(Formula!$B$2:$Z$14, MATCH(VALUE($A10), VALUE(Formula!$A$2:$A$14), 0), MATCH(N$1, Formula!$B$1:$Z$1, 0)) * Mezclado!$D10/(1-Formula!$B$19), 0)} -> 0 | O10: {=IF(ISNUMBER(MATCH($A10, _xlfn._xlws.FILTER(Procesos!$A$2:$A$25, Procesos!S$2:S$25="Molido"), 0)), INDEX(Formula!$B$2:$Z$14, MATCH(VALUE($A10), VALUE(Formula!$A$2:$A$14), 0), MATCH(O$1, Formula!$B$1:$Z$1, 0)) * Mezclado!$D10/(1-Formula!$B$19), 0)} -> 0 | P10: {=IF(ISNUMBER(MATCH($A10, _xlfn._xlws.FILTER(Procesos!$A$2:$A$25, Procesos!V$2:V$25="Molido"), 0)), INDEX(Formula!$B$2:$Z$14, MATCH(VALUE($A10), VALUE(Formula!$A$2:$A$14), 0), MATCH(P$1, Formula!$B$1:$Z$1, 0)) * Mezclado!$D10/(1-Formula!$B$19), 0)} -> 0
A11: 10 | B11: 20 | C11: 45956 | D11: {=IF(ISNUMBER(MATCH($A11, _xlfn._xlws.FILTER(Procesos!$A$2:$A$25, Procesos!C$2:C$25="Molido"), 0)), INDEX(Formula!$B$2:$Z$14, MATCH(VALUE($A11), VALUE(Formula!$A$2:$A$14), 0), MATCH(D$1, Formula!$B$1:$Z$1, 0)) * Mezclado!$D11/(1-Formula!$B$19), 0)} -> 0 | E11: {=IF(ISNUMBER(MATCH($A11, _xlfn._xlws.FILTER(Procesos!$A$2:$A$25, Procesos!D$2:D$25="Molido"), 0)), INDEX(Formula!$B$2:$Z$14, MATCH(VALUE($A11), VALUE(Formula!$A$2:$A$14), 0), MATCH(E$1, Formula!$B$1:$Z$1, 0)) * Mezclado!$D11/(1-Formula!$B$19), 0)} -> 0 | F11: {=IF(ISNUMBER(MATCH($A11, _xlfn._xlws.FILTER(Procesos!$A$2:$A$25, Procesos!F$2:F$25="Molido"), 0)), INDEX(Formula!$B$2:$Z$14, MATCH(VALUE($A11), VALUE(Formula!$A$2:$A$14), 0), MATCH(F$1, Formula!$B$1:$Z$1, 0)) * Mezclado!$D11/(1-Formula!$B$19), 0)} -> 0 | G11: {=IF(ISNUMBER(MATCH($A11, _xlfn._xlws.FILTER(Procesos!$A$2:$A$25, Procesos!G$2:G$25="Molido"), 0)), INDEX(Formula!$B$2:$Z$14, MATCH(VALUE($A11), VALUE(Formula!$A$2:$A$14), 0), MATCH(G$1, Formula!$B$1:$Z$1, 0)) * Mezclado!$D11/(1-Formula!$B$19), 0)} -> 0 | H11: {=IF(ISNUMBER(MATCH($A11, _xlfn._xlws.FILTER(Procesos!$A$2:$A$25, Procesos!H$2:H$25="Molido"), 0)), INDEX(Formula!$B$2:$Z$14, MATCH(VALUE($A11), VALUE(Formula!$A$2:$A$14), 0), MATCH(H$1, Formula!$B$1:$Z$1, 0)) * Mezclado!$D11/(1-Formula!$B$19), 0)} -> 0 | I11: {=IF(ISNUMBER(MATCH($A11, _xlfn._xlws.FILTER(Procesos!$A$2:$A$25, Procesos!I$2:I$25="Molido"), 0)), INDEX(Formula!$B$2:$Z$14, MATCH(VALUE($A11), VALUE(Formula!$A$2:$A$14), 0), MATCH(I$1, Formula!$B$1:$Z$1, 0)) * Mezclado!$D11/(1-Formula!$B$19), 0)} -> 0 | J11: {=IF(ISNUMBER(MATCH($A11, _xlfn._xlws.FILTER(Procesos!$A$2:$A$25, Procesos!J$2:J$25="Molido"), 0)), INDEX(Formula!$B$2:$Z$14, MATCH(VALUE($A11), VALUE(Formula!$A$2:$A$14), 0), MATCH(J$1, Formula!$B$1:$Z$1, 0)) * Mezclado!$D11/(1-Formula!$B$19), 0)} -> 0 | K11: {=IF(ISNUMBER(MATCH($A11, _xlfn._xlws.FILTER(Procesos!$A$2:$A$25, Procesos!K$2:K$25="Molido"), 0)), INDEX(Formula!$B$2:$Z$14, MATCH(VALUE($A11), VALUE(Formula!$A$2:$A$14), 0), MATCH(K$1, Formula!$B$1:$Z$1, 0)) * Mezclado!$D11/(1-Formula!$B$19), 0)} -> 0 | L11: {=IF(ISNUMBER(MATCH($A11, _xlfn._xlws.FILTER(Procesos!$A$2:$A$25, Procesos!N$2:N$25="Molido"), 0)), INDEX(Formula!$B$2:$Z$14, MATCH(VALUE($A11), VALUE(Formula!$A$2:$A$14), 0), MATCH(L$1, Formula!$B$1:$Z$1, 0)) * Mezclado!$D11/(1-Formula!$B$19), 0)} -> 0 | M11: {=IF(ISNUMBER(MATCH($A11, _xlfn._xlws.FILTER(Procesos!$A$2:$A$25, Procesos!O$2:O$25="Molido"), 0)), INDEX(Formula!$B$2:$Z$14, MATCH(VALUE($A11), VALUE(Formula!$A$2:$A$14), 0), MATCH(M$1, Formula!$B$1:$Z$1, 0)) * Mezclado!$D11/(1-Formula!$B$19), 0)} -> 0 | N11: {=IF(ISNUMBER(MATCH($A11, _xlfn._xlws.FILTER(Procesos!$A$2:$A$25, Procesos!R$2:R$25="Molido"), 0)), INDEX(Formula!$B$2:$Z$14, MATCH(VALUE($A11), VALUE(Formula!$A$2:$A$14), 0), MATCH(N$1, Formula!$B$1:$Z$1, 0)) * Mezclado!$D11/(1-Formula!$B$19), 0)} -> 0 | O11: {=IF(ISNUMBER(MATCH($A11, _xlfn._xlws.FILTER(Procesos!$A$2:$A$25, Procesos!S$2:S$25="Molido"), 0)), INDEX(Formula!$B$2:$Z$14, MATCH(VALUE($A11), VALUE(Formula!$A$2:$A$14), 0), MATCH(O$1, Formula!$B$1:$Z$1, 0)) * Mezclado!$D11/(1-Formula!$B$19), 0)} -> 0 | P11: {=IF(ISNUMBER(MATCH($A11, _xlfn._xlws.FILTER(Procesos!$A$2:$A$25, Procesos!V$2:V$25="Molido"), 0)), INDEX(Formula!$B$2:$Z$14, MATCH(VALUE($A11), VALUE(Formula!$A$2:$A$14), 0), MATCH(P$1, Formula!$B$1:$Z$1, 0)) * Mezclado!$D11/(1-Formula!$B$19), 0)} -> 0
