Workbook

Sheet General
A1: Municipalidad | B1: F.P. | C1: F.V. | D1: N° Lote | E1: Bolsa (g) | F1: Cantidad (Kg) | G1: Fecha | H1: Fecha Env. | I1: Marca | J1: Producto
A2: Sanchez Carrión | B2: 45962 | C2: 46327 | D2: 1 | E2: 1320 | F2: 9298.08 | G2: 45987 | I2: FACLAC | J2: HOJUELAS DE AVENA, QUINUA, MACA, HARINA DE SOYA INTEGRAL TOSTADA, ALMIDÓN DE MAÍZ AZUCARADA FORTIFICADA CON VITAMINAS Y MINERALES (HOJUELAS CRUDAS)
A3: Olmos | B3: 45992 | C3: 46357 | D3: 1 | E3: 1000 | F3: 11040 | G3: 46036 | I3: FACLAC | J3: MEZCLA PRECOCIDA DE QUINUA, KIWICHA, AVENA Y HARINA DE SOYA INTEGRAL TOSTADA CON LECHE ENTERA EN POLVO FORTIFICADA CON VITAMINAS Y MINERALES
A4: Sanchez Carrión | B4: 46023 | C4: 46388 | D4: 2 | E4: 1320 | F4: 9467.04 | G4: 46036 | I4: FACLAC | J4: HOJUELAS DE AVENA, QUINUA, MACA, HARINA DE SOYA INTEGRAL TOSTADA, ALMIDÓN DE MAÍZ AZUCARADA FORTIFICADA CON VITAMINAS Y MINERALES (HOJUELAS CRUDAS)
A5: Hualgayoc | B5: 46023 | C5: 46388 | D5: 1 | E5: 1687.06 | F5: 11906.242 | G5: 46038 | I5: FACLAC | J5: HOJUELAS PRECOCIDAS LACTEADAS DE KIWICHA, QUINUA Y AVENA, CON MACA, SOYA, TARHUI Y GARBANZO FORTIFICADAS CON VITAMINAS Y MINERALES
A6: Viru | B6: 46023 | C6: 46388 | D6: 1 | E6: 1000 | F6: 5850 | G6: 46038 | I6: FACLAC | J6: HOJUELAS PRECOCIDAS DE QUINUA, AVENA, KIWICHA, MACA, LINAZA, AJONJOLÍ CON PROTEÍNA AISLADA DE SOYA Y OMEGA 3 FORTIFICADO CON VITAMINAS Y MINERALES
A7: Florencia de Mora | B7: 46023 | C7: 46204 | D7: 1 | E7: 944.8 | F7: 4281.8336 | G7: 46044 | I7: FACLAC | J7: HOJUELAS DE AVENA QUINUA KIWICHA PRECOCIDA FORTIFICADA CON VITAMINAS Y MINERALES
A8: Olmos | B8: 46054 | C8: 46419 | D8: 2 | E8: 1000 | F8: 11058 | G8: 46055 | I8: FACLAC | J8: MEZCLA PRECOCIDA DE QUINUA, KIWICHA, AVENA Y HARINA DE SOYA INTEGRAL TOSTADA CON LECHE ENTERA EN POLVO FORTIFICADA CON VITAMINAS Y MINERALES
A9: Cajatambo | B9: 46054 | C9: 46419 | D9: 1 | E9: 1000 | F9: 1042 | G9: 46060 | I9: FACLAC | J9: HOJUELAS PRECOCIDAS DE AVENA, QUINUA, KIWICHA Y MACA ENRIQUECIDA CON VITAMINAS Y MINERALES
A10: Encañada | B10: 46054 | C10: 46419 | D10: 1 | E10: 1680 | F10: 21119.28 | G10: 46073 | I10: - | J10: MEZCLA PRECOCIDA DE HOJUELAS DE QUINUA, AVENA Y KIWICHA CON SEMILLAS DE CHÍA, HARINAS DE MACA Y CACAO FORTIFICADA CON VITAMINAS Y MINERALES
A11: Moyobamba | B11: 46082 | C11: 46447 | D11: 2 | E11: 1000 | F11: 9322 | G11: 46083 | I11: FACLAC | J11: HOJUELAS PRECOCIDAS AZUCARADAS DE AVENA, SACHA INCHI, HARINA DE MACA DESHIDRATADA, HARINA DE PLÁTANO, ALBUMINA DE HUEVO FORTIFICADA CON VITAMINAS Y MINERALES
A12: Olmos | B12: 46082 | C12: 46447 | D12: 3 | E12: 1000 | F12: 5611 | G12: 46085 | I12: FACLAC | J12: MEZCLA PRECOCIDA DE QUINUA, KIWICHA, AVENA Y HARINA DE SOYA INTEGRAL TOSTADA CON LECHE ENTERA EN POLVO FORTIFICADA CON VITAMINAS Y MINERALES
A13: Cajatambo | B13: 46082 | C13: 46447 | D13: 2 | E13: 1000 | F13: 1042 | G13: 46086 | I13: FACLAC | J13: HOJUELAS PRECOCIDAS DE AVENA, QUINUA, KIWICHA Y MACA ENRIQUECIDA CON VITAMINAS Y MINERALES
... A28: Encañada | B28: 46174 | C28: 46539 | D28: 3 | E28: 1680 | F28: 21119.28 | G28: 46175 | I28: FACLAC | J28: MEZCLA PRECOCIDA DE HOJUELAS DE QUINUA, AVENA Y KIWICHA CON SEMILLAS DE CHÍA, HARINAS DE MACA Y CACAO FORTIFICADA CON VITAMINAS Y MINERALES
A29: Hualgayoc | B29: 46174 | C29: 46539 | D29: 3 | E29: 1867.06 | F29: 11906.24 | G29: 46179 | I29: FACLAC | J29: HOJUELAS PRECOCIDAS LACTEADAS DE KIWICHA, QUINUA Y AVENA, CON MACA, SOYA, TARHUI Y GARBANZO FORTIFICADAS CON VITAMINAS Y MINERALES | K29: Trebol / 555 2026 / 22/6/26
A30: Alto Trujillo | B30: 46174 | C30: 46539 | D30: 4 | E30: 951.46 | F30: 3018.9826 | G30: 46188 | I30: FACLAC | J30: MEZCLA DE HOJUELAS DE QUINUA, AVENA Y KIWICHA ENRIQUECIDA CON VITAMINAS Y MINERALES - HOJUELAS CRUDAS | K30: Trebol / 593 2026 / 22/7/26
A31: Sanchez Carrión | B31: 46204 | C31: 46569 | D31: 5 | E31: 1320 | F31: 9298.08 | G31: 46214 | I31: FACLAC | J31: HOJUELAS DE AVENA, QUINUA, MACA, HARINA DE SOYA INTEGRAL TOSTADA, ALMIDÓN DE MAÍZ AZUCARADA FORTIFICADA CON VITAMINAS Y MINERALES (HOJUELAS CRUDAS) | K31: Santa Fe / 937 2026 / 22/7/26
A32: Alto Trujillo | B32: 46204 | C32: 46569 | D32: 5 | E32: 951.46 | F32: 3018.9826 | G32: 46218 | I32: FACLAC | J32: MEZCLA DE HOJUELAS DE QUINUA, AVENA Y KIWICHA ENRIQUECIDA CON VITAMINAS Y MINERALES - HOJUELAS CRUDAS | K32: Trebol/ 537 2026 / 8/6/26
A33: Florencia de Mora | B33: 46204 | C33: 46388 | D33: 4 | E33: 944.8 | F33: 4281.8336 | G33: 46218 | I33: FACLAC | J33: HOJUELAS DE AVENA QUINUA KIWICHA PRECOCIDA FORTIFICADA CON VITAMINAS Y MINERALES | K33: Santa Fe/ 0926 2026 / 18/7/26
A34: Encañada | B34: 46174 | C34: 46539 | D34: 3 | E34: 1680 | F34: 21119.28 | G34: 46192 | I34: FACLAC | J34: MEZCLA PRECOCIDA DE HOJUELAS DE QUINUA, AVENA Y KIWICHA CON SEMILLAS DE CHÍA, HARINAS DE MACA Y CACAO FORTIFICADA CON VITAMINAS Y MINERALES | K34: Rivelab - 483 2026 - 26/06/2026
A35: Moyobamba | B35: 46174 | C35: 46539 | D35: 4 | E35: 1000 | F35: 9294 | G35: 46197 | I35: FACLAC | J35: HOJUELAS PRECOCIDAS AZUCARADAS DE AVENA, SACHA INCHI, HARINA DE MACA DESHIDRATADA, HARINA DE PLÁTANO, ALBUMINA DE HUEVO FORTIFICADA CON VITAMINAS Y MINERALES | L35: Santa Fe - 0956 2026 - 1/07/26
A36: Viru | B36: 46204 | C36: 46569 | D36: 4 | E36: 1000 | F36: 6046 | G36: 46216 | I36: FACLAC | J36: HOJUELAS PRECOCIDAS DE QUINUA, AVENA, KIWICHA, MACA, LINAZA, AJONJOLÍ CON PROTEÍNA AISLADA DE SOYA Y OMEGA 3 FORTIFICADO CON VITAMINAS Y MINERALES | K36: Santa Fe - 0932 2026 - 13/07/26
A37: Alto Trujillo | B37: 46235 | C37: 46600 | D37: 7 | E37: 1185.12 | F37: 3759.21 | G37: 46235 | I37: FACLAC | J37: MEZCLA DE HOJUELAS DE QUINUA, AVENA Y KIWICHA ENRIQUECIDA CON VITAMINAS Y MINERALES - HOJUELAS CRUDAS | K37: Rivelab - 650 2026 - 07/08/2026
A38: Olmos | B38: 46235 | C38: 46600 | D38: 8 | E38: 1000 | F38: 5611 | G38: 46238 | I38: FACLAC | J38: MEZCLA PRECOCIDA DE QUINUA, KIWICHA, AVENA Y HARINA DE SOYA INTEGRAL TOSTADA CON LECHE ENTERA EN POLVO FORTIFICADA CON VITAMINAS Y MINERALES | K38: Rivelab - 656 2026 - 11/08/2026
A39: Viru | B39: 46235 | C39: 46600 | D39: 5 | E39: 1000 | F39: 13579 | G39: 46248 | I39: FACLAC | J39: HOJUELAS PRECOCIDAS DE QUINUA, AVENA, KIWICHA, MACA, LINAZA, AJONJOLÍ CON PROTEÍNA AISLADA DE SOYA Y OMEGA 3 FORTIFICADO CON VITAMINAS Y MINERALES | K39: Santa Fe - 1087 2026 - 21/08/26
A40: Sanchez Carrión | B40: 46235 | C40: 46600 | D40: 6 | E40: 1.06 | F40: 3743.92 | G40: 46249 | I40: FACLAC | J40: HOJUELAS DE AVENA, QUINUA, MACA, HARINA DE SOYA INTEGRAL TOSTADA, ALMIDÓN DE MAÍZ AZUCARADA FORTIFICADA CON VITAMINAS Y MINERALES (HOJUELAS CRUDAS) | K40: Santa Fe - 1085 2026 - 15/8/26
A41: Alto Trujillo | B41: 46235 | C41: 46600 | D41: 6 | E41: 951.46 | F41: 3018.9826 | G41: 46251 | I41: FACLAC | J41: MEZCLA DE HOJUELAS DE QUINUA, AVENA Y KIWICHA ENRIQUECIDA CON VITAMINAS Y MINERALES - HOJUELAS CRUDAS | K41: Trebol - 652 2026 - 25/08/2026

Sheet Mezclado
A1: Municipalidad | B1: Cantidad (Kg) | C1: Fecha | D1: Mezclado | E1: Avena | F1: Quinua | G1: Kiwicha | H1: Soya | I1: Maca | J1: Azucar | K1: Sacha Inchi | L1: Maiz Chufla | M1: Leche Polvo | N1: Aceite soya | O1: Aceite Girasol | P1: Chia | Q1: Cacao Deshidratado | R1: Garbanzo | S1: Tarhui | T1: Almidon maca | U1: Linaza | V1: Ajonjoli | W1: Proteina aislada soya | X1: Albumina clara de huevo | Y1: Harina de Plátano | Z1: Fosfato Tricálcio | AA1: Mix vitaminico
A2: {=General!A2:A41} -> Sanchez Carrión | B2: {=General!F2:G41} -> 9298.08 | C2: 45987 | D2: =B2*1/(1-Formula!$B$19) -> 9307.3874 | E2: {=_xlfn._xlws.FILTER(Formula!$B$2:$X$12,Formula!$A$2:$A$12=A2,0)*D2} -> 583.57319 | F2: 3807.6522 | G2: 0 | H2: 1057.3192 | I2: 740.86804 | J2: 1057.3192 | K2: 0 | L2: 1586.9095 | M2: 0 | N2: 0 | O2: 0 | P2: 0 | Q2: 0 | R2: 0 | S2: 0 | T2: 0 | U2: 0 | V2: 0 | W2: 0 | X2: 0 | Y2: 0 | Z2: 448.61607 | AA2: 25.129946
A3: Olmos | B3: 11040 | C3: 46036 | D3: =B3*1/(1-Formula!$B$19) -> 11051.051 | E3: {=_xlfn._xlws.FILTER(Formula!$B$2:$X$12,Formula!$A$2:$A$12=A3,0)*D3} -> 2509.8474 | F3: 3475.1733 | G3: 2895.9777 | H3: 579.19555 | I3: 0 | J3: 0 | K3: 0 | L3: 0 | M3: 1158.3911 | N3: 0 | O3: 0 | P3: 0 | Q3: 0 | R3: 0 | S3: 0 | T3: 0 | U3: 0 | V3: 0 | W3: 0 | X3: 0 | Y3: 0 | Z3: 409.29819 | AA3: 23.167822
A4: Sanchez Carrión | B4: 9467.04 | C4: 46036 | D4: =B4*1/(1-Formula!$B$19) -> 9476.5165 | E4: {=_xlfn._xlws.FILTER(Formula!$B$2:$X$12,Formula!$A$2:$A$12=A4,0)*D4} -> 594.17759 | F4: 3876.8429 | G4: 0 | H4: 1076.5323 | I4: 754.33071 | J4: 1076.5323 | K4: 0 | L4: 1615.7461 | M4: 0 | N4: 0 | O4: 0 | P4: 0 | Q4: 0 | R4: 0 | S4: 0 | T4: 0 | U4: 0 | V4: 0 | W4: 0 | X4: 0 | Y4: 0 | Z4: 456.7681 | AA4: 25.586595
A5: Hualgayoc | B5: 11906.242 | C5: 46038 | D5: =B5*1/(1-Formula!$B$19) -> 11918.16 | E5: {=_xlfn._xlws.FILTER(Formula!$B$2:$X$12,Formula!$A$2:$A$12=A5,0)*D5} -> 1531.4835 | F5: 2579.0898 | G5: 3974.7063 | H5: 107.26344 | I5: 1504.0718 | J5: 0 | K5: 0 | L5: 0 | M5: 1396.8083 | N5: 171.6215 | O5: 0 | P5: 0 | Q5: 0 | R5: 85.81075 | S5: 85.81075 | T5: 0 | U5: 0 | V5: 0 | W5: 0 | X5: 0 | Y5: 0 | Z5: 455.2737 | AA5: 26.219952
A6: Viru | B6: 5850 | C6: 46038 | D6: =B6*1/(1-Formula!$B$19) -> 5855.8559 | E6: {=_xlfn._xlws.FILTER(Formula!$B$2:$X$12,Formula!$A$2:$A$12=A6,0)*D6} -> 762.43243 | F6: 1314.0541 | G6: 2628.1081 | H6: 0 | I6: 597.2973 | J6: 0 | K6: 0 | L6: 0 | M6: 0 | N6: 0 | O6: 107.74775 | P6: 0 | Q6: 0 | R6: 0 | S6: 0 | T6: 0 | U6: 59.72973 | V6: 59.72973 | W6: 59.72973 | X6: 0 | Y6: 0 | Z6: 252.97297 | AA6: 14.054054
A7: Florencia de Mora | B7: 4281.8336 | C7: 46044 | D7: =B7*1/(1-Formula!$B$19) -> 4286.1197 | E7: {=_xlfn._xlws.FILTER(Formula!$B$2:$X$12,Formula!$A$2:$A$12=A7,0)*D7} -> 725.84585 | F7: 1723.8839 | G7: 1633.1532 | H7: 0 | I7: 0 | J7: 0 | K7: 0 | L7: 0 | M7: 0 | N7: 0 | O7: 0 | P7: 0 | Q7: 0 | R7: 0 | S7: 0 | T7: 0 | U7: 0 | V7: 0 | W7: 0 | X7: 0 | Y7: 0 | Z7: 192.34915 | AA7: 10.887688
A8: Olmos | B8: 11058 | C8: 46055 | D8: =B8*1/(1-Formula!$B$19) -> 11069.069 | E8: {=_xlfn._xlws.FILTER(Formula!$B$2:$X$12,Formula!$A$2:$A$12=A8,0)*D8} -> 2513.9395 | F8: 3480.8393 | G8: 2900.6994 | H8: 580.13989 | I8: 0 | J8: 0 | K8: 0 | L8: 0 | M8: 1160.2798 | N8: 0 | O8: 0 | P8: 0 | Q8: 0 | R8: 0 | S8: 0 | T8: 0 | U8: 0 | V8: 0 | W8: 0 | X8: 0 | Y8: 0 | Z8: 409.96552 | AA8: 23.205596
A9: Cajatambo | B9: 1042 | C9: 46060 | D9: =B9*1/(1-Formula!$B$19) -> 1043.043 | E9: {=_xlfn._xlws.FILTER(Formula!$B$2:$X$12,Formula!$A$2:$A$12=A9,0)*D9} -> 370.38458 | F9: 123.4963 | G9: 123.4963 | H9: 0 | I9: 370.38458 | J9: 0 | K9: 0 | L9: 0 | M9: 0 | N9: 0 | O9: 0 | P9: 0 | Q9: 0 | R9: 0 | S9: 0 | T9: 0 | U9: 0 | V9: 0 | W9: 0 | X9: 0 | Y9: 0 | Z9: 52.360761 | AA9: 2.9205205
A10: Encañada | B10: 21119.28 | C10: 46073 | D10: =B10*1/(1-Formula!$B$19) -> 21140.42 | E10: {=_xlfn._xlws.FILTER(Formula!$B$2:$X$12,Formula!$A$2:$A$12=A10,0)*D10} -> 4251.3385 | F10: 4151.9786 | G10: 9437.0837 | H10: 0 | I10: 1133.1265 | J10: 0 | K10: 0 | L10: 0 | M10: 0 | N10: 0 | O10: 0 | P10: 378.41353 | Q10: 942.86275 | R10: 0 | S10: 0 | T10: 0 | U10: 0 | V10: 0 | W10: 0 | X10: 0 | Y10: 0 | Z10: 801.22193 | AA10: 44.394883
A11: Moyobamba | B11: 9322 | C11: 46083 | D11: =B11*1/(1-Formula!$B$19) -> 9331.3313 | E11: {=_xlfn._xlws.FILTER(Formula!$B$2:$X$12,Formula!$A$2:$A$12=A11,0)*D11} -> 3277.8855 | F11: 0 | G11: 0 | H11: 0 | I11: 0 | J11: 1064.2486 | K11: 1106.8185 | L11: 0 | M11: 0 | N11: 0 | O11: 0 | P11: 0 | Q11: 0 | R11: 0 | S11: 0 | T11: 2234.922 | U11: 0 | V11: 0 | W11: 0 | X11: 319.27457 | Y11: 851.39884 | Z11: 0 | AA11: 476.78335
A12: Olmos | B12: 5611 | C12: 46085 | D12: =B12*1/(1-Formula!$B$19) -> 5616.6166 | E12: {=_xlfn._xlws.FILTER(Formula!$B$2:$X$12,Formula!$A$2:$A$12=A12,0)*D12} -> 1275.6117 | F12: 1766.2316 | G12: 1471.8597 | H12: 294.37194 | I12: 0 | J12: 0 | K12: 0 | L12: 0 | M12: 588.74388 | N12: 0 | O12: 0 | P12: 0 | Q12: 0 | R12: 0 | S12: 0 | T12: 0 | U12: 0 | V12: 0 | W12: 0 | X12: 0 | Y12: 0 | Z12: 208.02284 | AA12: 11.774878
A13: Cajatambo | B13: 1042 | C13: 46086 | D13: =B13*1/(1-Formula!$B$19) -> 1043.043 | E13: {=_xlfn._xlws.FILTER(Formula!$B$2:$X$12,Formula!$A$2:$A$12=A13,0)*D13} -> 370.38458 | F13: 123.4963 | G13: 123.4963 | H13: 0 | I13: 370.38458 | J13: 0 | K13: 0 | L13: 0 | M13: 0 | N13: 0 | O13: 0 | P13: 0 | Q13: 0 | R13: 0 | S13: 0 | T13: 0 | U13: 0 | V13: 0 | W13: 0 | X13: 0 | Y13: 0 | Z13: 52.360761 | AA13: 2.9205205
A14: Hualgayoc | B14: 11906.242 | C14: 46094 | D14: =B14*1/(1-Formula!$B$19) -> 11918.16 | E14: {=_xlfn._xlws.FILTER(Formula!$B$2:$X$12,Formula!$A$2:$A$12=A14,0)*D14} -> 1531.4835 | F14: 2579.0898 | G14: 3974.7063 | H14: 107.26344 | I14: 1504.0718 | J14: 0 | K14: 0 | L14: 0 | M14: 1396.8083 | N14: 171.6215 | O14: 0 | P14: 0 | Q14: 0 | R14: 85.81075 | S14: 85.81075 | T14: 0 | U14: 0 | V14: 0 | W14: 0 | X14: 0 | Y14: 0 | Z14: 455.2737 | AA14: 26.219952
... A41: Alto Trujillo | B41: 3018.9826 | C41: 46251 | D41: =B41*1/(1-Formula!$B$19) -> 3022.0046 | E41: {=_xlfn._xlws.FILTER(Formula!$B$2:$X$12,Formula!$A$2:$A$12=A41,0)*D41} -> 160.46844 | F41: 821.07865 | G41: 1932.2697 | H41: 0 | I41: 0 | J41: 0 | K41: 0 | L41: 0 | M41: 0 | N41: 0 | O41: 0 | P41: 0 | Q41: 0 | R41: 0 | S41: 0 | T41: 0 | U41: 0 | V41: 0 | W41: 0 | X41: 0 | Y41: 0 | Z41: 102.44596 | AA41: 5.7418087
A48: Alto Trujillo | E48: {=(D32-2800)*Formula!B2:X2} -> 11.788443 | F48: 60.318646 | G48: 141.94973 | H48: 0 | I48: 0 | J48: 0 | K48: 0 | L48: 0 | M48: 0 | N48: 0 | O48: 0 | P48: 0 | Q48: 0 | R48: 0 | S48: 0 | T48: 0 | U48: 0 | V48: 0 | W48: 0 | X48: 0 | Y48: 0 | Z48: 7.5259554 | AA48: 0.42180871
A49: Cajatambo | E49: {=400*Formula!B3:X3} -> 142.04 | F49: 47.36 | G49: 47.36 | H49: 0 | I49: 142.04 | J49: 0 | K49: 0 | L49: 0 | M49: 0 | N49: 0 | O49: 0 | P49: 0 | Q49: 0 | R49: 0 | S49: 0 | T49: 0 | U49: 0 | V49: 0 | W49: 0 | X49: 0 | Y49: 0 | Z49: 20.08 | AA49: 1.12
A50: Encañada | E50: {=400*Formula!B4:X4} -> 80.44 | F50: 78.56 | G50: 178.56 | H50: 0 | I50: 21.44 | J50: 0 | K50: 0 | L50: 0 | M50: 0 | N50: 0 | O50: 0 | P50: 7.16 | Q50: 17.84 | R50: 0 | S50: 0 | T50: 0 | U50: 0 | V50: 0 | W50: 0 | X50: 0 | Y50: 0 | Z50: 15.16 | AA50: 0.84
A51: Florencia de Mora | E51: {=400*Formula!B5:X5} -> 67.739204 | F51: 160.88061 | G51: 152.41321 | H51: 0 | I51: 0 | J51: 0 | K51: 0 | L51: 0 | M51: 0 | N51: 0 | O51: 0 | P51: 0 | Q51: 0 | R51: 0 | S51: 0 | T51: 0 | U51: 0 | V51: 0 | W51: 0 | X51: 0 | Y51: 0 | Z51: 17.950889 | AA51: 1.0160881
A52: Hualgayoc | E52: {=400*Formula!B6:X6} -> 51.4 | F52: 86.56 | G52: 133.4 | H52: 3.6 | I52: 50.48 | J52: 0 | K52: 0 | L52: 0 | M52: 46.88 | N52: 5.76 | O52: 0 | P52: 0 | Q52: 0 | R52: 2.88 | S52: 2.88 | T52: 0 | U52: 0 | V52: 0 | W52: 0 | X52: 0 | Y52: 0 | Z52: 15.28 | AA52: 0.88
A53: Moyobamba | E53: {=400*Formula!B7:X7} -> 140.51095 | F53: 0 | G53: 0 | H53: 0 | I53: 0 | J53: 45.620438 | K53: 47.445255 | L53: 0 | M53: 0 | N53: 0 | O53: 0 | P53: 0 | Q53: 0 | R53: 0 | S53: 0 | T53: 95.80292 | U53: 0 | V53: 0 | W53: 0 | X53: 13.686131 | Y53: 36.49635 | Z53: 0 | AA53: 20.437956
A54: Olmos | E54: {=400*Formula!B8:X8} -> 90.845563 | F54: 125.78616 | G54: 104.8218 | H54: 20.964361 | I54: 0 | J54: 0 | K54: 0 | L54: 0 | M54: 41.928721 | N54: 0 | O54: 0 | P54: 0 | Q54: 0 | R54: 0 | S54: 0 | T54: 0 | U54: 0 | V54: 0 | W54: 0 | X54: 0 | Y54: 0 | Z54: 14.814815 | AA54: 0.83857442
A55: Sanchez Carrión | E55: {=400*Formula!B9:X9} -> 25.08 | F55: 163.64 | G55: 0 | H55: 45.44 | I55: 31.84 | J55: 45.44 | K55: 0 | L55: 68.2 | M55: 0 | N55: 0 | O55: 0 | P55: 0 | Q55: 0 | R55: 0 | S55: 0 | T55: 0 | U55: 0 | V55: 0 | W55: 0 | X55: 0 | Y55: 0 | Z55: 19.28 | AA55: 1.08
A56: Viru | E56: {=400*Formula!B10:X10} -> 52.08 | F56: 89.76 | G56: 179.52 | H56: 0 | I56: 40.8 | J56: 0 | K56: 0 | L56: 0 | M56: 0 | N56: 0 | O56: 7.36 | P56: 0 | Q56: 0 | R56: 0 | S56: 0 | T56: 0 | U56: 4.08 | V56: 4.08 | W56: 4.08 | X56: 0 | Y56: 0 | Z56: 17.28 | AA56: 0.96
D59: =D24-4800-4400 -> 107.38739 | E59: {=_xlfn.ANCHORARRAY(E55)/400*D59} -> 6.7331892 | F59: 43.93218 | G59: 0 | H59: 12.199207 | I59: 8.548036 | J59: 12.199207 | K59: 0 | L59: 18.30955 | M59: 0 | N59: 0 | O59: 0 | P59: 0 | Q59: 0 | R59: 0 | S59: 0 | T59: 0 | U59: 0 | V59: 0 | W59: 0 | X59: 0 | Y59: 0 | Z59: 5.1760721 | AA59: 0.28994595

Sheet Laminado
A1: Municipalidad | B1: Cantidad (Kg) | C1: Fecha | D1: Avena | E1: Quinua | F1: Kiwicha
A2: {=Mezclado!A2:C41} -> Sanchez Carrión | B2: 9298.08 | C2: 45987 | D2: {=IF(ISNUMBER(MATCH(Mezclado!$A2, _xlfn._xlws.FILTER(Procesos!$A$2:$A$23, Procesos!B$2:B$23="Laminado"), 0)), Mezclado!E2/(1-Formula!$B$18),0)} -> 585.32918 | E2: {=IF(ISNUMBER(MATCH(Mezclado!$A2, _xlfn._xlws.FILTER(Procesos!$A$2:$A$23, Procesos!C$2:C$23="Laminado"), 0)), Mezclado!F2/(1-Formula!$B$18),0)} -> 3819.1095 | F2: {=IF(ISNUMBER(MATCH(Mezclado!$A2, _xlfn._xlws.FILTER(Procesos!$A$2:$A$23, Procesos!D$2:D$23="Laminado"), 0)), Mezclado!G2/(1-Formula!$B$18),0)} -> 0
A3: Olmos | B3: 11040 | C3: 46036 | D3: {=IF(ISNUMBER(MATCH(Mezclado!$A3, _xlfn._xlws.FILTER(Procesos!$A$2:$A$23, Procesos!B$2:B$23="Laminado"), 0)), Mezclado!E3/(1-Formula!$B$18),0)} -> 2517.3996 | E3: {=IF(ISNUMBER(MATCH(Mezclado!$A3, _xlfn._xlws.FILTER(Procesos!$A$2:$A$23, Procesos!C$2:C$23="Laminado"), 0)), Mezclado!F3/(1-Formula!$B$18),0)} -> 3485.6302 | F3: {=IF(ISNUMBER(MATCH(Mezclado!$A3, _xlfn._xlws.FILTER(Procesos!$A$2:$A$23, Procesos!D$2:D$23="Laminado"), 0)), Mezclado!G3/(1-Formula!$B$18),0)} -> 0
A4: Sanchez Carrión | B4: 9467.04 | C4: 46036 | D4: {=IF(ISNUMBER(MATCH(Mezclado!$A4, _xlfn._xlws.FILTER(Procesos!$A$2:$A$23, Procesos!B$2:B$23="Laminado"), 0)), Mezclado!E4/(1-Formula!$B$18),0)} -> 595.96548 | E4: {=IF(ISNUMBER(MATCH(Mezclado!$A4, _xlfn._xlws.FILTER(Procesos!$A$2:$A$23, Procesos!C$2:C$23="Laminado"), 0)), Mezclado!F4/(1-Formula!$B$18),0)} -> 3888.5084 | F4: {=IF(ISNUMBER(MATCH(Mezclado!$A4, _xlfn._xlws.FILTER(Procesos!$A$2:$A$23, Procesos!D$2:D$23="Laminado"), 0)), Mezclado!G4/(1-Formula!$B$18),0)} -> 0
A5: Hualgayoc | B5: 11906.242 | C5: 46038 | D5: {=IF(ISNUMBER(MATCH(Mezclado!$A5, _xlfn._xlws.FILTER(Procesos!$A$2:$A$23, Procesos!B$2:B$23="Laminado"), 0)), Mezclado!E5/(1-Formula!$B$18),0)} -> 1536.0918 | E5: {=IF(ISNUMBER(MATCH(Mezclado!$A5, _xlfn._xlws.FILTER(Procesos!$A$2:$A$23, Procesos!C$2:C$23="Laminado"), 0)), Mezclado!F5/(1-Formula!$B$18),0)} -> 2586.8503 | F5: {=IF(ISNUMBER(MATCH(Mezclado!$A5, _xlfn._xlws.FILTER(Procesos!$A$2:$A$23, Procesos!D$2:D$23="Laminado"), 0)), Mezclado!G5/(1-Formula!$B$18),0)} -> 3986.6663
A6: Viru | B6: 5850 | C6: 46038 | D6: {=IF(ISNUMBER(MATCH(Mezclado!$A6, _xlfn._xlws.FILTER(Procesos!$A$2:$A$23, Procesos!B$2:B$23="Laminado"), 0)), Mezclado!E6/(1-Formula!$B$18),0)} -> 764.72661 | E6: {=IF(ISNUMBER(MATCH(Mezclado!$A6, _xlfn._xlws.FILTER(Procesos!$A$2:$A$23, Procesos!C$2:C$23="Laminado"), 0)), Mezclado!F6/(1-Formula!$B$18),0)} -> 1318.0081 | F6: {=IF(ISNUMBER(MATCH(Mezclado!$A6, _xlfn._xlws.FILTER(Procesos!$A$2:$A$23, Procesos!D$2:D$23="Laminado"), 0)), Mezclado!G6/(1-Formula!$B$18),0)} -> 2636.0162
A7: Florencia de Mora | B7: 4281.8336 | C7: 46044 | D7: {=IF(ISNUMBER(MATCH(Mezclado!$A7, _xlfn._xlws.FILTER(Procesos!$A$2:$A$23, Procesos!B$2:B$23="Laminado"), 0)), Mezclado!E7/(1-Formula!$B$18),0)} -> 728.02994 | E7: {=IF(ISNUMBER(MATCH(Mezclado!$A7, _xlfn._xlws.FILTER(Procesos!$A$2:$A$23, Procesos!C$2:C$23="Laminado"), 0)), Mezclado!F7/(1-Formula!$B$18),0)} -> 1729.0711 | F7: {=IF(ISNUMBER(MATCH(Mezclado!$A7, _xlfn._xlws.FILTER(Procesos!$A$2:$A$23, Procesos!D$2:D$23="Laminado"), 0)), Mezclado!G7/(1-Formula!$B$18),0)} -> 1638.0674
A8: Olmos | B8: 11058 | C8: 46055 | D8: {=IF(ISNUMBER(MATCH(Mezclado!$A8, _xlfn._xlws.FILTER(Procesos!$A$2:$A$23, Procesos!B$2:B$23="Laminado"), 0)), Mezclado!E8/(1-Formula!$B$18),0)} -> 2521.504 | E8: {=IF(ISNUMBER(MATCH(Mezclado!$A8, _xlfn._xlws.FILTER(Procesos!$A$2:$A$23, Procesos!C$2:C$23="Laminado"), 0)), Mezclado!F8/(1-Formula!$B$18),0)} -> 3491.3133 | F8: {=IF(ISNUMBER(MATCH(Mezclado!$A8, _xlfn._xlws.FILTER(Procesos!$A$2:$A$23, Procesos!D$2:D$23="Laminado"), 0)), Mezclado!G8/(1-Formula!$B$18),0)} -> 0
A9: Cajatambo | B9: 1042 | C9: 46060 | D9: {=IF(ISNUMBER(MATCH(Mezclado!$A9, _xlfn._xlws.FILTER(Procesos!$A$2:$A$23, Procesos!B$2:B$23="Laminado"), 0)), Mezclado!E9/(1-Formula!$B$18),0)} -> 371.49908 | E9: {=IF(ISNUMBER(MATCH(Mezclado!$A9, _xlfn._xlws.FILTER(Procesos!$A$2:$A$23, Procesos!C$2:C$23="Laminado"), 0)), Mezclado!F9/(1-Formula!$B$18),0)} -> 123.8679 | F9: {=IF(ISNUMBER(MATCH(Mezclado!$A9, _xlfn._xlws.FILTER(Procesos!$A$2:$A$23, Procesos!D$2:D$23="Laminado"), 0)), Mezclado!G9/(1-Formula!$B$18),0)} -> 123.8679
A10: Encañada | B10: 21119.28 | C10: 46073 | D10: {=IF(ISNUMBER(MATCH(Mezclado!$A10, _xlfn._xlws.FILTER(Procesos!$A$2:$A$23, Procesos!B$2:B$23="Laminado"), 0)), Mezclado!E10/(1-Formula!$B$18),0)} -> 4264.1309 | E10: {=IF(ISNUMBER(MATCH(Mezclado!$A10, _xlfn._xlws.FILTER(Procesos!$A$2:$A$23, Procesos!C$2:C$23="Laminado"), 0)), Mezclado!F10/(1-Formula!$B$18),0)} -> 4164.472 | F10: {=IF(ISNUMBER(MATCH(Mezclado!$A10, _xlfn._xlws.FILTER(Procesos!$A$2:$A$23, Procesos!D$2:D$23="Laminado"), 0)), Mezclado!G10/(1-Formula!$B$18),0)} -> 9465.4801
A11: Moyobamba | B11: 9322 | C11: 46083 | D11: {=IF(ISNUMBER(MATCH(Mezclado!$A11, _xlfn._xlws.FILTER(Procesos!$A$2:$A$23, Procesos!B$2:B$23="Laminado"), 0)), Mezclado!E11/(1-Formula!$B$18),0)} -> 3287.7488 | E11: {=IF(ISNUMBER(MATCH(Mezclado!$A11, _xlfn._xlws.FILTER(Procesos!$A$2:$A$23, Procesos!C$2:C$23="Laminado"), 0)), Mezclado!F11/(1-Formula!$B$18),0)} -> 0 | F11: {=IF(ISNUMBER(MATCH(Mezclado!$A11, _xlfn._xlws.FILTER(Procesos!$A$2:$A$23, Procesos!D$2:D$23="Laminado"), 0)), Mezclado!G11/(1-Formula!$B$18),0)} -> 0
A12: Olmos | B12: 5611 | C12: 46085 | D12: {=IF(ISNUMBER(MATCH(Mezclado!$A12, _xlfn._xlws.FILTER(Procesos!$A$2:$A$23, Procesos!B$2:B$23="Laminado"), 0)), Mezclado!E12/(1-Formula!$B$18),0)} -> 1279.4501 | E12: {=IF(ISNUMBER(MATCH(Mezclado!$A12, _xlfn._xlws.FILTER(Procesos!$A$2:$A$23, Procesos!C$2:C$23="Laminado"), 0)), Mezclado!F12/(1-Formula!$B$18),0)} -> 1771.5463 | F12: {=IF(ISNUMBER(MATCH(Mezclado!$A12, _xlfn._xlws.FILTER(Procesos!$A$2:$A$23, Procesos!D$2:D$23="Laminado"), 0)), Mezclado!G12/(1-Formula!$B$18),0)} -> 0
A13: Cajatambo | B13: 1042 | C13: 46086 | D13: {=IF(ISNUMBER(MATCH(Mezclado!$A13, _xlfn._xlws.FILTER(Procesos!$A$2:$A$23, Procesos!B$2:B$23="Laminado"), 0)), Mezclado!E13/(1-Formula!$B$18),0)} -> 371.49908 | E13: {=IF(ISNUMBER(MATCH(Mezclado!$A13, _xlfn._xlws.FILTER(Procesos!$A$2:$A$23, Procesos!C$2:C$23="Laminado"), 0)), Mezclado!F13/(1-Formula!$B$18),0)} -> 123.8679 | F13: {=IF(ISNUMBER(MATCH(Mezclado!$A13, _xlfn._xlws.FILTER(Procesos!$A$2:$A$23, Procesos!D$2:D$23="Laminado"), 0)), Mezclado!G13/(1-Formula!$B$18),0)} -> 123.8679
A14: Hualgayoc | B14: 11906.242 | C14: 46094 | D14: {=IF(ISNUMBER(MATCH(Mezclado!$A14, _xlfn._xlws.FILTER(Procesos!$A$2:$A$23, Procesos!B$2:B$23="Laminado"), 0)), Mezclado!E14/(1-Formula!$B$18),0)} -> 1536.0918 | E14: {=IF(ISNUMBER(MATCH(Mezclado!$A14, _xlfn._xlws.FILTER(Procesos!$A$2:$A$23, Procesos!C$2:C$23="Laminado"), 0)), Mezclado!F14/(1-Formula!$B$18),0)} -> 2586.8503 | F14: {=IF(ISNUMBER(MATCH(Mezclado!$A14, _xlfn._xlws.FILTER(Procesos!$A$2:$A$23, Procesos!D$2:D$23="Laminado"), 0)), Mezclado!G14/(1-Formula!$B$18),0)} -> 3986.6663
... A41: Alto Trujillo | B41: 3018.9826 | C41: 46251 | D41: {=IF(ISNUMBER(MATCH(Mezclado!$A41, _xlfn._xlws.FILTER(Procesos!$A$2:$A$23, Procesos!B$2:B$23="Laminado"), 0)), Mezclado!E41/(1-Formula!$B$18),0)} -> 160.9513 | E41: {=IF(ISNUMBER(MATCH(Mezclado!$A41, _xlfn._xlws.FILTER(Procesos!$A$2:$A$23, Procesos!C$2:C$23="Laminado"), 0)), Mezclado!F41/(1-Formula!$B$18),0)} -> 823.54929 | F41: {=IF(ISNUMBER(MATCH(Mezclado!$A41, _xlfn._xlws.FILTER(Procesos!$A$2:$A$23, Procesos!D$2:D$23="Laminado"), 0)), Mezclado!G41/(1-Formula!$B$18),0)} -> 1938.084
D66: =D25/500*60 -> 94.841787 | E66: =E25/500*60 -> 163.46004 | F66: =F25-2000 -> 724.33396
F67: =F66*0.997 -> 722.16096

Sheet Molido
A1: Municipalidad | B1: Cantidad (Kg) | C1: Fecha | D1: Kiwicha | E1: Soya | F1: Sacha Inchi | G1: Maiz Chufla | H1: Chia | I1: Garbanzo
A2: {=Mezclado!A2:C41} -> Sanchez Carrión | B2: 9298.08 | C2: 45987 | D2: {=IF(ISNUMBER(MATCH(Mezclado!$A2, _xlfn._xlws.FILTER(Procesos!$A$2:$A$23, Procesos!D$2:D$23="Molido"), 0)), Mezclado!G2/(1-Formula!$B$17),0)} -> 0 | E2: {=Mezclado!H2:H41/(1-Formula!$B$17)} -> 1078.8972 | F2: {=Mezclado!K2:K41/(1-Formula!$B$17)} -> 0 | G2: {=Mezclado!L2:L41/(1-Formula!$B$17)} -> 1619.2955 | H2: {=Mezclado!P2:P41/(1-Formula!$B$17)} -> 0 | I2: {=Mezclado!R2:R41/(1-Formula!$B$17)} -> 0
A3: Olmos | B3: 11040 | C3: 46036 | D3: {=IF(ISNUMBER(MATCH(Mezclado!$A3, _xlfn._xlws.FILTER(Procesos!$A$2:$A$23, Procesos!D$2:D$23="Molido"), 0)), Mezclado!G3/(1-Formula!$B$17),0)} -> 2955.0793 | E3: 591.01587 | F3: 0 | G3: 0 | H3: 0 | I3: 0
A4: Sanchez Carrión | B4: 9467.04 | C4: 46036 | D4: {=IF(ISNUMBER(MATCH(Mezclado!$A4, _xlfn._xlws.FILTER(Procesos!$A$2:$A$23, Procesos!D$2:D$23="Molido"), 0)), Mezclado!G4/(1-Formula!$B$17),0)} -> 0 | E4: 1098.5023 | F4: 0 | G4: 1648.7205 | H4: 0 | I4: 0
A5: Hualgayoc | B5: 11906.242 | C5: 46038 | D5: {=IF(ISNUMBER(MATCH(Mezclado!$A5, _xlfn._xlws.FILTER(Procesos!$A$2:$A$23, Procesos!D$2:D$23="Molido"), 0)), Mezclado!G5/(1-Formula!$B$17),0)} -> 0 | E5: 109.45249 | F5: 0 | G5: 0 | H5: 0 | I5: 87.56199
A6: Viru | B6: 5850 | C6: 46038 | D6: {=IF(ISNUMBER(MATCH(Mezclado!$A6, _xlfn._xlws.FILTER(Procesos!$A$2:$A$23, Procesos!D$2:D$23="Molido"), 0)), Mezclado!G6/(1-Formula!$B$17),0)} -> 0 | E6: 0 | F6: 0 | G6: 0 | H6: 0 | I6: 0
A7: Florencia de Mora | B7: 4281.8336 | C7: 46044 | D7: {=IF(ISNUMBER(MATCH(Mezclado!$A7, _xlfn._xlws.FILTER(Procesos!$A$2:$A$23, Procesos!D$2:D$23="Molido"), 0)), Mezclado!G7/(1-Formula!$B$17),0)} -> 0 | E7: 0 | F7: 0 | G7: 0 | H7: 0 | I7: 0
A8: Olmos | B8: 11058 | C8: 46055 | D8: {=IF(ISNUMBER(MATCH(Mezclado!$A8, _xlfn._xlws.FILTER(Procesos!$A$2:$A$23, Procesos!D$2:D$23="Molido"), 0)), Mezclado!G8/(1-Formula!$B$17),0)} -> 2959.8974 | E8: 591.97948 | F8: 0 | G8: 0 | H8: 0 | I8: 0
A9: Cajatambo | B9: 1042 | C9: 46060 | D9: {=IF(ISNUMBER(MATCH(Mezclado!$A9, _xlfn._xlws.FILTER(Procesos!$A$2:$A$23, Procesos!D$2:D$23="Molido"), 0)), Mezclado!G9/(1-Formula!$B$17),0)} -> 0 | E9: 0 | F9: 0 | G9: 0 | H9: 0 | I9: 0
A10: Encañada | B10: 21119.28 | C10: 46073 | D10: {=IF(ISNUMBER(MATCH(Mezclado!$A10, _xlfn._xlws.FILTER(Procesos!$A$2:$A$23, Procesos!D$2:D$23="Molido"), 0)), Mezclado!G10/(1-Formula!$B$17),0)} -> 0 | E10: 0 | F10: 0 | G10: 0 | H10: 386.13625 | I10: 0
A11: Moyobamba | B11: 9322 | C11: 46083 | D11: {=IF(ISNUMBER(MATCH(Mezclado!$A11, _xlfn._xlws.FILTER(Procesos!$A$2:$A$23, Procesos!D$2:D$23="Molido"), 0)), Mezclado!G11/(1-Formula!$B$17),0)} -> 0 | E11: 0 | F11: 1129.4066 | G11: 0 | H11: 0 | I11: 0
A12: Olmos | B12: 5611 | C12: 46085 | D12: {=IF(ISNUMBER(MATCH(Mezclado!$A12, _xlfn._xlws.FILTER(Procesos!$A$2:$A$23, Procesos!D$2:D$23="Molido"), 0)), Mezclado!G12/(1-Formula!$B$17),0)} -> 1501.8977 | E12: 300.37953 | F12: 0 | G12: 0 | H12: 0 | I12: 0
A13: Cajatambo | B13: 1042 | C13: 46086 | D13: {=IF(ISNUMBER(MATCH(Mezclado!$A13, _xlfn._xlws.FILTER(Procesos!$A$2:$A$23, Procesos!D$2:D$23="Molido"), 0)), Mezclado!G13/(1-Formula!$B$17),0)} -> 0 | E13: 0 | F13: 0 | G13: 0 | H13: 0 | I13: 0
A14: Hualgayoc | B14: 11906.242 | C14: 46094 | D14: {=IF(ISNUMBER(MATCH(Mezclado!$A14, _xlfn._xlws.FILTER(Procesos!$A$2:$A$23, Procesos!D$2:D$23="Molido"), 0)), Mezclado!G14/(1-Formula!$B$17),0)} -> 0 | E14: 109.45249 | F14: 0 | G14: 0 | H14: 0 | I14: 87.56199
... A41: Alto Trujillo | B41: 3018.9826 | C41: 46251 | D41: {=IF(ISNUMBER(MATCH(Mezclado!$A41, _xlfn._xlws.FILTER(Procesos!$A$2:$A$23, Procesos!D$2:D$23="Molido"), 0)), Mezclado!G41/(1-Formula!$B$17),0)} -> 0 | E41: 0 | F41: 0 | G41: 0 | H41: 0 | I41: 0

Sheet Tostado
A1: Municipalidad | B1: Cantidad (Kg) | C1: Fecha | D1: Quinua | E1: Kiwicha | F1: Soya | G1: Sacha Inchi | H1: Maiz Chufla | I1: Garbanzo
A2: {=Mezclado!A2:C41} -> Sanchez Carrión | B2: 9298.08 | C2: 45987 | D2: 0 | E2: 0 | F2: {=Molido!E2:E41/(1-Formula!$B$16)} -> 1112.2651 | G2: {=Molido!F2:F41/(1-Formula!$B$16)} -> 0 | H2: {=Molido!G2:G41/(1-Formula!$B$16)} -> 1669.3768 | I2: {=Molido!I2:I41/(1-Formula!$B$16)} -> 0
A3: Olmos | B3: 11040 | C3: 46036 | D3: 0 | E3: 0 | F3: 609.29471 | G3: 0 | H3: 0 | I3: 0
A4: Sanchez Carrión | B4: 9467.04 | C4: 46036 | D4: 0 | E4: 0 | F4: 1132.4766 | G4: 0 | H4: 1699.7118 | I4: 0
A5: Hualgayoc | B5: 11906.242 | C5: 46038 | D5: 0 | E5: =Laminado!F5/(1-Formula!$B$16) -> 4109.9652 | F5: 112.83762 | G5: 0 | H5: 0 | I5: 90.270093
A6: Viru | B6: 5850 | C6: 46038 | D6: 0 | E6: 0 | F6: 0 | G6: 0 | H6: 0 | I6: 0
A7: Florencia de Mora | B7: 4281.8336 | C7: 46044 | D7: 0 | E7: =Laminado!F7/(1-Formula!$B$16) -> 1688.7292 | F7: 0 | G7: 0 | H7: 0 | I7: 0
A8: Olmos | B8: 11058 | C8: 46055 | D8: 0 | E8: =Laminado!F8/(1-Formula!$B$16) -> 0 | F8: 610.28812 | G8: 0 | H8: 0 | I8: 0
A9: Cajatambo | B9: 1042 | C9: 46060 | D9: =Laminado!E9/(1-Formula!$B$16) -> 127.69887 | E9: =Laminado!F9/(1-Formula!$B$16) -> 127.69887 | F9: 0 | G9: 0 | H9: 0 | I9: 0
A10: Encañada | B10: 21119.28 | C10: 46073 | D10: =Laminado!E10/(1-Formula!$B$16) -> 4293.2701 | E10: =Laminado!F10/(1-Formula!$B$16) -> 9758.2269 | F10: 0 | G10: 0 | H10: 0 | I10: 0
A11: Moyobamba | B11: 9322 | C11: 46083 | D11: 0 | E11: =Laminado!F11/(1-Formula!$B$16) -> 0 | F11: 0 | G11: 1164.3367 | H11: 0 | I11: 0
A12: Olmos | B12: 5611 | C12: 46085 | D12: 0 | E12: =Laminado!F12/(1-Formula!$B$16) -> 0 | F12: 309.66962 | G12: 0 | H12: 0 | I12: 0
A13: Cajatambo | B13: 1042 | C13: 46086 | D13: 0 | E13: =Laminado!F13/(1-Formula!$B$16) -> 127.69887 | F13: 0 | G13: 0 | H13: 0 | I13: 0
A14: Hualgayoc | B14: 11906.242 | C14: 46094 | D14: 0 | E14: =Laminado!F14/(1-Formula!$B$16) -> 4109.9652 | F14: 112.83762 | G14: 0 | H14: 0 | I14: 90.270093
A15: Alto Trujillo | B15: 3018.04 | C15: 46097 | D15: 0 | E15: 0 | F15: 0 | G15: 0 | H15: 0 | I15: 0
A16: Sanchez Carrión | B16: 9467.04 | C16: 46097 | D16: 0 | E16: 0 | F16: 1132.4766 | G16: 0 | H16: 1699.7118 | I16: 0
A17: Viru | B17: 6046 | C17: 46097 | D17: 0 | E17: 0 | F17: 0 | G17: 0 | H17: 0 | I17: 0
A18: Florencia de Mora | B18: 4281.8336 | C18: 46100 | D18: 0 | E18: =Laminado!F18/(1-Formula!$B$16) -> 1688.7292 | F18: 0 | G18: 0 | H18: 0 | I18: 0
A19: Encañada | B19: 21119.28 | C19: 46101 | D19: =Laminado!E19/(1-Formula!$B$16) -> 4293.2701 | E19: =Laminado!F19/(1-Formula!$B$16) -> 9758.2269 | F19: 0 | G19: 0 | H19: 0 | I19: 0
A20: Olmos | B20: 5840 | C20: 46115 | D20: 0 | E20: 0 | F20: 322.30807 | G20: 0 | H20: 0 | I20: 0
A21: Alto Trujillo | B21: 3018.04 | C21: 46129 | D21: 0 | E21: 0 | F21: 0 | G21: 0 | H21: 0 | I21: 0
A22: Moyobamba | B22: 9139 | C22: 46129 | D22: 0 | E22: 0 | F22: 0 | G22: 1141.4797 | H22: 0 | I22: 0
A23: Olmos | B23: 5611 | C23: 46146 | D23: 0 | E23: 0 | F23: 309.66962 | G23: 0 | H23: 0 | I23: 0
A24: Sanchez Carrión | B24: 9298.08 | C24: 46150 | D24: 0 | E24: 0 | F24: 1112.2651 | G24: 0 | H24: 1669.3768 | I24: 0
A25: Viru | B25: 6046 | C25: 46157 | D25: 0 | E25: 0 | F25: 0 | G25: 0 | H25: 0 | I25: 0
A26: Cajatambo | B26: 1016 | C26: 46174 | D26: 0 | E26: 0 | F26: 0 | G26: 0 | H26: 0 | I26: 0
A27: Olmos | B27: 5840 | C27: 46174 | D27: 0 | E27: 0 | F27: 322.30807 | G27: 0 | H27: 0 | I27: 0
A28: Encañada | B28: 21119.28 | C28: 46175 | D28: =Laminado!E28/(1-Formula!$B$16) -> 4293.2701 | E28: 0 | F28: 0 | G28: 0 | H28: 0 | I28: 0
A29: Hualgayoc | B29: 11906.24 | C29: 46179 | D29: 0 | E29: 0 | F29: 112.8376 | G29: 0 | H29: 0 | I29: 90.270081
A30: Alto Trujillo | B30: 3018.9826 | C30: 46188 | D30: 0 | E30: 0 | F30: 0 | G30: 0 | H30: 0 | I30: 0
A31: Sanchez Carrión | B31: 9298.08 | C31: 46214 | D31: 0 | E31: 0 | F31: 1112.2651 | G31: 0 | H31: 1669.3768 | I31: 0
A32: Alto Trujillo | B32: 3018.9826 | C32: 46218 | D32: 0 | E32: 0 | F32: 0 | G32: 0 | H32: 0 | I32: 0
A33: Florencia de Mora | B33: 4281.8336 | C33: 46218 | D33: 0 | E33: =Laminado!F33/(1-Formula!$B$16) -> 1688.7292 | F33: 0 | G33: 0 | H33: 0 | I33: 0
A34: Encañada | B34: 21119.28 | C34: 46192 | D34: =Laminado!E34/(1-Formula!$B$16) -> 4293.2701 | E34: =Laminado!F34/(1-Formula!$B$16) -> 9758.2269 | F34: 0 | G34: 0 | H34: 0 | I34: 0
A35: Moyobamba | B35: 9294 | C35: 46197 | D35: 0 | E35: 0 | F35: 0 | G35: 1160.8395 | H35: 0 | I35: 0
A36: Viru | B36: 6046 | C36: 46216 | D36: 0 | E36: 0 | F36: 0 | G36: 0 | H36: 0 | I36: 0
A37: Alto Trujillo | B37: 3759.21 | C37: 46235 | D37: 0 | E37: 0 | F37: 0 | G37: 0 | H37: 0 | I37: 0
A38: Olmos | B38: 5611 | C38: 46238 | D38: 0 | E38: 0 | F38: 309.66962 | G38: 0 | H38: 0 | I38: 0
A39: Viru | B39: 13579 | C39: 46248 | D39: 0 | E39: 0 | F39: 0 | G39: 0 | H39: 0 | I39: 0
A40: Sanchez Carrión | B40: 3743.92 | C40: 46249 | D40: 0 | E40: 0 | F40: 447.8593 | G40: 0 | H40: 672.18319 | I40: 0
...

Sheet Deshidratado
A1: Municipalidad | B1: Cantidad (Kg) | C1: Fecha | D1: Maca Deshidratada | E1: Maca | F1: Cacao
A2: {=Mezclado!A2:C26} -> Sanchez Carrión | B2: 9298.08 | C2: 45987 | D2: {=IF(Mezclado!I2:I26>300, Mezclado!I2:I26, 0)} -> 740.86804 | E2: {=IF(Mezclado!I2:I26>300, 0,Mezclado!I2:I26/(1-Formula!$B$15))} -> 0 | F2: {=_xlfn.ANCHORARRAY(Molido!H2)} -> 0
A3: Olmos | B3: 11040 | C3: 46036 | D3: 0 | E3: 0 | F3: 0
A4: Sanchez Carrión | B4: 9467.04 | C4: 46036 | D4: 754.33071 | E4: 0 | F4: 0
A5: Hualgayoc | B5: 11906.242 | C5: 46038 | D5: 1504.0718 | E5: 0 | F5: 0
A6: Viru | B6: 5850 | C6: 46038 | D6: 597.2973 | E6: 0 | F6: 0
A7: Florencia de Mora | B7: 4281.8336 | C7: 46044 | D7: 0 | E7: 0 | F7: 0
A8: Olmos | B8: 11058 | C8: 46055 | D8: 0 | E8: 0 | F8: 0
A9: Cajatambo | B9: 1042 | C9: 46060 | D9: 370.38458 | E9: 0 | F9: 0
A10: Encañada | B10: 21119.28 | C10: 46073 | D10: 1133.1265 | E10: 0 | F10: 386.13625
A11: Moyobamba | B11: 9322 | C11: 46083 | D11: 0 | E11: 0 | F11: 0
A12: Olmos | B12: 5611 | C12: 46085 | D12: 0 | E12: 0 | F12: 0
A13: Cajatambo | B13: 1042 | C13: 46086 | D13: 370.38458 | E13: 0 | F13: 0
A14: Hualgayoc | B14: 11906.242 | C14: 46094 | D14: 1504.0718 | E14: 0 | F14: 0
... A26: Cajatambo | B26: 1016 | C26: 46174 | D26: 361.14274 | E26: 0 | F26: 0
F27: 0
F28: 386.13625
F29: 0
F30: 0
F31: 0
F32: 0
F33: 0
F34: 386.13625
F35: 0
F36: 0
F37: 0
F38: 0
... F41: 0
E78: =E35/40 -> 0
E79: =E78-14 -> -14
E80: =E79*240 -> -3360

Sheet Materia Prima
A1: Municipalidad | B1: Cantidad (Kg) | C1: Fecha | D1: Avena | E1: Quinua Precocida | F1: Quinua Desaponificada | G1: Quinua | H1: Kiwicha Precocida | I1: Kiwicha | J1: Soya | K1: Maca Deshidratada | L1: {=Mezclado!J1:AA1} -> Azucar | M1: Sacha Inchi | N1: Maiz Chufla | O1: Leche Polvo | P1: Aceite soya | Q1: Aceite Girasol | R1: Chia | S1: Cacao Deshidratado | T1: Garbanzo | U1: Tarhui | V1: Almidon maca | W1: Linaza | X1: Ajonjoli | Y1: Proteina aislada soya | Z1: Albumina clara de huevo | AA1: Harina de Plátano | AB1: Fosfato Tricálcio | AC1: Mix vitaminico
A2: {=General!A2:A41} -> Sanchez Carrión | B2: {=General!F2:G41} -> 9298.08 | C2: 45987 | D2: {=Laminado!D2:D41} -> 585.32918 | E2: 0 | F2: {=IF(Laminado!E2:E9>500, Laminado!E2:E9, 0)} -> 3819.1095 | G2: {=IF(Laminado!E2:E41<500, Laminado!E2:E41, 0)/0.93} -> 0 | H2: 0 | I2: =Laminado!F2+Molido!D2 -> 0 | J2: {=_xlfn.ANCHORARRAY(Tostado!F2)} -> 1112.2651 | K2: {=Mezclado!I2:I41} -> 740.86804 | L2: {=Mezclado!J2:J41} -> 1057.3192 | M2: {=_xlfn.ANCHORARRAY(Tostado!G2)} -> 0 | N2: {=_xlfn.ANCHORARRAY(Tostado!H2)} -> 1669.3768 | O2: {=Mezclado!M2:M41} -> 0 | P2: {=Mezclado!N2:N41} -> 0 | Q2: {=Mezclado!O2:O41} -> 0 | R2: {=Mezclado!P2:P41} -> 0 | S2: {=Mezclado!Q2:Q41} -> 0 | T2: {=_xlfn.ANCHORARRAY(Tostado!I2)} -> 0 | U2: {=Mezclado!S2:S41} -> 0 | V2: {=Mezclado!T2:T41} -> 0 | W2: {=Mezclado!U2:U41} -> 0 | X2: {=Mezclado!V2:V41} -> 0 | Y2: {=Mezclado!W2:W41} -> 0 | Z2: {=Mezclado!X2:X41} -> 0 | AA2: {=Mezclado!Y2:Y41} -> 0 | AB2: {=Mezclado!Z2:Z41} -> 448.61607 | AC2: {=Mezclado!AA2:AA41} -> 25.129946
A3: Olmos | B3: 11040 | C3: 46036 | D3: 2517.3996 | E3: 0 | F3: 3485.6302 | G3: 0 | H3: 0 | I3: =Laminado!F3+Molido!D3 -> 2955.0793 | J3: 609.29471 | K3: 0 | L3: 0 | M3: 0 | N3: 0 | O3: 1158.3911 | P3: 0 | Q3: 0 | R3: 0 | S3: 0 | T3: 0 | U3: 0 | V3: 0 | W3: 0 | X3: 0 | Y3: 0 | Z3: 0 | AA3: 0 | AB3: 409.29819 | AC3: 23.167822
A4: Sanchez Carrión | B4: 9467.04 | C4: 46036 | D4: 595.96548 | E4: 0 | F4: 3888.5084 | G4: 0 | H4: 0 | I4: =Laminado!F4+Molido!D4 -> 0 | J4: 1132.4766 | K4: 754.33071 | L4: 1076.5323 | M4: 0 | N4: 1699.7118 | O4: 0 | P4: 0 | Q4: 0 | R4: 0 | S4: 0 | T4: 0 | U4: 0 | V4: 0 | W4: 0 | X4: 0 | Y4: 0 | Z4: 0 | AA4: 0 | AB4: 456.7681 | AC4: 25.586595
A5: Hualgayoc | B5: 11906.242 | C5: 46038 | D5: 1536.0918 | E5: 0 | F5: 2586.8503 | G5: 0 | H5: =Laminado!F5 -> 3986.6663 | I5: 0 | J5: 112.83762 | K5: 1504.0718 | L5: 0 | M5: 0 | N5: 0 | O5: 1396.8083 | P5: 171.6215 | Q5: 0 | R5: 0 | S5: 0 | T5: 90.270093 | U5: 85.81075 | V5: 0 | W5: 0 | X5: 0 | Y5: 0 | Z5: 0 | AA5: 0 | AB5: 455.2737 | AC5: 26.219952
A6: Viru | B6: 5850 | C6: 46038 | D6: 764.72661 | E6: 0 | F6: 1318.0081 | G6: 0 | H6: 0 | I6: =Laminado!F6+Molido!D6 -> 2636.0162 | J6: 0 | K6: 597.2973 | L6: 0 | M6: 0 | N6: 0 | O6: 0 | P6: 0 | Q6: 107.74775 | R6: 0 | S6: 0 | T6: 0 | U6: 0 | V6: 0 | W6: 59.72973 | X6: 59.72973 | Y6: 59.72973 | Z6: 0 | AA6: 0 | AB6: 252.97297 | AC6: 14.054054
A7: Florencia de Mora | B7: 4281.8336 | C7: 46044 | D7: 728.02994 | E7: 0 | F7: 1729.0711 | G7: 0 | H7: =Laminado!F7 -> 1638.0674 | I7: 0 | J7: 0 | K7: 0 | L7: 0 | M7: 0 | N7: 0 | O7: 0 | P7: 0 | Q7: 0 | R7: 0 | S7: 0 | T7: 0 | U7: 0 | V7: 0 | W7: 0 | X7: 0 | Y7: 0 | Z7: 0 | AA7: 0 | AB7: 192.34915 | AC7: 10.887688
A8: Olmos | B8: 11058 | C8: 46055 | D8: 2521.504 | E8: 0 | F8: 3491.3133 | G8: 0 | H8: 0 | I8: =Laminado!F8+Molido!D8 -> 2959.8974 | J8: 610.28812 | K8: 0 | L8: 0 | M8: 0 | N8: 0 | O8: 1160.2798 | P8: 0 | Q8: 0 | R8: 0 | S8: 0 | T8: 0 | U8: 0 | V8: 0 | W8: 0 | X8: 0 | Y8: 0 | Z8: 0 | AA8: 0 | AB8: 409.96552 | AC8: 23.205596
A9: Cajatambo | B9: 1042 | C9: 46060 | D9: 371.49908 | E9: 0 | F9: 0 | G9: 133.19129 | H9: 0 | I9: =Laminado!F9+Molido!D9 -> 123.8679 | J9: 0 | K9: 370.38458 | L9: 0 | M9: 0 | N9: 0 | O9: 0 | P9: 0 | Q9: 0 | R9: 0 | S9: 0 | T9: 0 | U9: 0 | V9: 0 | W9: 0 | X9: 0 | Y9: 0 | Z9: 0 | AA9: 0 | AB9: 52.360761 | AC9: 2.9205205
A10: Encañada | B10: 21119.28 | C10: 46073 | D10: 4264.1309 | E10: =Laminado!E10 -> 4164.472 | F10: 0 | G10: 0 | H10: =Laminado!F10 -> 9465.4801 | I10: 0 | J10: 0 | K10: 1133.1265 | L10: 0 | M10: 0 | N10: 0 | O10: 0 | P10: 0 | Q10: 0 | R10: 378.41353 | S10: 942.86275 | T10: 0 | U10: 0 | V10: 0 | W10: 0 | X10: 0 | Y10: 0 | Z10: 0 | AA10: 0 | AB10: 801.22193 | AC10: 44.394883
A11: Moyobamba | B11: 9322 | C11: 46083 | D11: 3287.7488 | E11: 0 | F11: {=IF(Laminado!E11:E18>500, Laminado!E11:E18, 0)} -> 0 | G11: 0 | H11: 0 | I11: =Laminado!F11+Molido!D11 -> 0 | J11: 0 | K11: 0 | L11: 1064.2486 | M11: 1164.3367 | N11: 0 | O11: 0 | P11: 0 | Q11: 0 | R11: 0 | S11: 0 | T11: 0 | U11: 0 | V11: 2234.922 | W11: 0 | X11: 0 | Y11: 0 | Z11: 319.27457 | AA11: 851.39884 | AB11: 0 | AC11: 476.78335
A12: Olmos | B12: 5611 | C12: 46085 | D12: 1279.4501 | E12: 0 | F12: 1771.5463 | G12: 0 | H12: 0 | I12: =Laminado!F12+Molido!D12 -> 1501.8977 | J12: 309.66962 | K12: 0 | L12: 0 | M12: 0 | N12: 0 | O12: 588.74388 | P12: 0 | Q12: 0 | R12: 0 | S12: 0 | T12: 0 | U12: 0 | V12: 0 | W12: 0 | X12: 0 | Y12: 0 | Z12: 0 | AA12: 0 | AB12: 208.02284 | AC12: 11.774878
A13: Cajatambo | B13: 1042 | C13: 46086 | D13: 371.49908 | E13: 0 | F13: 0 | G13: 133.19129 | H13: 0 | I13: =Laminado!F13+Molido!D13 -> 123.8679 | J13: 0 | K13: 370.38458 | L13: 0 | M13: 0 | N13: 0 | O13: 0 | P13: 0 | Q13: 0 | R13: 0 | S13: 0 | T13: 0 | U13: 0 | V13: 0 | W13: 0 | X13: 0 | Y13: 0 | Z13: 0 | AA13: 0 | AB13: 52.360761 | AC13: 2.9205205
A14: Hualgayoc | B14: 11906.242 | C14: 46094 | D14: 1536.0918 | E14: 0 | F14: 2586.8503 | G14: 0 | H14: =Laminado!F14 -> 3986.6663 | I14: 0 | J14: 112.83762 | K14: 1504.0718 | L14: 0 | M14: 0 | N14: 0 | O14: 1396.8083 | P14: 171.6215 | Q14: 0 | R14: 0 | S14: 0 | T14: 90.270093 | U14: 85.81075 | V14: 0 | W14: 0 | X14: 0 | Y14: 0 | Z14: 0 | AA14: 0 | AB14: 455.2737 | AC14: 26.219952
A15: Alto Trujillo | B15: 3018.04 | C15: 46097 | D15: 160.90105 | E15: 0 | F15: 823.29217 | G15: 0 | H15: 0 | I15: =Laminado!F15+Molido!D15 -> 1937.4789 | J15: 0 | K15: 0 | L15: 0 | M15: 0 | N15: 0 | O15: 0 | P15: 0 | Q15: 0 | R15: 0 | S15: 0 | T15: 0 | U15: 0 | V15: 0 | W15: 0 | X15: 0 | Y15: 0 | Z15: 0 | AA15: 0 | AB15: 102.41397 | AC15: 5.740016
A16: Sanchez Carrión | B16: 9467.04 | C16: 46097 | D16: 595.96548 | E16: 0 | F16: 3888.5084 | G16: 0 | H16: 0 | I16: =Laminado!F16+Molido!D16 -> 0 | J16: 1132.4766 | K16: 754.33071 | L16: 1076.5323 | M16: 0 | N16: 1699.7118 | O16: 0 | P16: 0 | Q16: 0 | R16: 0 | S16: 0 | T16: 0 | U16: 0 | V16: 0 | W16: 0 | X16: 0 | Y16: 0 | Z16: 0 | AA16: 0 | AB16: 456.7681 | AC16: 25.586595
A17: Viru | B17: 6046 | C17: 46097 | D17: 790.34822 | E17: 0 | F17: 1362.167 | G17: 0 | H17: 0 | I17: =Laminado!F17+Molido!D17 -> 2724.334 | J17: 0 | K17: 617.30931 | L17: 0 | M17: 0 | N17: 0 | O17: 0 | P17: 0 | Q17: 111.35776 | R17: 0 | S17: 0 | T17: 0 | U17: 0 | V17: 0 | W17: 61.730931 | X17: 61.730931 | Y17: 61.730931 | Z17: 0 | AA17: 0 | AB17: 261.44865 | AC17: 14.524925
A18: Florencia de Mora | B18: 4281.8336 | C18: 46100 | D18: 728.02994 | E18: 0 | F18: 1729.0711 | G18: 0 | H18: =Laminado!F18 -> 1638.0674 | I18: 0 | J18: 0 | K18: 0 | L18: 0 | M18: 0 | N18: 0 | O18: 0 | P18: 0 | Q18: 0 | R18: 0 | S18: 0 | T18: 0 | U18: 0 | V18: 0 | W18: 0 | X18: 0 | Y18: 0 | Z18: 0 | AA18: 0 | AB18: 192.34915 | AC18: 10.887688
A19: Encañada | B19: 21119.28 | C19: 46101 | D19: 4264.1309 | E19: =Laminado!E19 -> 4164.472 | F19: 0 | G19: 0 | H19: =Laminado!F19 -> 9465.4801 | I19: 0 | J19: 0 | K19: 1133.1265 | L19: 0 | M19: 0 | N19: 0 | O19: 0 | P19: 0 | Q19: 0 | R19: 378.41353 | S19: 942.86275 | T19: 0 | U19: 0 | V19: 0 | W19: 0 | X19: 0 | Y19: 0 | Z19: 0 | AA19: 0 | AB19: 801.22193 | AC19: 44.394883
A20: Olmos | B20: 5840 | C20: 46115 | D20: 1331.6679 | E20: 0 | F20: {=IF(Laminado!E20:E26>500, Laminado!E20:E26, 0)} -> 1843.8478 | G20: 0 | H20: 0 | I20: =Laminado!F20+Molido!D20 -> 1563.1941 | J20: 322.30807 | K20: 0 | L20: 0 | M20: 0 | N20: 0 | O20: 612.7721 | P20: 0 | Q20: 0 | R20: 0 | S20: 0 | T20: 0 | U20: 0 | V20: 0 | W20: 0 | X20: 0 | Y20: 0 | Z20: 0 | AA20: 0 | AB20: 216.51281 | AC20: 12.255442
A21: Alto Trujillo | B21: 3018.04 | C21: 46129 | D21: 160.90105 | E21: 0 | F21: 823.29217 | G21: 0 | H21: 0 | I21: =Laminado!F21+Molido!D21 -> 1937.4789 | J21: 0 | K21: 0 | L21: 0 | M21: 0 | N21: 0 | O21: 0 | P21: 0 | Q21: 0 | R21: 0 | S21: 0 | T21: 0 | U21: 0 | V21: 0 | W21: 0 | X21: 0 | Y21: 0 | Z21: 0 | AA21: 0 | AB21: 102.41397 | AC21: 5.740016
A22: Moyobamba | B22: 9139 | C22: 46129 | D22: 3223.2071 | E22: 0 | F22: 0 | G22: 0 | H22: 0 | I22: =Laminado!F22+Molido!D22 -> 0 | J22: 0 | K22: 0 | L22: 1043.3563 | M22: 1141.4797 | N22: 0 | O22: 0 | P22: 0 | Q22: 0 | R22: 0 | S22: 0 | T22: 0 | U22: 0 | V22: 2191.0483 | W22: 0 | X22: 0 | Y22: 0 | Z22: 313.00689 | AA22: 834.68505 | AB22: 0 | AC22: 467.42363
A23: Olmos | B23: 5611 | C23: 46146 | D23: 1279.4501 | E23: 0 | F23: 1771.5463 | G23: 0 | H23: 0 | I23: =Laminado!F23+Molido!D23 -> 1501.8977 | J23: 309.66962 | K23: 0 | L23: 0 | M23: 0 | N23: 0 | O23: 588.74388 | P23: 0 | Q23: 0 | R23: 0 | S23: 0 | T23: 0 | U23: 0 | V23: 0 | W23: 0 | X23: 0 | Y23: 0 | Z23: 0 | AA23: 0 | AB23: 208.02284 | AC23: 11.774878
A24: Sanchez Carrión | B24: 9298.08 | C24: 46150 | D24: 585.32918 | E24: 0 | F24: 3819.1095 | G24: 0 | H24: 0 | I24: 0 | J24: 1112.2651 | K24: 740.86804 | L24: 1057.3192 | M24: 0 | N24: 1669.3768 | O24: 0 | P24: 0 | Q24: 0 | R24: 0 | S24: 0 | T24: 0 | U24: 0 | V24: 0 | W24: 0 | X24: 0 | Y24: 0 | Z24: 0 | AA24: 0 | AB24: 448.61607 | AC24: 25.129946
A25: Viru | B25: 6046 | C25: 46157 | D25: 790.34822 | E25: 0 | F25: 1362.167 | G25: 0 | H25: 0 | I25: =Laminado!F25+Molido!D25 -> 2724.334 | J25: 0 | K25: 617.30931 | L25: 0 | M25: 0 | N25: 0 | O25: 0 | P25: 0 | Q25: 111.35776 | R25: 0 | S25: 0 | T25: 0 | U25: 0 | V25: 0 | W25: 61.730931 | X25: 61.730931 | Y25: 61.730931 | Z25: 0 | AA25: 0 | AB25: 261.44865 | AC25: 14.524925
A26: Cajatambo | B26: 1016 | C26: 46174 | D26: 362.22943 | E26: 0 | F26: 0 | G26: 129.8679 | H26: 0 | I26: =Laminado!F24+Molido!D24 -> 0 | J26: 0 | K26: 361.14274 | L26: 0 | M26: 0 | N26: 0 | O26: 0 | P26: 0 | Q26: 0 | R26: 0 | S26: 0 | T26: 0 | U26: 0 | V26: 0 | W26: 0 | X26: 0 | Y26: 0 | Z26: 0 | AA26: 0 | AB26: 51.054254 | AC26: 2.8476476
A27: Olmos | B27: 5840 | C27: 46174 | D27: 1331.6679 | E27: 0 | F27: =IF(Laminado!E27>500, Laminado!E27, 0) -> 1843.8478 | G27: 0 | H27: =Laminado!F27 -> 0 | I27: =Laminado!F27+Molido!D27 -> 1563.1941 | J27: 322.30807 | K27: 0 | L27: 0 | M27: 0 | N27: 0 | O27: 612.7721 | P27: 0 | Q27: 0 | R27: 0 | S27: 0 | T27: 0 | U27: 0 | V27: 0 | W27: 0 | X27: 0 | Y27: 0 | Z27: 0 | AA27: 0 | AB27: 216.51281 | AC27: 12.255442
A28: Encañada | B28: 21119.28 | C28: 46175 | D28: 4264.1309 | E28: =Laminado!E28 -> 4164.472 | F28: 0 | G28: 0 | H28: =Laminado!F28 -> 9465.4801 | I28: 0 | J28: 0 | K28: 1133.1265 | L28: 0 | M28: 0 | N28: 0 | O28: 0 | P28: 0 | Q28: 0 | R28: 378.41353 | S28: 942.86275 | T28: 0 | U28: 0 | V28: 0 | W28: 0 | X28: 0 | Y28: 0 | Z28: 0 | AA28: 0 | AB28: 801.22193 | AC28: 44.394883
A29: Hualgayoc | B29: 11906.24 | C29: 46179 | D29: 1536.0916 | E29: 0 | F29: {=IF(Laminado!E29:E33>500, Laminado!E29:E33, 0)} -> 2586.85 | G29: 0 | H29: =Laminado!F29 -> 3986.6657 | I29: 0 | J29: 112.8376 | K29: 1504.0716 | L29: 0 | M29: 0 | N29: 0 | O29: 1396.8081 | P29: 171.62148 | Q29: 0 | R29: 0 | S29: 0 | T29: 90.270081 | U29: 85.810739 | V29: 0 | W29: 0 | X29: 0 | Y29: 0 | Z29: 0 | AA29: 0 | AB29: 455.27364 | AC29: 26.219948
A30: Alto Trujillo | B30: 3018.9826 | C30: 46188 | D30: 160.9513 | E30: 0 | F30: 823.54929 | G30: 0 | H30: 0 | I30: =Laminado!F30+Molido!D30 -> 1938.084 | J30: 0 | K30: 0 | L30: 0 | M30: 0 | N30: 0 | O30: 0 | P30: 0 | Q30: 0 | R30: 0 | S30: 0 | T30: 0 | U30: 0 | V30: 0 | W30: 0 | X30: 0 | Y30: 0 | Z30: 0 | AA30: 0 | AB30: 102.44596 | AC30: 5.7418087
A31: Sanchez Carrión | B31: 9298.08 | C31: 46214 | D31: 585.32918 | E31: 0 | F31: 3819.1095 | G31: 0 | H31: 0 | I31: =Laminado!F31+Molido!D31 -> 0 | J31: 1112.2651 | K31: 740.86804 | L31: 1057.3192 | M31: 0 | N31: 1669.3768 | O31: 0 | P31: 0 | Q31: 0 | R31: 0 | S31: 0 | T31: 0 | U31: 0 | V31: 0 | W31: 0 | X31: 0 | Y31: 0 | Z31: 0 | AA31: 0 | AB31: 448.61607 | AC31: 25.129946
A32: Alto Trujillo | B32: 3018.9826 | C32: 46218 | D32: 160.9513 | E32: 0 | F32: 823.54929 | G32: 0 | H32: 0 | I32: =Laminado!F32+Molido!D32 -> 1938.084 | J32: 0 | K32: 0 | L32: 0 | M32: 0 | N32: 0 | O32: 0 | P32: 0 | Q32: 0 | R32: 0 | S32: 0 | T32: 0 | U32: 0 | V32: 0 | W32: 0 | X32: 0 | Y32: 0 | Z32: 0 | AA32: 0 | AB32: 102.44596 | AC32: 5.7418087
A33: Florencia de Mora | B33: 4281.8336 | C33: 46218 | D33: 728.02994 | E33: 0 | F33: 1729.0711 | G33: 0 | H33: =Laminado!F33 -> 1638.0674 | I33: 0 | J33: 0 | K33: 0 | L33: 0 | M33: 0 | N33: 0 | O33: 0 | P33: 0 | Q33: 0 | R33: 0 | S33: 0 | T33: 0 | U33: 0 | V33: 0 | W33: 0 | X33: 0 | Y33: 0 | Z33: 0 | AA33: 0 | AB33: 192.34915 | AC33: 10.887688
A34: Encañada | B34: 21119.28 | C34: 46192 | D34: 4264.1309 | E34: =Laminado!E34 -> 4164.472 | F34: 0 | G34: 0 | H34: 0 | I34: =Laminado!F34+Molido!D34 -> 9465.4801 | J34: 0 | K34: 1133.1265 | L34: 0 | M34: 0 | N34: 0 | O34: 0 | P34: 0 | Q34: 0 | R34: 378.41353 | S34: 942.86275 | T34: 0 | U34: 0 | V34: 0 | W34: 0 | X34: 0 | Y34: 0 | Z34: 0 | AA34: 0 | AB34: 801.22193 | AC34: 44.394883
A35: Moyobamba | B35: 9294 | C35: 46197 | D35: 3277.8736 | E35: 0 | F35: {=IF(Laminado!E35:E41>500, Laminado!E35:E41, 0)} -> 0 | G35: 0 | H35: 0 | I35: =Laminado!F35+Molido!D35 -> 0 | J35: 0 | K35: 0 | L35: 1061.0519 | M35: 1160.8395 | N35: 0 | O35: 0 | P35: 0 | Q35: 0 | R35: 0 | S35: 0 | T35: 0 | U35: 0 | V35: 2228.209 | W35: 0 | X35: 0 | Y35: 0 | Z35: 318.31558 | AA35: 848.84154 | AB35: 0 | AC35: 475.35126
A36: Viru | B36: 6046 | C36: 46216 | D36: 790.34822 | E36: 0 | F36: 1362.167 | G36: 0 | H36: 0 | I36: =Laminado!F36+Molido!D36 -> 2724.334 | J36: 0 | K36: 617.30931 | L36: 0 | M36: 0 | N36: 0 | O36: 0 | P36: 0 | Q36: 111.35776 | R36: 0 | S36: 0 | T36: 0 | U36: 0 | V36: 0 | W36: 61.730931 | X36: 61.730931 | Y36: 61.730931 | Z36: 0 | AA36: 0 | AB36: 261.44865 | AC36: 14.524925
A37: Alto Trujillo | B37: 3759.21 | C37: 46235 | D37: 200.41511 | E37: 0 | F37: 1025.4762 | G37: 0 | H37: =Laminado!F37 -> 2413.2848 | I37: 0 | J37: 0 | K37: 0 | L37: 0 | M37: 0 | N37: 0 | O37: 0 | P37: 0 | Q37: 0 | R37: 0 | S37: 0 | T37: 0 | U37: 0 | V37: 0 | W37: 0 | X37: 0 | Y37: 0 | Z37: 0 | AA37: 0 | AB37: 127.56478 | AC37: 7.1496486
A38: Olmos | B38: 5611 | C38: 46238 | D38: 1279.4501 | E38: 0 | F38: 1771.5463 | G38: 0 | H38: 0 | I38: =Laminado!F38+Molido!D38 -> 1501.8977 | J38: 309.66962 | K38: 0 | L38: 0 | M38: 0 | N38: 0 | O38: 588.74388 | P38: 0 | Q38: 0 | R38: 0 | S38: 0 | T38: 0 | U38: 0 | V38: 0 | W38: 0 | X38: 0 | Y38: 0 | Z38: 0 | AA38: 0 | AB38: 208.02284 | AC38: 11.774878
A39: Viru | B39: 13579 | C39: 46248 | D39: 1775.0808 | E39: 0 | F39: 3059.3558 | G39: 0 | H39: 0 | I39: =Laminado!F39+Molido!D39 -> 6118.7117 | J39: 0 | K39: 1386.4444 | L39: 0 | M39: 0 | N39: 0 | O39: 0 | P39: 0 | Q39: 250.1037 | R39: 0 | S39: 0 | T39: 0 | U39: 0 | V39: 0 | W39: 138.64444 | X39: 138.64444 | Y39: 138.64444 | Z39: 0 | AA39: 0 | AB39: 587.2 | AC39: 32.622222
A40: Sanchez Carrión | B40: 3743.92 | C40: 46249 | D40: 235.68582 | E40: 0 | F40: 1537.7842 | G40: 0 | H40: 0 | I40: =Laminado!F40+Molido!D40 -> 0 | J40: 447.8593 | K40: 298.31435 | L40: 425.73505 | M40: 0 | N40: 672.18319 | O40: 0 | P40: 0 | Q40: 0 | R40: 0 | S40: 0 | T40: 0 | U40: 0 | V40: 0 | W40: 0 | X40: 0 | Y40: 0 | Z40: 0 | AA40: 0 | AB40: 180.63758 | AC40: 10.118703
...

Sheet Resumen
B2: Agosto | D2: =MONTH(DATE(2025,MATCH(B2,{"enero","febrero","marzo","abril","mayo","junio","julio","agosto","septiembre","octubre","noviembre","diciembre"},0),1)) -> 8
B5: Materia Prima | C5: Total (Kg) | D5: Capacida Sacos | E5: Redondeo | F5: U.M. | G5: N° Sacos
B6: {=TRANSPOSE('Materia Prima'!D1:AC1)} -> Avena | C6: {=SUMPRODUCT((MONTH('Materia Prima'!$C$2:$C$74)=$D$2)*('Materia Prima'!D2:D74))} -> 3651.5831 | D6: 25 | E6: =G6*D6 -> 3675 | F6: Kg | G6: =ROUNDUP(C6/D6,0) -> 147
B7: Quinua Precocida | C7: {=SUMPRODUCT((MONTH('Materia Prima'!$C$2:$C$74)=$D$2)*('Materia Prima'!E2:E74))} -> 0 | D7: 50 | E7: =G7*D7 -> 0 | F7: Kg | G7: =ROUNDUP(C7/D7,0) -> 0
B8: Quinua Desaponificada | C8: {=SUMPRODUCT((MONTH('Materia Prima'!$C$2:$C$74)=$D$2)*('Materia Prima'!F2:F74))} -> 8217.7118 | D8: 50 | E8: =G8*D8 -> 8250 | F8: Kg | G8: =ROUNDUP(C8/D8,0) -> 165
B9: Quinua | C9: {=SUMPRODUCT((MONTH('Materia Prima'!$C$2:$C$74)=$D$2)*('Materia Prima'!G2:G74))} -> 0 | D9: 50 | E9: =G9*D9 -> 0 | F9: Kg | G9: =ROUNDUP(C9/D9,0) -> 0
B10: Kiwicha Precocida | C10: {=SUMPRODUCT((MONTH('Materia Prima'!$C$2:$C$74)=$D$2)*('Materia Prima'!H2:H74))} -> 2413.2848 | D10: 50 | E10: =G10*D10 -> 2450 | F10: Kg | G10: =ROUNDUP(C10/D10,0) -> 49
B11: Kiwicha | C11: {=SUMPRODUCT((MONTH('Materia Prima'!$C$2:$C$74)=$D$2)*('Materia Prima'!I2:I74))} -> 9558.6933 | D11: 50 | E11: =G11*D11 -> 9600 | F11: Kg | G11: =ROUNDUP(C11/D11,0) -> 192
B12: Soya | C12: {=SUMPRODUCT((MONTH('Materia Prima'!$C$2:$C$74)=$D$2)*('Materia Prima'!J2:J74))} -> 757.52892 | D12: 50 | E12: =G12*D12 -> 800 | F12: Kg | G12: =ROUNDUP(C12/D12,0) -> 16
B13: Maca Deshidratada | C13: {=SUMPRODUCT((MONTH('Materia Prima'!$C$2:$C$74)=$D$2)*('Materia Prima'!K2:K74))} -> 1684.7588 | D13: 50 | E13: =G13*D13 -> 1700 | F13: Kg | G13: =ROUNDUP(C13/D13,0) -> 34
B14: Azucar | C14: {=SUMPRODUCT((MONTH('Materia Prima'!$C$2:$C$74)=$D$2)*('Materia Prima'!L2:L74))} -> 425.73505 | D14: 50 | E14: =G14*D14 -> 450 | F14: Kg | G14: =ROUNDUP(C14/D14,0) -> 9
B15: Sacha Inchi | C15: {=SUMPRODUCT((MONTH('Materia Prima'!$C$2:$C$74)=$D$2)*('Materia Prima'!M2:M74))} -> 0 | D15: 50 | E15: =G15*D15 -> 0 | F15: Kg | G15: =ROUNDUP(C15/D15,0) -> 0
B16: Maiz Chufla | C16: {=SUMPRODUCT((MONTH('Materia Prima'!$C$2:$C$74)=$D$2)*('Materia Prima'!N2:N74))} -> 672.18319 | D16: 25 | E16: =G16*D16 -> 675 | F16: Kg | G16: =ROUNDUP(C16/D16,0) -> 27
B17: Leche Polvo | C17: {=SUMPRODUCT((MONTH('Materia Prima'!$C$2:$C$74)=$D$2)*('Materia Prima'!O2:O74))} -> 588.74388 | D17: 25 | E17: =G17*D17 -> 600 | F17: Kg | G17: =ROUNDUP(C17/D17,0) -> 24
B18: Aceite soya | C18: {=SUMPRODUCT((MONTH('Materia Prima'!$C$2:$C$74)=$D$2)*('Materia Prima'!P2:P74))} -> 0 | D18: 4 | E18: =G18*D18 -> 0 | F18: L | G18: =ROUNDUP(C18/D18,0) -> 0
B19: Aceite Girasol | C19: {=SUMPRODUCT((MONTH('Materia Prima'!$C$2:$C$74)=$D$2)*('Materia Prima'!Q2:Q74))} -> 250.1037 | D19: 4 | E19: =G19*D19 -> 252 | F19: L | G19: =ROUNDUP(C19/D19,0) -> 63
B20: Chia | C20: {=SUMPRODUCT((MONTH('Materia Prima'!$C$2:$C$74)=$D$2)*('Materia Prima'!R2:R74))} -> 0 | D20: 50 | E20: =G20*D20 -> 0 | F20: Kg | G20: =ROUNDUP(C20/D20,0) -> 0
B21: Cacao Deshidratado | C21: {=SUMPRODUCT((MONTH('Materia Prima'!$C$2:$C$74)=$D$2)*('Materia Prima'!S2:S74))/0.92} -> 0 | D21: 25 | E21: =G21*D21 -> 0 | F21: Kg | G21: =ROUNDUP(C21/D21,0) -> 0
B22: Garbanzo | C22: {=SUMPRODUCT((MONTH('Materia Prima'!$C$2:$C$74)=$D$2)*('Materia Prima'!T2:T74))} -> 0 | D22: 25 | E22: =G22*D22 -> 0 | F22: Kg | G22: =ROUNDUP(C22/D22,0) -> 0
B23: Tarhui | C23: {=SUMPRODUCT((MONTH('Materia Prima'!$C$2:$C$74)=$D$2)*('Materia Prima'!U2:U74))} -> 0 | D23: 25 | E23: =G23*D23 -> 0 | F23: Kg | G23: =ROUNDUP(C23/D23,0) -> 0
B24: Almidon maca | C24: {=SUMPRODUCT((MONTH('Materia Prima'!$C$2:$C$74)=$D$2)*('Materia Prima'!V2:V74))} -> 0 | D24: 50 | E24: =G24*D24 -> 0 | F24: Kg | G24: =ROUNDUP(C24/D24,0) -> 0
B25: Linaza | C25: {=SUMPRODUCT((MONTH('Materia Prima'!$C$2:$C$74)=$D$2)*('Materia Prima'!W2:W74))} -> 138.64444 | D25: 50 | E25: =G25*D25 -> 150 | F25: Kg | G25: =ROUNDUP(C25/D25,0) -> 3
B26: Ajonjoli | C26: {=SUMPRODUCT((MONTH('Materia Prima'!$C$2:$C$74)=$D$2)*('Materia Prima'!X2:X74))} -> 138.64444 | D26: 25 | E26: =G26*D26 -> 150 | F26: Kg | G26: =ROUNDUP(C26/D26,0) -> 6
B27: Proteina aislada soya | C27: {=SUMPRODUCT((MONTH('Materia Prima'!$C$2:$C$74)=$D$2)*('Materia Prima'!Y2:Y74))} -> 138.64444 | D27: 50 | E27: =G27*D27 -> 150 | F27: Kg | G27: =ROUNDUP(C27/D27,0) -> 3
B28: Albumina clara de huevo | C28: {=SUMPRODUCT((MONTH('Materia Prima'!$C$2:$C$74)=$D$2)*('Materia Prima'!Z2:Z74))} -> 0 | D28: 20 | E28: =G28*D28 -> 0 | F28: Kg | G28: =ROUNDUP(C28/D28,0) -> 0
B29: Harina de Plátano | C29: {=SUMPRODUCT((MONTH('Materia Prima'!$C$2:$C$74)=$D$2)*('Materia Prima'!AA2:AA74))} -> 0 | D29: 25 | E29: =G29*D29 -> 0 | F29: Kg | G29: =ROUNDUP(C29/D29,0) -> 0
B30: Fosfato Tricálcio | C30: {=SUMPRODUCT((MONTH('Materia Prima'!$C$2:$C$74)=$D$2)*('Materia Prima'!AB2:AB74))} -> 1205.8712 | D30: 25 | E30: =G30*D30 -> 1225 | F30: Kg | G30: =ROUNDUP(C30/D30,0) -> 49
B31: Mix vitaminico | C31: {=SUMPRODUCT((MONTH('Materia Prima'!$C$2:$C$74)=$D$2)*('Materia Prima'!AC2:AC74))} -> 67.40726 | D31: 25 | E31: =G31*D31 -> 75 | F31: Kg | G31: =ROUNDUP(C31/D31,0) -> 3

Sheet Formula
B1: {=Mezclado!E1:AA1} -> Avena | C1: Quinua | D1: Kiwicha | E1: Soya | F1: Maca | G1: Azucar | H1: Sacha Inchi | I1: Maiz Chufla | J1: Leche Polvo | K1: Aceite soya | L1: Aceite Girasol | M1: Chia | N1: Cacao Deshidratado | O1: Garbanzo | P1: Tarhui | Q1: Almidon maca | R1: Linaza | S1: Ajonjoli | T1: Proteina aislada soya | U1: Albumina clara de huevo | V1: Harina de Plátano | W1: Fosfato Tricálcio | X1: Mix vitaminico
A2: Alto Trujillo | B2: 0.0531 | C2: 0.2717 | D2: 0.6394 | W2: 0.0339 | X2: 0.0019 | Y2: =SUM(B2:X2) -> 1
A3: Cajatambo | B3: 0.3551 | C3: 0.1184 | D3: 0.1184 | F3: 0.3551 | W3: 0.0502 | X3: 0.0028 | Y3: =SUM(B3:X3) -> 1
A4: Encañada | B4: 0.2011 | C4: 0.1964 | D4: 0.4464 | F4: 0.0536 | M4: 0.0179 | N4: 0.0446 | W4: 0.0379 | X4: 0.0021 | Y4: =SUM(B4:X4) -> 1
A5: Florencia de Mora | B5: =8/47.24 -> 0.16934801 | C5: =19/47.24 -> 0.40220152 | D5: =18/47.24 -> 0.38103302 | W5: =2.12/47.24 -> 0.044877223 | X5: =0.12/47.24 -> 0.0025402202 | Y5: =SUM(B5:X5) -> 1
A6: Hualgayoc | B6: 0.1285 | C6: 0.2164 | D6: 0.3335 | E6: 0.009 | F6: 0.1262 | J6: 0.1172 | K6: 0.0144 | O6: 0.0072 | P6: 0.0072 | W6: 0.0382 | X6: 0.0022 | Y6: =SUM(B6:X6) -> 1
A7: Moyobamba | B7: =15.4/43.84 -> 0.35127737 | G7: =5/43.84 -> 0.11405109 | H7: =5.2/43.84 -> 0.11861314 | Q7: =10.5/43.84 -> 0.2395073 | U7: =1.5/43.84 -> 0.034215328 | V7: =4/43.84 -> 0.091240876 | X7: =2.24/43.84 -> 0.051094891 | Y7: =SUM(B7:X7) -> 1
A8: Olmos | B8: =13/57.24 -> 0.22711391 | C8: =18/57.24 -> 0.31446541 | D8: =15/57.24 -> 0.26205451 | E8: =3/57.24 -> 0.052410901 | J8: =6/57.24 -> 0.1048218 | W8: =2.12/57.24 -> 0.037037037 | X8: =0.12/57.24 -> 0.0020964361 | Y8: =SUM(B8:X8) -> 1
A9: Sanchez Carrión | B9: 0.0627 | C9: 0.4091 | E9: 0.1136 | F9: 0.0796 | G9: 0.1136 | I9: 0.1705 | W9: 0.0482 | X9: 0.0027 | Y9: =SUM(B9:X9) -> 1
A10: Viru | B10: 0.1302 | C10: 0.2244 | D10: 0.4488 | F10: 0.102 | L10: 0.0184 | R10: 0.0102 | S10: 0.0102 | T10: 0.0102 | W10: 0.0432 | X10: 0.0024 | Y10: =SUM(B10:X10) -> 1
A14: MERMA
A15: Deshidratado | B15: 0.7
A16: Tostado | B16: 0.03
A17: Molido | B17: 0.02
A18: Laminado | B18: 0.003
A19: Mezclado | B19: 0.001
A21: Diciembre
A22: Enero
A23: Febrero
A24: Marzo
A25: Abril
A26: Mayo
A27: Junio
A28: Julio
A29: Agosto
A30: Septiembre
A31: Octubre
A32: Noviembre

Sheet Procesos
B1: {=Mezclado!E1:AA1} -> Avena | C1: Quinua | D1: Kiwicha | E1: Soya | F1: Maca | G1: Azucar | H1: Sacha Inchi | I1: Maiz Chufla | J1: Leche Polvo | K1: Aceite soya | L1: Aceite Girasol | M1: Chia | N1: Cacao Deshidratado | O1: Garbanzo | P1: Tarhui | Q1: Almidon maca | R1: Linaza | S1: Ajonjoli | T1: Proteina aislada soya | U1: Albumina clara de huevo | V1: Harina de Plátano | W1: Fosfato Tricálcio | X1: Mix vitaminico
A2: Alto Trujillo
A3: Alto Trujillo | B3: Laminado | C3: Laminado | D3: Laminado
A4: Cajatambo
A5: Cajatambo | B5: Laminado | C5: Laminado | D5: Laminado
A6: Encañada | C6: Tostado | D6: Tostado | F6: Deshidratado | N6: Deshidratado
A7: Encañada | B7: Laminado | C7: Laminado | D7: Laminado | N7: Molido | O7: Molido
A8: Florencia de Mora | D8: Tostado
A9: Florencia de Mora | B9: Laminado | C9: Laminado | D9: Laminado
A10: Hualgayoc | D10: Tostado | E10: Tostado | F10: Deshidratado
A11: Hualgayoc | B11: Laminado | C11: Laminado | D11: Laminado | E11: Molido
A12: Moyobamba | H12: Tostado
A13: Moyobamba | B13: Laminado | H13: Molido
A14: Olmos | E14: Tostado
A15: Olmos | B15: Laminado | C15: Laminado | D15: Molido | E15: Molido
A16: Sanchez Carrión | E16: Tostado | I16: Tostado
A17: Sanchez Carrión | B17: Laminado | C17: Laminado | E17: Molido | I17: Molido
A18: Viru
A19: Viru | B19: Laminado | C19: Laminado | D19: Laminado
