Workbook

Sheet Cereal
A1: EMPRESA | B1: MUNICIPALIDAD | C1: MES | D1: FECHA | E1: N° BOLSAS | F1: KG BOLSA | G1: TOTAL (KG) | H1: CAP. SACOS | I1: N° SACOS | J1: UNIDADES | K1: PRODUCCIÓN | L1: ENVASADO | M1: SALIDA | N1: PRODUCTO
A2: PENDIENTE | B2: Agua Blanca | C2: Enero | D2: 46081 | E2: 640 | F2: 1.27593 | G2: =Cereal[[#This Row],[N° BOLSAS]]*Cereal[[#This Row],[KG BOLSA]] -> 816.5952 | H2: 35 | I2: =ROUNDDOWN(Cereal[[#This Row],[N° BOLSAS]]/Cereal[[#This Row],[CAP. SACOS]],0) -> 18 | J2: =Cereal[[#This Row],[N° BOLSAS]]-Cereal[[#This Row],[N° SACOS]]*Cereal[[#This Row],[CAP. SACOS]] -> 10 | K2: 46075 | L2: 46075 | M2: 46119 | N2: HOJUELAS DE KIWICHA TOSTADA, SOYA INTEGRAL, QUINUA, AVENA CON MACA ENRIQUECIDA CON VITAMINAS Y MINERALES
A3: PENDIENTE | B3: Agua Blanca | C3: Febrero | D3: 46081 | E3: 640 | F3: 1.27593 | G3: =Cereal[[#This Row],[N° BOLSAS]]*Cereal[[#This Row],[KG BOLSA]] -> 816.5952 | H3: 35 | I3: =ROUNDDOWN(Cereal[[#This Row],[N° BOLSAS]]/Cereal[[#This Row],[CAP. SACOS]],0) -> 18 | J3: =Cereal[[#This Row],[N° BOLSAS]]-Cereal[[#This Row],[N° SACOS]]*Cereal[[#This Row],[CAP. SACOS]] -> 10 | K3: 46075 | L3: 46075 | M3: 46119 | N3: HOJUELAS DE KIWICHA TOSTADA, SOYA INTEGRAL, QUINUA, AVENA CON MACA ENRIQUECIDA CON VITAMINAS Y MINERALES
A4: PENDIENTE | B4: Agua Blanca | C4: Marzo | D4: 46081 | E4: 640 | F4: 1.27593 | G4: =Cereal[[#This Row],[N° BOLSAS]]*Cereal[[#This Row],[KG BOLSA]] -> 816.5952 | H4: 35 | I4: =ROUNDDOWN(Cereal[[#This Row],[N° BOLSAS]]/Cereal[[#This Row],[CAP. SACOS]],0) -> 18 | J4: =Cereal[[#This Row],[N° BOLSAS]]-Cereal[[#This Row],[N° SACOS]]*Cereal[[#This Row],[CAP. SACOS]] -> 10 | K4: 46075 | L4: 46075 | M4: 46119 | N4: HOJUELAS DE KIWICHA TOSTADA, SOYA INTEGRAL, QUINUA, AVENA CON MACA ENRIQUECIDA CON VITAMINAS Y MINERALES
A5: PENDIENTE | B5: Agua Blanca | C5: Abril | D5: 46081 | E5: 640 | F5: 1.27593 | G5: =Cereal[[#This Row],[N° BOLSAS]]*Cereal[[#This Row],[KG BOLSA]] -> 816.5952 | H5: 35 | I5: =ROUNDDOWN(Cereal[[#This Row],[N° BOLSAS]]/Cereal[[#This Row],[CAP. SACOS]],0) -> 18 | J5: =Cereal[[#This Row],[N° BOLSAS]]-Cereal[[#This Row],[N° SACOS]]*Cereal[[#This Row],[CAP. SACOS]] -> 10 | K5: 46075 | L5: 46075 | M5: 46119 | N5: HOJUELAS DE KIWICHA TOSTADA, SOYA INTEGRAL, QUINUA, AVENA CON MACA ENRIQUECIDA CON VITAMINAS Y MINERALES
A6: PENDIENTE | B6: Agua Blanca | C6: Mayo | D6: 46140 | E6: 640 | F6: 1.27593 | G6: =Cereal[[#This Row],[N° BOLSAS]]*Cereal[[#This Row],[KG BOLSA]] -> 816.5952 | H6: 35 | I6: =ROUNDDOWN(Cereal[[#This Row],[N° BOLSAS]]/Cereal[[#This Row],[CAP. SACOS]],0) -> 18 | J6: =Cereal[[#This Row],[N° BOLSAS]]-Cereal[[#This Row],[N° SACOS]]*Cereal[[#This Row],[CAP. SACOS]] -> 10 | K6: 46147 | L6: 46147 | M6: 46147 | N6: HOJUELAS DE KIWICHA TOSTADA, SOYA INTEGRAL, QUINUA, AVENA CON MACA ENRIQUECIDA CON VITAMINAS Y MINERALES
A7: PENDIENTE | B7: Agua Blanca | C7: Junio | D7: 46140 | E7: 640 | F7: 1.27593 | G7: =Cereal[[#This Row],[N° BOLSAS]]*Cereal[[#This Row],[KG BOLSA]] -> 816.5952 | H7: 35 | I7: =ROUNDDOWN(Cereal[[#This Row],[N° BOLSAS]]/Cereal[[#This Row],[CAP. SACOS]],0) -> 18 | J7: =Cereal[[#This Row],[N° BOLSAS]]-Cereal[[#This Row],[N° SACOS]]*Cereal[[#This Row],[CAP. SACOS]] -> 10 | K7: 46147 | L7: 46147 | M7: 46147 | N7: HOJUELAS DE KIWICHA TOSTADA, SOYA INTEGRAL, QUINUA, AVENA CON MACA ENRIQUECIDA CON VITAMINAS Y MINERALES
A8: PENDIENTE | B8: Agua Blanca | C8: Julio | D8: 46199 | E8: 640 | F8: 1.27593 | G8: =Cereal[[#This Row],[N° BOLSAS]]*Cereal[[#This Row],[KG BOLSA]] -> 816.5952 | H8: 35 | I8: =ROUNDDOWN(Cereal[[#This Row],[N° BOLSAS]]/Cereal[[#This Row],[CAP. SACOS]],0) -> 18 | J8: =Cereal[[#This Row],[N° BOLSAS]]-Cereal[[#This Row],[N° SACOS]]*Cereal[[#This Row],[CAP. SACOS]] -> 10 | K8: 46202 | L8: 46202 | M8: 46202 | N8: HOJUELAS DE KIWICHA TOSTADA, SOYA INTEGRAL, QUINUA, AVENA CON MACA ENRIQUECIDA CON VITAMINAS Y MINERALES
A9: PENDIENTE | B9: Agua Blanca | C9: Agosto | D9: 46199 | E9: 640 | F9: 1.27593 | G9: =Cereal[[#This Row],[N° BOLSAS]]*Cereal[[#This Row],[KG BOLSA]] -> 816.5952 | H9: 35 | I9: =ROUNDDOWN(Cereal[[#This Row],[N° BOLSAS]]/Cereal[[#This Row],[CAP. SACOS]],0) -> 18 | J9: =Cereal[[#This Row],[N° BOLSAS]]-Cereal[[#This Row],[N° SACOS]]*Cereal[[#This Row],[CAP. SACOS]] -> 10 | K9: 46202 | L9: 46202 | M9: 46202 | N9: HOJUELAS DE KIWICHA TOSTADA, SOYA INTEGRAL, QUINUA, AVENA CON MACA ENRIQUECIDA CON VITAMINAS Y MINERALES
A10: PENDIENTE | B10: Agua Blanca | C10: Setiembre | D10: 46262 | E10: 640 | F10: 1.27593 | G10: =Cereal[[#This Row],[N° BOLSAS]]*Cereal[[#This Row],[KG BOLSA]] -> 816.5952 | H10: 35 | I10: =ROUNDDOWN(Cereal[[#This Row],[N° BOLSAS]]/Cereal[[#This Row],[CAP. SACOS]],0) -> 18 | J10: =Cereal[[#This Row],[N° BOLSAS]]-Cereal[[#This Row],[N° SACOS]]*Cereal[[#This Row],[CAP. SACOS]] -> 10 | K10: 46263 | L10: 46263 | M10: 46269 | N10: HOJUELAS DE KIWICHA TOSTADA, SOYA INTEGRAL, QUINUA, AVENA CON MACA ENRIQUECIDA CON VITAMINAS Y MINERALES
A11: PENDIENTE | B11: Agua Blanca | C11: Octubre | D11: 46262 | E11: 640 | F11: 1.27593 | G11: =Cereal[[#This Row],[N° BOLSAS]]*Cereal[[#This Row],[KG BOLSA]] -> 816.5952 | H11: 35 | I11: =ROUNDDOWN(Cereal[[#This Row],[N° BOLSAS]]/Cereal[[#This Row],[CAP. SACOS]],0) -> 18 | J11: =Cereal[[#This Row],[N° BOLSAS]]-Cereal[[#This Row],[N° SACOS]]*Cereal[[#This Row],[CAP. SACOS]] -> 10 | K11: 46263 | L11: 46263 | M11: 46269 | N11: HOJUELAS DE KIWICHA TOSTADA, SOYA INTEGRAL, QUINUA, AVENA CON MACA ENRIQUECIDA CON VITAMINAS Y MINERALES
A12: PENDIENTE | B12: Agua Blanca | C12: Noviembre | D12: 46322 | E12: 640 | F12: 1.27593 | G12: =Cereal[[#This Row],[N° BOLSAS]]*Cereal[[#This Row],[KG BOLSA]] -> 816.5952 | H12: 35 | I12: =ROUNDDOWN(Cereal[[#This Row],[N° BOLSAS]]/Cereal[[#This Row],[CAP. SACOS]],0) -> 18 | J12: =Cereal[[#This Row],[N° BOLSAS]]-Cereal[[#This Row],[N° SACOS]]*Cereal[[#This Row],[CAP. SACOS]] -> 10 | N12: HOJUELAS DE KIWICHA TOSTADA, SOYA INTEGRAL, QUINUA, AVENA CON MACA ENRIQUECIDA CON VITAMINAS Y MINERALES
A13: PENDIENTE | B13: Agua Blanca | C13: Diciembre | D13: 46322 | E13: 640 | F13: 1.27593 | G13: =Cereal[[#This Row],[N° BOLSAS]]*Cereal[[#This Row],[KG BOLSA]] -> 816.5952 | H13: 35 | I13: =ROUNDDOWN(Cereal[[#This Row],[N° BOLSAS]]/Cereal[[#This Row],[CAP. SACOS]],0) -> 18 | J13: =Cereal[[#This Row],[N° BOLSAS]]-Cereal[[#This Row],[N° SACOS]]*Cereal[[#This Row],[CAP. SACOS]] -> 10 | N13: HOJUELAS DE KIWICHA TOSTADA, SOYA INTEGRAL, QUINUA, AVENA CON MACA ENRIQUECIDA CON VITAMINAS Y MINERALES
A14: PENDIENTE | B14: Alto Biavo | C14: O.C. | D14: 46052 | E14: 1041 | F14: 1 | G14: =Cereal[[#This Row],[N° BOLSAS]]*Cereal[[#This Row],[KG BOLSA]] -> 1041 | H14: 50 | I14: =ROUNDDOWN(Cereal[[#This Row],[N° BOLSAS]]/Cereal[[#This Row],[CAP. SACOS]],0) -> 20 | J14: =Cereal[[#This Row],[N° BOLSAS]]-Cereal[[#This Row],[N° SACOS]]*Cereal[[#This Row],[CAP. SACOS]] -> 41 | K14: 46051 | L14: 46051 | M14: 46051 | N14: HOJUELAS PRECOCIDAS AZUCARADAS DE AVENA, CAÑIHUA, QUINUA, CEBADA, MACA, ALBUMINA DE HUEVO FORTIFICADA CON VITAMINAS Y MINERALES
A15: PENDIENTE | B15: Alto Biavo | C15: Marzo | D15: 46112 | E15: 547 | F15: 1 | G15: =Cereal[[#This Row],[N° BOLSAS]]*Cereal[[#This Row],[KG BOLSA]] -> 547 | H15: 50 | I15: =ROUNDDOWN(Cereal[[#This Row],[N° BOLSAS]]/Cereal[[#This Row],[CAP. SACOS]],0) -> 10 | J15: =Cereal[[#This Row],[N° BOLSAS]]-Cereal[[#This Row],[N° SACOS]]*Cereal[[#This Row],[CAP. SACOS]] -> 47 | K15: 46109 | L15: 46109 | M15: 46109 | N15: HOJUELAS PRECOCIDAS AZUCARADAS DE AVENA, CAÑIHUA, QUINUA, CEBADA, MACA, ALBUMINA DE HUEVO FORTIFICADA CON VITAMINAS Y MINERALES
A16: PENDIENTE | B16: Alto Biavo | C16: Abril | D16: 46112 | E16: 528 | F16: 1 | G16: =Cereal[[#This Row],[N° BOLSAS]]*Cereal[[#This Row],[KG BOLSA]] -> 528 | H16: 50 | I16: =ROUNDDOWN(Cereal[[#This Row],[N° BOLSAS]]/Cereal[[#This Row],[CAP. SACOS]],0) -> 10 | J16: =Cereal[[#This Row],[N° BOLSAS]]-Cereal[[#This Row],[N° SACOS]]*Cereal[[#This Row],[CAP. SACOS]] -> 28 | K16: 46109 | L16: 46109 | M16: 46109 | N16: HOJUELAS PRECOCIDAS AZUCARADAS DE AVENA, CAÑIHUA, QUINUA, CEBADA, MACA, ALBUMINA DE HUEVO FORTIFICADA CON VITAMINAS Y MINERALES
A17: PENDIENTE | B17: Alto Biavo | C17: Mayo | D17: 46127 | E17: 547 | F17: 1 | G17: =Cereal[[#This Row],[N° BOLSAS]]*Cereal[[#This Row],[KG BOLSA]] -> 547 | H17: 50 | I17: =ROUNDDOWN(Cereal[[#This Row],[N° BOLSAS]]/Cereal[[#This Row],[CAP. SACOS]],0) -> 10 | J17: =Cereal[[#This Row],[N° BOLSAS]]-Cereal[[#This Row],[N° SACOS]]*Cereal[[#This Row],[CAP. SACOS]] -> 47 | K17: 46136 | L17: 46136 | M17: 46147 | N17: HOJUELAS PRECOCIDAS AZUCARADAS DE AVENA, CAÑIHUA, QUINUA, CEBADA, MACA, ALBUMINA DE HUEVO FORTIFICADA CON VITAMINAS Y MINERALES
A18: PENDIENTE | B18: Alto Biavo | C18: Junio | D18: 46127 | E18: 528 | F18: 1 | G18: =Cereal[[#This Row],[N° BOLSAS]]*Cereal[[#This Row],[KG BOLSA]] -> 528 | H18: 50 | I18: =ROUNDDOWN(Cereal[[#This Row],[N° BOLSAS]]/Cereal[[#This Row],[CAP. SACOS]],0) -> 10 | J18: =Cereal[[#This Row],[N° BOLSAS]]-Cereal[[#This Row],[N° SACOS]]*Cereal[[#This Row],[CAP. SACOS]] -> 28 | K18: 46136 | L18: 46136 | M18: 46147 | N18: HOJUELAS PRECOCIDAS AZUCARADAS DE AVENA, CAÑIHUA, QUINUA, CEBADA, MACA, ALBUMINA DE HUEVO FORTIFICADA CON VITAMINAS Y MINERALES
A19: PENDIENTE | B19: Alto Biavo | C19: Julio | D19: 46188 | E19: 547 | F19: 1 | G19: =Cereal[[#This Row],[N° BOLSAS]]*Cereal[[#This Row],[KG BOLSA]] -> 547 | H19: 50 | I19: =ROUNDDOWN(Cereal[[#This Row],[N° BOLSAS]]/Cereal[[#This Row],[CAP. SACOS]],0) -> 10 | J19: =Cereal[[#This Row],[N° BOLSAS]]-Cereal[[#This Row],[N° SACOS]]*Cereal[[#This Row],[CAP. SACOS]] -> 47 | K19: 46175 | L19: 46175 | M19: 46178 | N19: HOJUELAS PRECOCIDAS AZUCARADAS DE AVENA, CAÑIHUA, QUINUA, CEBADA, MACA, ALBUMINA DE HUEVO FORTIFICADA CON VITAMINAS Y MINERALES
A20: PENDIENTE | B20: Alto Biavo | C20: Agosto | D20: 46188 | E20: 547 | F20: 1 | G20: =Cereal[[#This Row],[N° BOLSAS]]*Cereal[[#This Row],[KG BOLSA]] -> 547 | H20: 50 | I20: =ROUNDDOWN(Cereal[[#This Row],[N° BOLSAS]]/Cereal[[#This Row],[CAP. SACOS]],0) -> 10 | J20: =Cereal[[#This Row],[N° BOLSAS]]-Cereal[[#This Row],[N° SACOS]]*Cereal[[#This Row],[CAP. SACOS]] -> 47 | K20: 46175 | L20: 46175 | M20: 46178 | N20: HOJUELAS PRECOCIDAS AZUCARADAS DE AVENA, CAÑIHUA, QUINUA, CEBADA, MACA, ALBUMINA DE HUEVO FORTIFICADA CON VITAMINAS Y MINERALES
A21: PENDIENTE | B21: Alto Biavo | C21: Setiembre | D21: 46249 | E21: 530 | F21: 1 | G21: =Cereal[[#This Row],[N° BOLSAS]]*Cereal[[#This Row],[KG BOLSA]] -> 530 | H21: 50 | I21: =ROUNDDOWN(Cereal[[#This Row],[N° BOLSAS]]/Cereal[[#This Row],[CAP. SACOS]],0) -> 10 | J21: =Cereal[[#This Row],[N° BOLSAS]]-Cereal[[#This Row],[N° SACOS]]*Cereal[[#This Row],[CAP. SACOS]] -> 30 | K21: 46241 | L21: 46241 | M21: 46253 | N21: HOJUELAS PRECOCIDAS AZUCARADAS DE AVENA, CAÑIHUA, QUINUA, CEBADA, MACA, ALBUMINA DE HUEVO FORTIFICADA CON VITAMINAS Y MINERALES
A22: PENDIENTE | B22: Alto Biavo | C22: Octubre | D22: 46249 | E22: 548 | F22: 1 | G22: =Cereal[[#This Row],[N° BOLSAS]]*Cereal[[#This Row],[KG BOLSA]] -> 548 | H22: 50 | I22: =ROUNDDOWN(Cereal[[#This Row],[N° BOLSAS]]/Cereal[[#This Row],[CAP. SACOS]],0) -> 10 | J22: =Cereal[[#This Row],[N° BOLSAS]]-Cereal[[#This Row],[N° SACOS]]*Cereal[[#This Row],[CAP. SACOS]] -> 48 | K22: 46241 | L22: 46241 | M22: 46253 | N22: HOJUELAS PRECOCIDAS AZUCARADAS DE AVENA, CAÑIHUA, QUINUA, CEBADA, MACA, ALBUMINA DE HUEVO FORTIFICADA CON VITAMINAS Y MINERALES
A23: PENDIENTE | B23: Alto Biavo | C23: Noviembre | D23: 46310 | E23: 530 | F23: 1 | G23: =Cereal[[#This Row],[N° BOLSAS]]*Cereal[[#This Row],[KG BOLSA]] -> 530 | H23: 50 | I23: =ROUNDDOWN(Cereal[[#This Row],[N° BOLSAS]]/Cereal[[#This Row],[CAP. SACOS]],0) -> 10 | J23: =Cereal[[#This Row],[N° BOLSAS]]-Cereal[[#This Row],[N° SACOS]]*Cereal[[#This Row],[CAP. SACOS]] -> 30 | N23: HOJUELAS PRECOCIDAS AZUCARADAS DE AVENA, CAÑIHUA, QUINUA, CEBADA, MACA, ALBUMINA DE HUEVO FORTIFICADA CON VITAMINAS Y MINERALES
A24: PENDIENTE | B24: Alto Biavo | C24: Diciembre | D24: 46310 | E24: 548 | F24: 1 | G24: =Cereal[[#This Row],[N° BOLSAS]]*Cereal[[#This Row],[KG BOLSA]] -> 548 | H24: 50 | I24: =ROUNDDOWN(Cereal[[#This Row],[N° BOLSAS]]/Cereal[[#This Row],[CAP. SACOS]],0) -> 10 | J24: =Cereal[[#This Row],[N° BOLSAS]]-Cereal[[#This Row],[N° SACOS]]*Cereal[[#This Row],[CAP. SACOS]] -> 48 | N24: HOJUELAS PRECOCIDAS AZUCARADAS DE AVENA, CAÑIHUA, QUINUA, CEBADA, MACA, ALBUMINA DE HUEVO FORTIFICADA CON VITAMINAS Y MINERALES
A25: PENDIENTE | B25: Alto Trujillo | C25: Abril | D25: 46112 | E25: 3120 | F25: 0.95146 | G25: =Cereal[[#This Row],[N° BOLSAS]]*Cereal[[#This Row],[KG BOLSA]] -> 2968.5552 | H25: 40 | I25: =ROUNDDOWN(Cereal[[#This Row],[N° BOLSAS]]/Cereal[[#This Row],[CAP. SACOS]],0) -> 78 | J25: =Cereal[[#This Row],[N° BOLSAS]]-Cereal[[#This Row],[N° SACOS]]*Cereal[[#This Row],[CAP. SACOS]] -> 0 | K25: 46105 | L25: 46105 | M25: 46105 | N25: MEZCLA DE HOJUELAS DE QUINUA, AVENA Y KIWICHA ENRIQUECIDA CON VITAMINAS Y MINERALES - HOJUELAS CRUDAS
A26: PENDIENTE | B26: Alto Trujillo | C26: Mayo | D26: 46142 | E26: 3120 | F26: 0.95146 | G26: =Cereal[[#This Row],[N° BOLSAS]]*Cereal[[#This Row],[KG BOLSA]] -> 2968.5552 | H26: 40 | I26: =ROUNDDOWN(Cereal[[#This Row],[N° BOLSAS]]/Cereal[[#This Row],[CAP. SACOS]],0) -> 78 | J26: =Cereal[[#This Row],[N° BOLSAS]]-Cereal[[#This Row],[N° SACOS]]*Cereal[[#This Row],[CAP. SACOS]] -> 0 | K26: 46139 | L26: 46139 | M26: 46139 | N26: MEZCLA DE HOJUELAS DE QUINUA, AVENA Y KIWICHA ENRIQUECIDA CON VITAMINAS Y MINERALES - HOJUELAS CRUDAS
A27: PENDIENTE | B27: Alto Trujillo | C27: Junio | D27: 46173 | E27: 3120 | F27: 0.95146 | G27: =Cereal[[#This Row],[N° BOLSAS]]*Cereal[[#This Row],[KG BOLSA]] -> 2968.5552 | H27: 40 | I27: =ROUNDDOWN(Cereal[[#This Row],[N° BOLSAS]]/Cereal[[#This Row],[CAP. SACOS]],0) -> 78 | J27: =Cereal[[#This Row],[N° BOLSAS]]-Cereal[[#This Row],[N° SACOS]]*Cereal[[#This Row],[CAP. SACOS]] -> 0 | K27: 46161 | L27: 46161 | M27: 46167 | N27: MEZCLA DE HOJUELAS DE QUINUA, AVENA Y KIWICHA ENRIQUECIDA CON VITAMINAS Y MINERALES - HOJUELAS CRUDAS
A28: PENDIENTE | B28: Alto Trujillo | C28: Julio | D28: 46203 | E28: 3120 | F28: 0.95146 | G28: =Cereal[[#This Row],[N° BOLSAS]]*Cereal[[#This Row],[KG BOLSA]] -> 2968.5552 | H28: 40 | I28: =ROUNDDOWN(Cereal[[#This Row],[N° BOLSAS]]/Cereal[[#This Row],[CAP. SACOS]],0) -> 78 | J28: =Cereal[[#This Row],[N° BOLSAS]]-Cereal[[#This Row],[N° SACOS]]*Cereal[[#This Row],[CAP. SACOS]] -> 0 | K28: 46197 | L28: 46197 | M28: 46197 | N28: MEZCLA DE HOJUELAS DE QUINUA, AVENA Y KIWICHA ENRIQUECIDA CON VITAMINAS Y MINERALES - HOJUELAS CRUDAS
A29: PENDIENTE | B29: Alto Trujillo | C29: Agosto | D29: 46234 | E29: 3120 | F29: 0.95146 | G29: =Cereal[[#This Row],[N° BOLSAS]]*Cereal[[#This Row],[KG BOLSA]] -> 2968.5552 | H29: 40 | I29: =ROUNDDOWN(Cereal[[#This Row],[N° BOLSAS]]/Cereal[[#This Row],[CAP. SACOS]],0) -> 78 | J29: =Cereal[[#This Row],[N° BOLSAS]]-Cereal[[#This Row],[N° SACOS]]*Cereal[[#This Row],[CAP. SACOS]] -> 0 | K29: 46225 | L29: 46225 | M29: 46225 | N29: MEZCLA DE HOJUELAS DE QUINUA, AVENA Y KIWICHA ENRIQUECIDA CON VITAMINAS Y MINERALES - HOJUELAS CRUDAS
A30: PENDIENTE | B30: Alto Trujillo | C30: O.C. | D30: 46265 | E30: 3120 | F30: 1.18512 | G30: =Cereal[[#This Row],[N° BOLSAS]]*Cereal[[#This Row],[KG BOLSA]] -> 3697.5744 | H30: 35 | I30: =ROUNDDOWN(Cereal[[#This Row],[N° BOLSAS]]/Cereal[[#This Row],[CAP. SACOS]],0) -> 89 | J30: =Cereal[[#This Row],[N° BOLSAS]]-Cereal[[#This Row],[N° SACOS]]*Cereal[[#This Row],[CAP. SACOS]] -> 5 | K30: 46244 | L30: 46244 | M30: 46244 | N30: MEZCLA DE HOJUELAS DE QUINUA, AVENA Y KIWICHA ENRIQUECIDA CON VITAMINAS Y MINERALES - HOJUELAS CRUDAS
A31: PENDIENTE | B31: Alto Trujillo | C31: Setiembre | D31: 46265 | E31: 3120 | F31: 0.95146 | G31: =Cereal[[#This Row],[N° BOLSAS]]*Cereal[[#This Row],[KG BOLSA]] -> 2968.5552 | H31: 40 | I31: =ROUNDDOWN(Cereal[[#This Row],[N° BOLSAS]]/Cereal[[#This Row],[CAP. SACOS]],0) -> 78 | J31: =Cereal[[#This Row],[N° BOLSAS]]-Cereal[[#This Row],[N° SACOS]]*Cereal[[#This Row],[CAP. SACOS]] -> 0 | K31: 46251 | L31: 46251 | M31: 46263 | N31: MEZCLA DE HOJUELAS DE QUINUA, AVENA Y KIWICHA ENRIQUECIDA CON VITAMINAS Y MINERALES - HOJUELAS CRUDAS
A32: PENDIENTE | B32: Alto Trujillo | C32: Octubre | D32: 46295 | E32: 3120 | F32: 0.95146 | G32: =Cereal[[#This Row],[N° BOLSAS]]*Cereal[[#This Row],[KG BOLSA]] -> 2968.5552 | H32: 40 | I32: =ROUNDDOWN(Cereal[[#This Row],[N° BOLSAS]]/Cereal[[#This Row],[CAP. SACOS]],0) -> 78 | J32: =Cereal[[#This Row],[N° BOLSAS]]-Cereal[[#This Row],[N° SACOS]]*Cereal[[#This Row],[CAP. SACOS]] -> 0 | K32: 46290 | L32: 46290 | M32: 46290 | N32: MEZCLA DE HOJUELAS DE QUINUA, AVENA Y KIWICHA ENRIQUECIDA CON VITAMINAS Y MINERALES - HOJUELAS CRUDAS
A33: PENDIENTE | B33: Alto Trujillo | C33: Noviembre | D33: 46326 | E33: 3120 | F33: 0.95146 | G33: =Cereal[[#This Row],[N° BOLSAS]]*Cereal[[#This Row],[KG BOLSA]] -> 2968.5552 | H33: 40 | I33: =ROUNDDOWN(Cereal[[#This Row],[N° BOLSAS]]/Cereal[[#This Row],[CAP. SACOS]],0) -> 78 | J33: =Cereal[[#This Row],[N° BOLSAS]]-Cereal[[#This Row],[N° SACOS]]*Cereal[[#This Row],[CAP. SACOS]] -> 0 | N33: MEZCLA DE HOJUELAS DE QUINUA, AVENA Y KIWICHA ENRIQUECIDA CON VITAMINAS Y MINERALES - HOJUELAS CRUDAS
A34: PENDIENTE | B34: Alto Trujillo | C34: Diciembre | D34: 46356 | E34: 3120 | F34: 0.95146 | G34: =Cereal[[#This Row],[N° BOLSAS]]*Cereal[[#This Row],[KG BOLSA]] -> 2968.5552 | H34: 40 | I34: =ROUNDDOWN(Cereal[[#This Row],[N° BOLSAS]]/Cereal[[#This Row],[CAP. SACOS]],0) -> 78 | J34: =Cereal[[#This Row],[N° BOLSAS]]-Cereal[[#This Row],[N° SACOS]]*Cereal[[#This Row],[CAP. SACOS]] -> 0 | N34: MEZCLA DE HOJUELAS DE QUINUA, AVENA Y KIWICHA ENRIQUECIDA CON VITAMINAS Y MINERALES - HOJUELAS CRUDAS
A35: PENDIENTE | B35: Alto Trujillo | C35: 46388 | D35: 46387 | E35: 3120 | F35: 0.95146 | G35: =Cereal[[#This Row],[N° BOLSAS]]*Cereal[[#This Row],[KG BOLSA]] -> 2968.5552 | H35: 40 | I35: =ROUNDDOWN(Cereal[[#This Row],[N° BOLSAS]]/Cereal[[#This Row],[CAP. SACOS]],0) -> 78 | J35: =Cereal[[#This Row],[N° BOLSAS]]-Cereal[[#This Row],[N° SACOS]]*Cereal[[#This Row],[CAP. SACOS]] -> 0 | N35: MEZCLA DE HOJUELAS DE QUINUA, AVENA Y KIWICHA ENRIQUECIDA CON VITAMINAS Y MINERALES - HOJUELAS CRUDAS
A36: PENDIENTE | B36: Alto Trujillo | C36: 46419 | D36: 46418 | E36: 3120 | F36: 0.95146 | G36: =Cereal[[#This Row],[N° BOLSAS]]*Cereal[[#This Row],[KG BOLSA]] -> 2968.5552 | H36: 40 | I36: =ROUNDDOWN(Cereal[[#This Row],[N° BOLSAS]]/Cereal[[#This Row],[CAP. SACOS]],0) -> 78 | J36: =Cereal[[#This Row],[N° BOLSAS]]-Cereal[[#This Row],[N° SACOS]]*Cereal[[#This Row],[CAP. SACOS]] -> 0 | N36: MEZCLA DE HOJUELAS DE QUINUA, AVENA Y KIWICHA ENRIQUECIDA CON VITAMINAS Y MINERALES - HOJUELAS CRUDAS
A37: PENDIENTE | B37: Alto Trujillo | C37: 46447 | D37: 46446 | E37: 3120 | F37: 0.95146 | G37: =Cereal[[#This Row],[N° BOLSAS]]*Cereal[[#This Row],[KG BOLSA]] -> 2968.5552 | H37: 40 | I37: =ROUNDDOWN(Cereal[[#This Row],[N° BOLSAS]]/Cereal[[#This Row],[CAP. SACOS]],0) -> 78 | J37: =Cereal[[#This Row],[N° BOLSAS]]-Cereal[[#This Row],[N° SACOS]]*Cereal[[#This Row],[CAP. SACOS]] -> 0 | N37: MEZCLA DE HOJUELAS DE QUINUA, AVENA Y KIWICHA ENRIQUECIDA CON VITAMINAS Y MINERALES - HOJUELAS CRUDAS
A38: PENDIENTE | B38: Ascope | C38: Enero / Febrero / Marzo | D38: 46037 | E38: 2400 | F38: 0.778 | G38: =Cereal[[#This Row],[N° BOLSAS]]*Cereal[[#This Row],[KG BOLSA]] -> 1867.2 | H38: 60 | I38: =ROUNDDOWN(Cereal[[#This Row],[N° BOLSAS]]/Cereal[[#This Row],[CAP. SACOS]],0) -> 40 | J38: =Cereal[[#This Row],[N° BOLSAS]]-Cereal[[#This Row],[N° SACOS]]*Cereal[[#This Row],[CAP. SACOS]] -> 0 | K38: 46039 | L38: 46039 | M38: 46049 | N38: HOJUELAS DE AVENA, KIWICHA, QUINUA, MAÍZ CHUFLA CON SOYA, MACA Y AZÚCAR FORTIFICADA CON VITAMINAS Y MINERALES - HOJUELAS PRECOCIDAS
A39: PENDIENTE | B39: Ascope | C39: Abril / Mayo / Junio | D39: 46096 | E39: 2400 | F39: 0.778 | G39: =Cereal[[#This Row],[N° BOLSAS]]*Cereal[[#This Row],[KG BOLSA]] -> 1867.2 | H39: 60 | I39: =ROUNDDOWN(Cereal[[#This Row],[N° BOLSAS]]/Cereal[[#This Row],[CAP. SACOS]],0) -> 40 | J39: =Cereal[[#This Row],[N° BOLSAS]]-Cereal[[#This Row],[N° SACOS]]*Cereal[[#This Row],[CAP. SACOS]] -> 0 | K39: 46101 | L39: 46101 | M39: 46101 | N39: HOJUELAS DE AVENA, KIWICHA, QUINUA, MAÍZ CHUFLA CON SOYA, MACA Y AZÚCAR FORTIFICADA CON VITAMINAS Y MINERALES - HOJUELAS PRECOCIDAS
A40: PENDIENTE | B40: Ascope | C40: Julio / Agosto / Septiembre | D40: 46188 | E40: 2400 | F40: 0.778 | G40: =Cereal[[#This Row],[N° BOLSAS]]*Cereal[[#This Row],[KG BOLSA]] -> 1867.2 | H40: 60 | I40: =ROUNDDOWN(Cereal[[#This Row],[N° BOLSAS]]/Cereal[[#This Row],[CAP. SACOS]],0) -> 40 | J40: =Cereal[[#This Row],[N° BOLSAS]]-Cereal[[#This Row],[N° SACOS]]*Cereal[[#This Row],[CAP. SACOS]] -> 0 | K40: 46192 | L40: 46192 | M40: 46192 | N40: HOJUELAS DE AVENA, KIWICHA, QUINUA, MAÍZ CHUFLA CON SOYA, MACA Y AZÚCAR FORTIFICADA CON VITAMINAS Y MINERALES - HOJUELAS PRECOCIDAS
...

Sheet Leche
A1: EMPRESA | B1: MUNICIPALIDAD | C1: MES | D1: FECHA | E1: N° LATAS | F1: TOTAL CAJAS | G1: UNIDADES | H1: ENTREGA | I1: CONFIRMACIÓN
A2: PENDIENTE | B2: Agua Blanca | C2: Abril | D2: 46117 | E2: 640 | F2: =ROUNDDOWN(Leche[[#This Row],[N° LATAS]]/48,0) -> 13 | G2: =Leche[[#This Row],[N° LATAS]]-Leche[[#This Row],[TOTAL CAJAS]]*48 -> 16 | H2: 46119 | I2: Confirmado
A3: PENDIENTE | B3: Agua Blanca | C3: Enero | D3: 46117 | E3: 640 | F3: =ROUNDDOWN(Leche[[#This Row],[N° LATAS]]/48,0) -> 13 | G3: =Leche[[#This Row],[N° LATAS]]-Leche[[#This Row],[TOTAL CAJAS]]*48 -> 16 | H3: 46119 | I3: Confirmado
A4: PENDIENTE | B4: Agua Blanca | C4: Febrero | D4: 46117 | E4: 640 | F4: =ROUNDDOWN(Leche[[#This Row],[N° LATAS]]/48,0) -> 13 | G4: =Leche[[#This Row],[N° LATAS]]-Leche[[#This Row],[TOTAL CAJAS]]*48 -> 16 | H4: 46119 | I4: Confirmado
A5: PENDIENTE | B5: Agua Blanca | C5: Marzo | D5: 46117 | E5: 640 | F5: =ROUNDDOWN(Leche[[#This Row],[N° LATAS]]/48,0) -> 13 | G5: =Leche[[#This Row],[N° LATAS]]-Leche[[#This Row],[TOTAL CAJAS]]*48 -> 16 | H5: 46119 | I5: Confirmado
A6: PENDIENTE | B6: Agua Blanca | C6: Junio | D6: 46140 | E6: 640 | F6: =ROUNDDOWN(Leche[[#This Row],[N° LATAS]]/48,0) -> 13 | G6: =Leche[[#This Row],[N° LATAS]]-Leche[[#This Row],[TOTAL CAJAS]]*48 -> 16 | H6: 46147 | I6: Confirmado
A7: PENDIENTE | B7: Agua Blanca | C7: Mayo | D7: 46140 | E7: 640 | F7: =ROUNDDOWN(Leche[[#This Row],[N° LATAS]]/48,0) -> 13 | G7: =Leche[[#This Row],[N° LATAS]]-Leche[[#This Row],[TOTAL CAJAS]]*48 -> 16 | H7: 46147 | I7: Confirmado
A8: PENDIENTE | B8: Agua Blanca | C8: Agosto | D8: 46199 | E8: 640 | F8: =ROUNDDOWN(Leche[[#This Row],[N° LATAS]]/48,0) -> 13 | G8: =Leche[[#This Row],[N° LATAS]]-Leche[[#This Row],[TOTAL CAJAS]]*48 -> 16 | H8: 46202 | I8: Confirmado
A9: PENDIENTE | B9: Agua Blanca | C9: Julio | D9: 46199 | E9: 640 | F9: =ROUNDDOWN(Leche[[#This Row],[N° LATAS]]/48,0) -> 13 | G9: =Leche[[#This Row],[N° LATAS]]-Leche[[#This Row],[TOTAL CAJAS]]*48 -> 16 | H9: 46202 | I9: Confirmado
A10: PENDIENTE | B10: Agua Blanca | C10: Octubre | D10: 46262 | E10: 640 | F10: =ROUNDDOWN(Leche[[#This Row],[N° LATAS]]/48,0) -> 13 | G10: =Leche[[#This Row],[N° LATAS]]-Leche[[#This Row],[TOTAL CAJAS]]*48 -> 16 | H10: 46269 | I10: Confirmado
A11: PENDIENTE | B11: Agua Blanca | C11: Setiembre | D11: 46262 | E11: 640 | F11: =ROUNDDOWN(Leche[[#This Row],[N° LATAS]]/48,0) -> 13 | G11: =Leche[[#This Row],[N° LATAS]]-Leche[[#This Row],[TOTAL CAJAS]]*48 -> 16 | H11: 46269 | I11: Confirmado
A12: PENDIENTE | B12: Agua Blanca | C12: Diciembre | D12: 46322 | E12: 640 | F12: =ROUNDDOWN(Leche[[#This Row],[N° LATAS]]/48,0) -> 13 | G12: =Leche[[#This Row],[N° LATAS]]-Leche[[#This Row],[TOTAL CAJAS]]*48 -> 16
A13: PENDIENTE | B13: Agua Blanca | C13: Noviembre | D13: 46322 | E13: 640 | F13: =ROUNDDOWN(Leche[[#This Row],[N° LATAS]]/48,0) -> 13 | G13: =Leche[[#This Row],[N° LATAS]]-Leche[[#This Row],[TOTAL CAJAS]]*48 -> 16
A14: PENDIENTE | B14: Alto Biavo | C14: Marzo | D14: 46112 | E14: 1064 | F14: =ROUNDDOWN(Leche[[#This Row],[N° LATAS]]/48,0) -> 22 | G14: =Leche[[#This Row],[N° LATAS]]-Leche[[#This Row],[TOTAL CAJAS]]*48 -> 8 | H14: 46109 | I14: Confirmado
A15: PENDIENTE | B15: Alto Biavo | C15: Abril | D15: 46112 | E15: 1030 | F15: =ROUNDDOWN(Leche[[#This Row],[N° LATAS]]/48,0) -> 21 | G15: =Leche[[#This Row],[N° LATAS]]-Leche[[#This Row],[TOTAL CAJAS]]*48 -> 22 | H15: 46109 | I15: Confirmado
A16: PENDIENTE | B16: Alto Biavo | C16: Mayo | D16: 46127 | E16: 1065 | F16: =ROUNDDOWN(Leche[[#This Row],[N° LATAS]]/48,0) -> 22 | G16: =Leche[[#This Row],[N° LATAS]]-Leche[[#This Row],[TOTAL CAJAS]]*48 -> 9 | H16: 46147 | I16: Confirmado
A17: PENDIENTE | B17: Alto Biavo | C17: Junio | D17: 46127 | E17: 1031 | F17: =ROUNDDOWN(Leche[[#This Row],[N° LATAS]]/48,0) -> 21 | G17: =Leche[[#This Row],[N° LATAS]]-Leche[[#This Row],[TOTAL CAJAS]]*48 -> 23 | H17: 46147 | I17: Confirmado
A18: PENDIENTE | B18: Alto Biavo | C18: Julio | D18: 46188 | E18: 1065 | F18: =ROUNDDOWN(Leche[[#This Row],[N° LATAS]]/48,0) -> 22 | G18: =Leche[[#This Row],[N° LATAS]]-Leche[[#This Row],[TOTAL CAJAS]]*48 -> 9 | H18: 46178 | I18: Confirmado
A19: PENDIENTE | B19: Alto Biavo | C19: Agosto | D19: 46188 | E19: 1065 | F19: =ROUNDDOWN(Leche[[#This Row],[N° LATAS]]/48,0) -> 22 | G19: =Leche[[#This Row],[N° LATAS]]-Leche[[#This Row],[TOTAL CAJAS]]*48 -> 9 | H19: 46178 | I19: Confirmado
A20: PENDIENTE | B20: Alto Biavo | C20: O.C. | D20: 46223 | E20: 388 | F20: =ROUNDDOWN(Leche[[#This Row],[N° LATAS]]/48,0) -> 8 | G20: =Leche[[#This Row],[N° LATAS]]-Leche[[#This Row],[TOTAL CAJAS]]*48 -> 4 | H20: 46222 | I20: Confirmado
A21: PENDIENTE | B21: Alto Biavo | C21: Setiembre | D21: 46249 | E21: 1033 | F21: =ROUNDDOWN(Leche[[#This Row],[N° LATAS]]/48,0) -> 21 | G21: =Leche[[#This Row],[N° LATAS]]-Leche[[#This Row],[TOTAL CAJAS]]*48 -> 25 | H21: 46254 | I21: Confirmado
A22: PENDIENTE | B22: Alto Biavo | C22: Octubre | D22: 46249 | E22: 1068 | F22: =ROUNDDOWN(Leche[[#This Row],[N° LATAS]]/48,0) -> 22 | G22: =Leche[[#This Row],[N° LATAS]]-Leche[[#This Row],[TOTAL CAJAS]]*48 -> 12 | H22: 46254 | I22: Confirmado
A23: PENDIENTE | B23: Alto Biavo | C23: Noviembre | D23: 46310 | E23: 1033 | F23: =ROUNDDOWN(Leche[[#This Row],[N° LATAS]]/48,0) -> 21 | G23: =Leche[[#This Row],[N° LATAS]]-Leche[[#This Row],[TOTAL CAJAS]]*48 -> 25
A24: PENDIENTE | B24: Alto Biavo | C24: Diciembre | D24: 46310 | E24: 1068 | F24: =ROUNDDOWN(Leche[[#This Row],[N° LATAS]]/48,0) -> 22 | G24: =Leche[[#This Row],[N° LATAS]]-Leche[[#This Row],[TOTAL CAJAS]]*48 -> 12
A25: PENDIENTE | B25: Alto Biavo - 25 | C25: O.C. | D25: 46052 | E25: 2024 | F25: =ROUNDDOWN(Leche[[#This Row],[N° LATAS]]/48,0) -> 42 | G25: =Leche[[#This Row],[N° LATAS]]-Leche[[#This Row],[TOTAL CAJAS]]*48 -> 8 | H25: 46051 | I25: Confirmado
A26: PENDIENTE | B26: Alto Trujillo | C26: Abril | D26: 46112 | E26: 4680 | F26: =ROUNDDOWN(Leche[[#This Row],[N° LATAS]]/48,0) -> 97 | G26: =Leche[[#This Row],[N° LATAS]]-Leche[[#This Row],[TOTAL CAJAS]]*48 -> 24 | H26: 46101 | I26: Confirmado
A27: PENDIENTE | B27: Alto Trujillo | C27: Mayo | D27: 46142 | E27: 4680 | F27: =ROUNDDOWN(Leche[[#This Row],[N° LATAS]]/48,0) -> 97 | G27: =Leche[[#This Row],[N° LATAS]]-Leche[[#This Row],[TOTAL CAJAS]]*48 -> 24 | H27: 46139 | I27: Confirmado
A28: PENDIENTE | B28: Alto Trujillo | C28: Junio | D28: 46173 | E28: 4680 | F28: =ROUNDDOWN(Leche[[#This Row],[N° LATAS]]/48,0) -> 97 | G28: =Leche[[#This Row],[N° LATAS]]-Leche[[#This Row],[TOTAL CAJAS]]*48 -> 24 | H28: 46167 | I28: Confirmado
A29: PENDIENTE | B29: Alto Trujillo | C29: Julio | D29: 46203 | E29: 4680 | F29: =ROUNDDOWN(Leche[[#This Row],[N° LATAS]]/48,0) -> 97 | G29: =Leche[[#This Row],[N° LATAS]]-Leche[[#This Row],[TOTAL CAJAS]]*48 -> 24 | H29: 46198 | I29: Confirmado
A30: PENDIENTE | B30: Alto Trujillo | C30: Agosto | D30: 46234 | E30: 4680 | F30: =ROUNDDOWN(Leche[[#This Row],[N° LATAS]]/48,0) -> 97 | G30: =Leche[[#This Row],[N° LATAS]]-Leche[[#This Row],[TOTAL CAJAS]]*48 -> 24 | H30: 46225 | I30: Confirmado
A31: PENDIENTE | B31: Alto Trujillo | C31: O.C. | D31: 46265 | E31: 5829 | F31: =ROUNDDOWN(Leche[[#This Row],[N° LATAS]]/48,0) -> 121 | G31: =Leche[[#This Row],[N° LATAS]]-Leche[[#This Row],[TOTAL CAJAS]]*48 -> 21 | H31: 46244 | I31: Confirmado
A32: PENDIENTE | B32: Alto Trujillo | C32: Setiembre | D32: 46265 | E32: 4680 | F32: =ROUNDDOWN(Leche[[#This Row],[N° LATAS]]/48,0) -> 97 | G32: =Leche[[#This Row],[N° LATAS]]-Leche[[#This Row],[TOTAL CAJAS]]*48 -> 24 | H32: 46266 | I32: Confirmado
A33: PENDIENTE | B33: Alto Trujillo | C33: Octubre | D33: 46295 | E33: 4680 | F33: =ROUNDDOWN(Leche[[#This Row],[N° LATAS]]/48,0) -> 97 | G33: =Leche[[#This Row],[N° LATAS]]-Leche[[#This Row],[TOTAL CAJAS]]*48 -> 24 | H33: 46290 | I33: Confirmado
A34: PENDIENTE | B34: Alto Trujillo | C34: Noviembre | D34: 46326 | E34: 4680 | F34: =ROUNDDOWN(Leche[[#This Row],[N° LATAS]]/48,0) -> 97 | G34: =Leche[[#This Row],[N° LATAS]]-Leche[[#This Row],[TOTAL CAJAS]]*48 -> 24
A35: PENDIENTE | B35: Alto Trujillo | C35: Diciembre | D35: 46356 | E35: 4680 | F35: =ROUNDDOWN(Leche[[#This Row],[N° LATAS]]/48,0) -> 97 | G35: =Leche[[#This Row],[N° LATAS]]-Leche[[#This Row],[TOTAL CAJAS]]*48 -> 24
A36: PENDIENTE | B36: Alto Trujillo | C36: 46388 | D36: 46387 | E36: 4680 | F36: =ROUNDDOWN(Leche[[#This Row],[N° LATAS]]/48,0) -> 97 | G36: =Leche[[#This Row],[N° LATAS]]-Leche[[#This Row],[TOTAL CAJAS]]*48 -> 24
A37: PENDIENTE | B37: Alto Trujillo | C37: 46419 | D37: 46418 | E37: 4680 | F37: =ROUNDDOWN(Leche[[#This Row],[N° LATAS]]/48,0) -> 97 | G37: =Leche[[#This Row],[N° LATAS]]-Leche[[#This Row],[TOTAL CAJAS]]*48 -> 24
A38: PENDIENTE | B38: Alto Trujillo | C38: 46447 | D38: 46446 | E38: 4680 | F38: =ROUNDDOWN(Leche[[#This Row],[N° LATAS]]/48,0) -> 97 | G38: =Leche[[#This Row],[N° LATAS]]-Leche[[#This Row],[TOTAL CAJAS]]*48 -> 24
A39: PENDIENTE | B39: Angel Saavedra | C39: O.C. | D39: 46112 | E39: 1500 | F39: =ROUNDDOWN(Leche[[#This Row],[N° LATAS]]/48,0) -> 31 | G39: =Leche[[#This Row],[N° LATAS]]-Leche[[#This Row],[TOTAL CAJAS]]*48 -> 12 | H39: 46112 | I39: Confirmado
A40: PENDIENTE | B40: Angel Saavedra | C40: O.C. | D40: 46142 | E40: 1800 | F40: =ROUNDDOWN(Leche[[#This Row],[N° LATAS]]/48,0) -> 37 | G40: =Leche[[#This Row],[N° LATAS]]-Leche[[#This Row],[TOTAL CAJAS]]*48 -> 24 | H40: 46140 | I40: Confirmado
...

Sheet Producción
A1: Empresa | B1: Municipalidad | C1: Mes | D1: Fecha | E1: Total (Kg) | F1: F. Prod | G1: {=TRANSPOSE(_xlfn.ANCHORARRAY(Almacen!B9))} -> Trigo | H1: Avena | I1: Quinua | J1: Soya | K1: Maiz pollo | L1: Maiz Chufla | M1: Maca | N1: Leche en Polvo | O1: Azucar | P1: Quinua Qaliwarma | Q1: Kiwicha | R1: Cocoa | S1: Sorbato | T1: S. Canela | U1: S. Leche | V1: S. Platano | W1: S. Vainilla | X1: S. Lucuma
A2: {=Cereal[[EMPRESA]:[FECHA]]} -> PENDIENTE | B2: Agua Blanca | C2: Enero | D2: 46081 | E2: {=Cereal[TOTAL (KG)]} -> 816.5952 | F2: {=Cereal[PRODUCCIÓN]} -> 46075 | G2: {=_xlfn._xlws.FILTER(Formulas!$C$2:$T$201, ISNUMBER(MATCH(Formulas!$B$2:$B$201, B2, 0)),0) * E2} -> 163.31904 | H2: 555.28474 | I2: 32.663808 | J2: 32.663808 | K2: 0 | L2: 0 | M2: 32.663808 | N2: 0 | O2: 0 | P2: 0 | Q2: 0 | R2: 0 | S2: 0 | T2: 0 | U2: 0 | V2: 0 | W2: 0 | X2: 0
A3: PENDIENTE | B3: Agua Blanca | C3: Febrero | D3: 46081 | E3: 816.5952 | F3: 46075 | G3: {=_xlfn._xlws.FILTER(Formulas!$C$2:$T$201, ISNUMBER(MATCH(Formulas!$B$2:$B$201, B3, 0)),0) * E3} -> 163.31904 | H3: 555.28474 | I3: 32.663808 | J3: 32.663808 | K3: 0 | L3: 0 | M3: 32.663808 | N3: 0 | O3: 0 | P3: 0 | Q3: 0 | R3: 0 | S3: 0 | T3: 0 | U3: 0 | V3: 0 | W3: 0 | X3: 0
A4: PENDIENTE | B4: Agua Blanca | C4: Marzo | D4: 46081 | E4: 816.5952 | F4: 46075 | G4: {=_xlfn._xlws.FILTER(Formulas!$C$2:$T$201, ISNUMBER(MATCH(Formulas!$B$2:$B$201, B4, 0)),0) * E4} -> 163.31904 | H4: 555.28474 | I4: 32.663808 | J4: 32.663808 | K4: 0 | L4: 0 | M4: 32.663808 | N4: 0 | O4: 0 | P4: 0 | Q4: 0 | R4: 0 | S4: 0 | T4: 0 | U4: 0 | V4: 0 | W4: 0 | X4: 0
A5: PENDIENTE | B5: Agua Blanca | C5: Abril | D5: 46081 | E5: 816.5952 | F5: 46075 | G5: {=_xlfn._xlws.FILTER(Formulas!$C$2:$T$201, ISNUMBER(MATCH(Formulas!$B$2:$B$201, B5, 0)),0) * E5} -> 163.31904 | H5: 555.28474 | I5: 32.663808 | J5: 32.663808 | K5: 0 | L5: 0 | M5: 32.663808 | N5: 0 | O5: 0 | P5: 0 | Q5: 0 | R5: 0 | S5: 0 | T5: 0 | U5: 0 | V5: 0 | W5: 0 | X5: 0
A6: PENDIENTE | B6: Agua Blanca | C6: Mayo | D6: 46140 | E6: 816.5952 | F6: 46147 | G6: {=_xlfn._xlws.FILTER(Formulas!$C$2:$T$201, ISNUMBER(MATCH(Formulas!$B$2:$B$201, B6, 0)),0) * E6} -> 163.31904 | H6: 555.28474 | I6: 32.663808 | J6: 32.663808 | K6: 0 | L6: 0 | M6: 32.663808 | N6: 0 | O6: 0 | P6: 0 | Q6: 0 | R6: 0 | S6: 0 | T6: 0 | U6: 0 | V6: 0 | W6: 0 | X6: 0
A7: PENDIENTE | B7: Agua Blanca | C7: Junio | D7: 46140 | E7: 816.5952 | F7: 46147 | G7: {=_xlfn._xlws.FILTER(Formulas!$C$2:$T$201, ISNUMBER(MATCH(Formulas!$B$2:$B$201, B7, 0)),0) * E7} -> 163.31904 | H7: 555.28474 | I7: 32.663808 | J7: 32.663808 | K7: 0 | L7: 0 | M7: 32.663808 | N7: 0 | O7: 0 | P7: 0 | Q7: 0 | R7: 0 | S7: 0 | T7: 0 | U7: 0 | V7: 0 | W7: 0 | X7: 0
A8: PENDIENTE | B8: Agua Blanca | C8: Julio | D8: 46199 | E8: 816.5952 | F8: 46202 | G8: {=_xlfn._xlws.FILTER(Formulas!$C$2:$T$201, ISNUMBER(MATCH(Formulas!$B$2:$B$201, B8, 0)),0) * E8} -> 163.31904 | H8: 555.28474 | I8: 32.663808 | J8: 32.663808 | K8: 0 | L8: 0 | M8: 32.663808 | N8: 0 | O8: 0 | P8: 0 | Q8: 0 | R8: 0 | S8: 0 | T8: 0 | U8: 0 | V8: 0 | W8: 0 | X8: 0
A9: PENDIENTE | B9: Agua Blanca | C9: Agosto | D9: 46199 | E9: 816.5952 | F9: 46202 | G9: {=_xlfn._xlws.FILTER(Formulas!$C$2:$T$201, ISNUMBER(MATCH(Formulas!$B$2:$B$201, B9, 0)),0) * E9} -> 163.31904 | H9: 555.28474 | I9: 32.663808 | J9: 32.663808 | K9: 0 | L9: 0 | M9: 32.663808 | N9: 0 | O9: 0 | P9: 0 | Q9: 0 | R9: 0 | S9: 0 | T9: 0 | U9: 0 | V9: 0 | W9: 0 | X9: 0
A10: PENDIENTE | B10: Agua Blanca | C10: Setiembre | D10: 46262 | E10: 816.5952 | F10: 46263 | G10: {=_xlfn._xlws.FILTER(Formulas!$C$2:$T$201, ISNUMBER(MATCH(Formulas!$B$2:$B$201, B10, 0)),0) * E10} -> 163.31904 | H10: 555.28474 | I10: 32.663808 | J10: 32.663808 | K10: 0 | L10: 0 | M10: 32.663808 | N10: 0 | O10: 0 | P10: 0 | Q10: 0 | R10: 0 | S10: 0 | T10: 0 | U10: 0 | V10: 0 | W10: 0 | X10: 0
A11: PENDIENTE | B11: Agua Blanca | C11: Octubre | D11: 46262 | E11: 816.5952 | F11: 46263 | G11: {=_xlfn._xlws.FILTER(Formulas!$C$2:$T$201, ISNUMBER(MATCH(Formulas!$B$2:$B$201, B11, 0)),0) * E11} -> 163.31904 | H11: 555.28474 | I11: 32.663808 | J11: 32.663808 | K11: 0 | L11: 0 | M11: 32.663808 | N11: 0 | O11: 0 | P11: 0 | Q11: 0 | R11: 0 | S11: 0 | T11: 0 | U11: 0 | V11: 0 | W11: 0 | X11: 0
A12: PENDIENTE | B12: Agua Blanca | C12: Noviembre | D12: 46322 | E12: 816.5952 | F12: 0 | G12: {=_xlfn._xlws.FILTER(Formulas!$C$2:$T$201, ISNUMBER(MATCH(Formulas!$B$2:$B$201, B12, 0)),0) * E12} -> 163.31904 | H12: 555.28474 | I12: 32.663808 | J12: 32.663808 | K12: 0 | L12: 0 | M12: 32.663808 | N12: 0 | O12: 0 | P12: 0 | Q12: 0 | R12: 0 | S12: 0 | T12: 0 | U12: 0 | V12: 0 | W12: 0 | X12: 0
A13: PENDIENTE | B13: Agua Blanca | C13: Diciembre | D13: 46322 | E13: 816.5952 | F13: 0 | G13: {=_xlfn._xlws.FILTER(Formulas!$C$2:$T$201, ISNUMBER(MATCH(Formulas!$B$2:$B$201, B13, 0)),0) * E13} -> 163.31904 | H13: 555.28474 | I13: 32.663808 | J13: 32.663808 | K13: 0 | L13: 0 | M13: 32.663808 | N13: 0 | O13: 0 | P13: 0 | Q13: 0 | R13: 0 | S13: 0 | T13: 0 | U13: 0 | V13: 0 | W13: 0 | X13: 0
A14: PENDIENTE | B14: Alto Biavo | C14: O.C. | D14: 46052 | E14: 1041 | F14: 46051 | G14: {=_xlfn._xlws.FILTER(Formulas!$C$2:$T$201, ISNUMBER(MATCH(Formulas!$B$2:$B$201, B14, 0)),0) * E14} -> 208.2 | H14: 333.12 | I14: 41.64 | J14: 0 | K14: 0 | L14: 0 | M14: 52.05 | N14: 0 | O14: 405.99 | P14: 0 | Q14: 0 | R14: 0 | S14: 0 | T14: 0 | U14: 0 | V14: 0 | W14: 0 | X14: 0
... A34: PENDIENTE | B34: Alto Trujillo | C34: Diciembre | D34: 46356 | E34: 2968.5552 | F34: 0 | G34: {=_xlfn._xlws.FILTER(Formulas!$C$2:$T$201, ISNUMBER(MATCH(Formulas!$B$2:$B$201, B34, 0)),0) * E34} -> 534.73974 | H34: 2225.9166 | I34: 207.89882 | J34: 0 | K34: 0 | L34: 0 | M34: 0 | N34: 0 | O34: 0 | P34: 0 | Q34: 0 | R34: 0 | S34: 0 | T34: 0 | U34: 0 | V34: 0 | W34: 0 | X34: 0
A35: PENDIENTE | B35: Alto Trujillo | C35: 46388 | D35: 46387 | E35: 2968.5552 | F35: 0 | G35: {=_xlfn._xlws.FILTER(Formulas!$C$2:$T$201, ISNUMBER(MATCH(Formulas!$B$2:$B$201, B35, 0)),0) * E35} -> 534.73974 | H35: 2225.9166 | I35: 207.89882 | J35: 0 | K35: 0 | L35: 0 | M35: 0 | N35: 0 | O35: 0 | P35: 0 | Q35: 0 | R35: 0 | S35: 0 | T35: 0 | U35: 0 | V35: 0 | W35: 0 | X35: 0
A36: PENDIENTE | B36: Alto Trujillo | C36: 46419 | D36: 46418 | E36: 2968.5552 | F36: 0 | G36: {=_xlfn._xlws.FILTER(Formulas!$C$2:$T$201, ISNUMBER(MATCH(Formulas!$B$2:$B$201, B36, 0)),0) * E36} -> 534.73974 | H36: 2225.9166 | I36: 207.89882 | J36: 0 | K36: 0 | L36: 0 | M36: 0 | N36: 0 | O36: 0 | P36: 0 | Q36: 0 | R36: 0 | S36: 0 | T36: 0 | U36: 0 | V36: 0 | W36: 0 | X36: 0
A37: PENDIENTE | B37: Alto Trujillo | C37: 46447 | D37: 46446 | E37: 2968.5552 | F37: 0 | G37: {=_xlfn._xlws.FILTER(Formulas!$C$2:$T$201, ISNUMBER(MATCH(Formulas!$B$2:$B$201, B37, 0)),0) * E37} -> 534.73974 | H37: 2225.9166 | I37: 207.89882 | J37: 0 | K37: 0 | L37: 0 | M37: 0 | N37: 0 | O37: 0 | P37: 0 | Q37: 0 | R37: 0 | S37: 0 | T37: 0 | U37: 0 | V37: 0 | W37: 0 | X37: 0
A38: PENDIENTE | B38: Ascope | C38: Enero / Febrero / Marzo | D38: 46037 | E38: 1867.2 | F38: 46039 | G38: {=_xlfn._xlws.FILTER(Formulas!$C$2:$T$201, ISNUMBER(MATCH(Formulas!$B$2:$B$201, B38, 0)),0) * E38} -> 279.88009 | H38: 708.69636 | I38: 74.96788 | J38: 74.96788 | K38: 0 | L38: 0 | M38: 74.96788 | N38: 0 | O38: 653.71991 | P38: 0 | Q38: 0 | R38: 0 | S38: 0 | T38: 0 | U38: 0 | V38: 0 | W38: 0 | X38: 0
A39: PENDIENTE | B39: Ascope | C39: Abril / Mayo / Junio | D39: 46096 | E39: 1867.2 | F39: 46101 | G39: {=_xlfn._xlws.FILTER(Formulas!$C$2:$T$201, ISNUMBER(MATCH(Formulas!$B$2:$B$201, B39, 0)),0) * E39} -> 279.88009 | H39: 708.69636 | I39: 74.96788 | J39: 74.96788 | K39: 0 | L39: 0 | M39: 74.96788 | N39: 0 | O39: 653.71991 | P39: 0 | Q39: 0 | R39: 0 | S39: 0 | T39: 0 | U39: 0 | V39: 0 | W39: 0 | X39: 0
A40: PENDIENTE | B40: Ascope | C40: Julio / Agosto / Septiembre | D40: 46188 | E40: 1867.2 | F40: 46192 | G40: {=_xlfn._xlws.FILTER(Formulas!$C$2:$T$201, ISNUMBER(MATCH(Formulas!$B$2:$B$201, B40, 0)),0) * E40} -> 279.88009 | H40: 708.69636 | I40: 74.96788 | J40: 74.96788 | K40: 0 | L40: 0 | M40: 74.96788 | N40: 0 | O40: 653.71991 | P40: 0 | Q40: 0 | R40: 0 | S40: 0 | T40: 0 | U40: 0 | V40: 0 | W40: 0 | X40: 0
A41: PENDIENTE | B41: Ascope | C41: Octubre / Noviembre / Diciembre | D41: 46280 | E41: 1867.2 | F41: 46281 | G41: {=_xlfn._xlws.FILTER(Formulas!$C$2:$T$201, ISNUMBER(MATCH(Formulas!$B$2:$B$201, B41, 0)),0) * E41} -> 279.88009 | H41: 708.69636 | I41: 74.96788 | J41: 74.96788 | K41: 0 | L41: 0 | M41: 74.96788 | N41: 0 | O41: 653.71991 | P41: 0 | Q41: 0 | R41: 0 | S41: 0 | T41: 0 | U41: 0 | V41: 0 | W41: 0 | X41: 0
A42: PENDIENTE | B42: Asuncion | C42: Enero / Febrero / Marzo / Abril | D42: 46097 | E42: 9390 | F42: 46096 | G42: {=_xlfn._xlws.FILTER(Formulas!$C$2:$T$201, ISNUMBER(MATCH(Formulas!$B$2:$B$201, B42, 0)),0) * E42} -> 1878 | H42: 6523.7904 | I42: 329.40321 | J42: 329.40321 | K42: 0 | L42: 0 | M42: 329.40321 | N42: 0 | O42: 0 | P42: 0 | Q42: 0 | R42: 0 | S42: 0 | T42: 0 | U42: 0 | V42: 0 | W42: 0 | X42: 0
A43: PENDIENTE | B43: Asuncion | C43: Mayo / Junio | D43: 46133 | E43: 4696.5 | F43: 46130 | G43: {=_xlfn._xlws.FILTER(Formulas!$C$2:$T$201, ISNUMBER(MATCH(Formulas!$B$2:$B$201, B43, 0)),0) * E43} -> 939.3 | H43: 3262.9373 | I43: 164.75422 | J43: 164.75422 | K43: 0 | L43: 0 | M43: 164.75422 | N43: 0 | O43: 0 | P43: 0 | Q43: 0 | R43: 0 | S43: 0 | T43: 0 | U43: 0 | V43: 0 | W43: 0 | X43: 0
A44: PENDIENTE | B44: Asuncion | C44: Julio / Agosto | D44: 46181 | E44: 4696.5 | F44: 46179 | G44: {=_xlfn._xlws.FILTER(Formulas!$C$2:$T$201, ISNUMBER(MATCH(Formulas!$B$2:$B$201, B44, 0)),0) * E44} -> 939.3 | H44: 3262.9373 | I44: 164.75422 | J44: 164.75422 | K44: 0 | L44: 0 | M44: 164.75422 | N44: 0 | O44: 0 | P44: 0 | Q44: 0 | R44: 0 | S44: 0 | T44: 0 | U44: 0 | V44: 0 | W44: 0 | X44: 0
A45: PENDIENTE | B45: Asuncion | C45: O.C. | D45: 46254 | E45: 3032.92 | F45: 46237 | G45: {=_xlfn._xlws.FILTER(Formulas!$C$2:$T$201, ISNUMBER(MATCH(Formulas!$B$2:$B$201, B45, 0)),0) * E45} -> 606.584 | H45: 2107.1496 | I45: 106.39548 | J45: 106.39548 | K45: 0 | L45: 0 | M45: 106.39548 | N45: 0 | O45: 0 | P45: 0 | Q45: 0 | R45: 0 | S45: 0 | T45: 0 | U45: 0 | V45: 0 | W45: 0 | X45: 0
A46: PENDIENTE | B46: Asuncion | C46: Septiembre / Octubre | D46: 46254 | E46: 4696.5 | F46: 46253 | G46: {=_xlfn._xlws.FILTER(Formulas!$C$2:$T$201, ISNUMBER(MATCH(Formulas!$B$2:$B$201, B46, 0)),0) * E46} -> 939.3 | H46: 3262.9373 | I46: 164.75422 | J46: 164.75422 | K46: 0 | L46: 0 | M46: 164.75422 | N46: 0 | O46: 0 | P46: 0 | Q46: 0 | R46: 0 | S46: 0 | T46: 0 | U46: 0 | V46: 0 | W46: 0 | X46: 0
A47: PENDIENTE | B47: Asuncion | C47: Noviembre / Diciembre | D47: 46322 | E47: 4696.5 | F47: 0 | G47: {=_xlfn._xlws.FILTER(Formulas!$C$2:$T$201, ISNUMBER(MATCH(Formulas!$B$2:$B$201, B47, 0)),0) * E47} -> 939.3 | H47: 3262.9373 | I47: 164.75422 | J47: 164.75422 | K47: 0 | L47: 0 | M47: 164.75422 | N47: 0 | O47: 0 | P47: 0 | Q47: 0 | R47: 0 | S47: 0 | T47: 0 | U47: 0 | V47: 0 | W47: 0 | X47: 0
A48: PENDIENTE | B48: Asuncion - Chacas | C48: Enero / Febrero / Marzo | D48: 46127 | E48: 1525.5 | F48: 46128 | G48: {=_xlfn._xlws.FILTER(Formulas!$C$2:$T$201, ISNUMBER(MATCH(Formulas!$B$2:$B$201, B48, 0)),0) * E48} -> 305.1 | H48: 1052.595 | I48: 91.53 | J48: 0 | K48: 0 | L48: 0 | M48: 76.275 | N48: 0 | O48: 0 | P48: 0 | Q48: 0 | R48: 0 | S48: 0 | T48: 0 | U48: 0 | V48: 0 | W48: 0 | X48: 0
A49: PENDIENTE | B49: Asuncion - Chacas | C49: Abril / Mayo / Junio | D49: 46127 | E49: 1525.5 | F49: 46128 | G49: {=_xlfn._xlws.FILTER(Formulas!$C$2:$T$201, ISNUMBER(MATCH(Formulas!$B$2:$B$201, B49, 0)),0) * E49} -> 305.1 | H49: 1052.595 | I49: 91.53 | J49: 0 | K49: 0 | L49: 0 | M49: 76.275 | N49: 0 | O49: 0 | P49: 0 | Q49: 0 | R49: 0 | S49: 0 | T49: 0 | U49: 0 | V49: 0 | W49: 0 | X49: 0
... A215: PENDIENTE | B215: Chiclayo1 | C215: Diciembre | D215: 46352 | E215: 8951.25 | F215: 0 | G215: {=_xlfn._xlws.FILTER(Formulas!$C$2:$T$201, ISNUMBER(MATCH(Formulas!$B$2:$B$201, B215, 0)),0) * E215} -> 2327.325 | H215: 5818.3125 | I215: 357.97001 | J215: 0 | K215: 0 | L215: 0 | M215: 447.5625 | N215: 0 | O215: 0 | P215: 0 | Q215: 0 | R215: 0 | S215: 0 | T215: 0 | U215: 0 | V215: 0 | W215: 0 | X215: 0
A216: PENDIENTE | B216: Chiclayo1 | C216: 46388 | D216: 46371 | E216: 8951.25 | F216: 0 | G216: {=_xlfn._xlws.FILTER(Formulas!$C$2:$T$201, ISNUMBER(MATCH(Formulas!$B$2:$B$201, B216, 0)),0) * E216} -> 2327.325 | H216: 5818.3125 | I216: 357.97001 | J216: 0 | K216: 0 | L216: 0 | M216: 447.5625 | N216: 0 | O216: 0 | P216: 0 | Q216: 0 | R216: 0 | S216: 0 | T216: 0 | U216: 0 | V216: 0 | W216: 0 | X216: 0
A217: PENDIENTE | B217: Chiclayo1 | C217: 46419 | D217: 46377 | E217: 8085 | F217: 0 | G217: {=_xlfn._xlws.FILTER(Formulas!$C$2:$T$201, ISNUMBER(MATCH(Formulas!$B$2:$B$201, B217, 0)),0) * E217} -> 2102.1 | H217: 5255.25 | I217: 323.32775 | J217: 0 | K217: 0 | L217: 0 | M217: 404.25 | N217: 0 | O217: 0 | P217: 0 | Q217: 0 | R217: 0 | S217: 0 | T217: 0 | U217: 0 | V217: 0 | W217: 0 | X217: 0
A218: PENDIENTE | B218: Chilete | C218: Enero | D218: 46053 | E218: 802.9992 | F218: 46034 | G218: {=_xlfn._xlws.FILTER(Formulas!$C$2:$T$201, ISNUMBER(MATCH(Formulas!$B$2:$B$201, B218, 0)),0) * E218} -> 160.53094 | H218: 546.35638 | I218: 32.037291 | J218: 32.037291 | K218: 0 | L218: 0 | M218: 32.037291 | N218: 0 | O218: 0 | P218: 0 | Q218: 0 | R218: 0 | S218: 0 | T218: 0 | U218: 0 | V218: 0 | W218: 0 | X218: 0
A219: PENDIENTE | B219: Chilete | C219: Febrero | D219: 46053 | E219: 725.2896 | F219: 46034 | G219: {=_xlfn._xlws.FILTER(Formulas!$C$2:$T$201, ISNUMBER(MATCH(Formulas!$B$2:$B$201, B219, 0)),0) * E219} -> 144.99569 | H219: 493.48319 | I219: 28.936908 | J219: 28.936908 | K219: 0 | L219: 0 | M219: 28.936908 | N219: 0 | O219: 0 | P219: 0 | Q219: 0 | R219: 0 | S219: 0 | T219: 0 | U219: 0 | V219: 0 | W219: 0 | X219: 0
A220: PENDIENTE | B220: Chilete | C220: Marzo | D220: 46053 | E220: 802.9992 | F220: 46034 | G220: {=_xlfn._xlws.FILTER(Formulas!$C$2:$T$201, ISNUMBER(MATCH(Formulas!$B$2:$B$201, B220, 0)),0) * E220} -> 160.53094 | H220: 546.35638 | I220: 32.037291 | J220: 32.037291 | K220: 0 | L220: 0 | M220: 32.037291 | N220: 0 | O220: 0 | P220: 0 | Q220: 0 | R220: 0 | S220: 0 | T220: 0 | U220: 0 | V220: 0 | W220: 0 | X220: 0
A221: PENDIENTE | B221: Chilete | C221: Abril | D221: 46111 | E221: 777.096 | F221: 46106 | G221: {=_xlfn._xlws.FILTER(Formulas!$C$2:$T$201, ISNUMBER(MATCH(Formulas!$B$2:$B$201, B221, 0)),0) * E221} -> 155.35253 | H221: 528.73198 | I221: 31.00383 | J221: 31.00383 | K221: 0 | L221: 0 | M221: 31.00383 | N221: 0 | O221: 0 | P221: 0 | Q221: 0 | R221: 0 | S221: 0 | T221: 0 | U221: 0 | V221: 0 | W221: 0 | X221: 0
A222: PENDIENTE | B222: Chilete | C222: Mayo | D222: 46111 | E222: 802.9992 | F222: 46106 | G222: {=_xlfn._xlws.FILTER(Formulas!$C$2:$T$201, ISNUMBER(MATCH(Formulas!$B$2:$B$201, B222, 0)),0) * E222} -> 160.53094 | H222: 546.35638 | I222: 32.037291 | J222: 32.037291 | K222: 0 | L222: 0 | M222: 32.037291 | N222: 0 | O222: 0 | P222: 0 | Q222: 0 | R222: 0 | S222: 0 | T222: 0 | U222: 0 | V222: 0 | W222: 0 | X222: 0
A223: PENDIENTE | B223: Chilete | C223: Junio | D223: 46111 | E223: 777.096 | F223: 46106 | G223: {=_xlfn._xlws.FILTER(Formulas!$C$2:$T$201, ISNUMBER(MATCH(Formulas!$B$2:$B$201, B223, 0)),0) * E223} -> 155.35253 | H223: 528.73198 | I223: 31.00383 | J223: 31.00383 | K223: 0 | L223: 0 | M223: 31.00383 | N223: 0 | O223: 0 | P223: 0 | Q223: 0 | R223: 0 | S223: 0 | T223: 0 | U223: 0 | V223: 0 | W223: 0 | X223: 0
A224: PENDIENTE | B224: Chilete | C224: Julio | D224: 46203 | E224: 802.9992 | F224: 46194 | G224: {=_xlfn._xlws.FILTER(Formulas!$C$2:$T$201, ISNUMBER(MATCH(Formulas!$B$2:$B$201, B224, 0)),0) * E224} -> 160.53094 | H224: 546.35638 | I224: 32.037291 | J224: 32.037291 | K224: 0 | L224: 0 | M224: 32.037291 | N224: 0 | O224: 0 | P224: 0 | Q224: 0 | R224: 0 | S224: 0 | T224: 0 | U224: 0 | V224: 0 | W224: 0 | X224: 0
...

Sheet Entradas y Salidas
A1: FECHA | B1: PRODUCTO | C1: PROVEEDOR | D1: CODIGO | E1: LOTE | F1: CANTIDAD | G1: UNIDAD MEDIDA | H1: NOTAS | K1: FECHA | L1: PRODUCTO | M1: PROVEEDOR | N1: CODIGO | O1: LOTE | P1: CANTIDAD | Q1: UNIDAD MEDIDA | R1: VEHICULO
A2: 45989 | B2: Azucar | D2: AZ | E2: 1 | F2: 6000 | G2: Kg | K2: 46020 | L2: Trigo | M2: INDURLAC | P2: 10000 | Q2: Kg
A3: 45991 | B3: Avena | C3: Syngular | D3: AV | E3: 1 | F3: 36000 | G3: Kg | K3: 46062 | L3: Trigo | P3: 3000 | Q3: Kg
A4: 45992 | B4: Avena | C4: Syngular | D4: AV | E4: 2 | F4: 30000 | G4: Kg | K4: 46086 | L4: Trigo | M4: INDURLAC | P4: 6000 | Q4: Kg
A5: 45992 | B5: Quinua | D5: Q | E5: 1 | F5: 6000 | G5: Kg | K5: 46101 | L5: Trigo | M5: INDURLAC | P5: 3000 | Q5: Kg
A6: 45996 | B6: Avena | C6: Syngular | D6: AV | E6: 3 | F6: 40000 | G6: Kg | K6: 46116 | L6: Trigo | M6: INDURLAC | P6: 5000 | Q6: Kg
A7: 45997 | B7: Leche en Polvo | D7: LP | E7: 1 | F7: 800 | G7: Kg | K7: 46119 | L7: Avena | P7: =79*25 -> 1975 | Q7: Kg
A8: 45997 | B8: Leche | F8: 453 | G8: x48 latas | K8: 46139 | L8: Trigo | M8: INDURLAC | P8: 9000 | Q8: Kg
A9: 46003 | B9: Trigo | D9: TG | E9: 1 | F9: 32000 | G9: Kg | K9: 46169 | L9: Soya | M9: Yonyan | P9: 3000 | Q9: Kg
A10: 46003 | B10: Quinua | D10: Q | E10: 2 | F10: 5400 | G10: Kg | K10: 46211 | L10: Trigo | P10: 8000 | Q10: Kg
A11: 46004 | B11: Avena | C11: Syngular | D11: AV | E11: 4 | F11: 40000 | G11: Kg | K11: 46223 | L11: Trigo | P11: 5000 | Q11: Kg
A12: 46007 | B12: Avena | C12: Syngular | D12: AV | E12: 5 | F12: 40000 | G12: Kg | K12: 46249 | L12: Avena | P12: 2000 | Q12: Kg
A13: 46007 | B13: S. Vainilla | D13: SV | E13: 1 | F13: 20 | G13: Kg | K13: 46252 | L13: Avena | P13: 3000 | Q13: Kg
A14: 46008 | B14: Avena | C14: Syngular | D14: AV | E14: 6 | F14: 40000 | G14: Kg | K14: 46255 | L14: Avena | P14: 6000 | Q14: Kg
A15: 46011 | B15: Leche | F15: 114 | G15: x48 latas | K15: 46280 | L15: Trigo | M15: INDURLAC | P15: 10000 | Q15: Kg
A16: 46376 | B16: Avena | D16: AV | E16: 7 | F16: 20000 | G16: Kg | H16: Otro Almacen
A17: 46024 | B17: Maca | D17: MC | E17: 1 | F17: 5000 | G17: Kg
A18: 46024 | B18: Kiwicha | D18: KW | E18: 1 | F18: 200 | G18: Kg
A19: 46024 | B19: Maiz pollo | D19: MZP | E19: 1 | F19: 440 | G19: Kg
A20: 46024 | B20: Maiz chufla | D20: MZC | E20: 1 | F20: 138 | G20: Kg
A21: 46025 | B21: Azucar | D21: AZ | E21: 2 | F21: 35000 | G21: Kg
A22: 46028 | B22: Soya | D22: SY | E22: 1 | F22: 5000 | G22: Kg
A23: 46028 | B23: Quinua | D23: Q | E23: 3 | F23: 2500 | G23: Kg | H23: 8.5 tn - 6 tn devolución
A24: 46028 | B24: S. Leche | D24: SL | E24: 1 | F24: 40 | G24: Kg
A25: 46030 | B25: Trigo | D25: TG | E25: 2 | F25: 25000 | G25: Kg
A26: 46030 | B26: Avena | D26: AV | E26: 8 | F26: 17000 | G26: Kg
A27: 46030 | B27: Leche | F27: 212 | G27: x48 latas
A28: 46030 | B28: Leche | F28: 572 | G28: x48 latas
A29: 46030 | B29: Maiz chufla | D29: MZC | E29: 2 | F29: 200 | G29: Kg
A30: 46030 | B30: Maiz Pollo | D30: MZP | E30: 2 | F30: 150 | G30: Kg
A31: 46030 | B31: Kiwicha | D31: KW | E31: 2 | F31: 300 | G31: Kg
A32: 46030 | B32: Leche en Polvo | D32: LP | E32: 2 | F32: 1200 | G32: Kg
A33: 46037 | B33: Leche | F33: 485 | G33: x48 latas
A34: 46039 | B34: Quinua Qaliwarma | D34: QQ | E34: 1 | F34: 350 | G34: Kg
A35: 46040 | B35: Cocoa | D35: CC | E35: 1 | F35: 200 | G35: Kg
A36: 46041 | B36: Leche | F36: 489 | G36: x48 latas
A37: 46041 | B37: Avena | D37: AV | E37: 9 | F37: 25000 | G37: Kg | H37: Singular
A38: 46041 | B38: Avena | D38: AV | E38: 9 | F38: 15000 | G38: Kg | H38: Agropel
A39: 46043 | B39: Leche | F39: 1000 | G39: x48 latas
A40: 46045 | B40: Maiz chufla | D40: MZC | E40: 3 | F40: =12*46 -> 552 | G40: Kg
...

Sheet Almacen
C1: STOCK | F1: Proyección | G1: Saldo
B2: Leche Total | C2: Tarros total | D2: Cajas | E2: Unidades | J2: PRODUCTO ENVASADO EN ALMACEN
C3: =252*48 -SUMIF(Leche[CONFIRMACIÓN], "Confirmado", Leche[N° LATAS]) + SUMIF(Entradas[PRODUCTO],"Leche",Entradas[CANTIDAD])*48 - SUMIF(Salida[PRODUCTO],"Leche",Salida[CANTIDAD])*48 + 257*48 -> 112873.75 | D3: =ROUNDDOWN(C3/48,0) -> 2351 | E3: =C3-D3*48 -> 25.75 | F3: =Calculo!C36 -> 95451.95 | G3: =C3-F3 -> 17421.8 | J3: Empresa | K3: Cliente | L3: Mes | M3: Fecha | N3: N° Bolsas | O3: Kg Bolsa | P3: Total (Kg) | Q3: Cap. Sacos | R3: N° Sacos | S3: Unidades | T3: Producción | U3: Envasado
F4: =F3/48 -> 1988.5823 | G4: =G3/48 -> 362.95417 | J4: {=_xlfn._xlws.FILTER(Cereal[[EMPRESA]:[ENVASADO]], (Cereal[ENVASADO]<>"") * (Cereal[SALIDA]="") * (Cereal[ENVASADO] <= TODAY()))} -> CORDELAN | K4: Huayllabamba | L4: Octubre | M4: 46289 | N4: 620 | O4: 1.0565 | P4: 655.03 | Q4: 40 | R4: 15 | S4: 20 | T4: 46281 | U4: 46281
J5: CORDELAN | K5: Huayllabamba | L5: Noviembre | M5: 46289 | N5: 620 | O5: 1.0565 | P5: 655.03 | Q5: 40 | R5: 15 | S5: 20 | T5: 46281 | U5: 46281
J6: PENDIENTE | K6: Marcara1 | L6: Octubre / Noviembre / Diciembre | M6: 46295 | N6: 2340 | O6: 0.62064 | P6: 1452.2976 | Q6: 70 | R6: 33 | S6: 30 | T6: 46293 | U6: 46293
J7: GRAN INDUST. | K7: Qaliwarma Avena | L7: Yurimag | M7: 46295 | N7: 10960 | O7: 0.26 | P7: 2849.6 | Q7: 100 | R7: 109 | S7: 60 | T7: 46293 | U7: 46293
B8: Producto | C8: Total (kg) | D8: Saco (kg) | E8: N°Sacos | F8: Proyección | G8: Saldo | J8: PENDIENTE | K8: Taurija | L8: Octubre | M8: 46295 | N8: 450 | O8: 0.74464 | P8: 335.088 | Q8: 60 | R8: 7 | S8: 30 | T8: 46281 | U8: 46281
B9: {=TRANSPOSE(Formulas!C1:T1)} -> Trigo | C9: =12600+18396*1.11-SUMIF(Producción!F:F,"<>0",Producción!G:G)*1.11 + SUMIF(Entradas[PRODUCTO],B9,Entradas[CANTIDAD]) - SUMIF(Salida[PRODUCTO],B9,Salida[CANTIDAD]) -6600-400 -> 9105.6107 | D9: 50 | E9: =C9/D9 -> 182.11221 | F9: {=TRANSPOSE(Calculo!C17:T17)} -> 25637.13 | G9: =C9-F9 -> -16531.519 | H9: pedir 16 TN mas | J9: PENDIENTE | K9: Taurija | L9: Noviembre | M9: 46295 | N9: 450 | O9: 0.74464 | P9: 335.088 | Q9: 60 | R9: 7 | S9: 30 | T9: 46281 | U9: 46281
B10: Avena | C10: =47575+7625-SUMIF(Producción!$F:$F,"<>0",Producción!H:H) + SUMIF(Entradas[PRODUCTO],B10,Entradas[CANTIDAD])-106 - SUMIF(Salida[PRODUCTO],B10,Salida[CANTIDAD])-6800 -> -18997.667 | D10: 25 | E10: =C10/D10 -> -759.90668 | F10: 81633.024 | G10: =C10-F10 -> -100630.69 | H10: faltan llegar 55 | J10: PENDIENTE | K10: Taurija | L10: Diciembre | M10: 46295 | N10: 450 | O10: 0.74464 | P10: 335.088 | Q10: 60 | R10: 7 | S10: 30 | T10: 46281 | U10: 46281
B11: Quinua | C11: =2500-SUMIF(Producción!$F:$F,"<>0",Producción!I:I) + SUMIF(Entradas[PRODUCTO],B11,Entradas[CANTIDAD]) +1600 -> 6466.7704 | D11: 50 | E11: =C11/D11 -> 129.33541 | F11: 2995.9986 | G11: =C11-F11 -> 3470.7718 | J11: FACOIMPEC | K11: Urpay | L11: Octubre / Noviembre / Diciembre | M11: 46288 | N11: 1316.13 | O11: 1 | P11: 1316.13 | Q11: 40 | R11: 32 | S11: 36.13 | T11: 46282 | U11: 46282
B12: Soya | C12: =10200-SUMIF(Producción!$F:$F,"<>0",Producción!J:J)*1.07 + SUMIF(Entradas[PRODUCTO],B12,Entradas[CANTIDAD])- SUMIF(Salida[PRODUCTO],B12,Salida[CANTIDAD])-3788+1129 -> 20410.387 | D12: 50 | E12: =C12/D12 -> 408.20774 | F12: 3574.8408 | G12: =C12-F12 -> 16835.546
B13: Maiz pollo | C13: =66*1.03-SUMIF(Producción!$F:$F,"<>0",Producción!K:K)*1.03 + SUMIF(Entradas[PRODUCTO],B13,Entradas[CANTIDAD])+60 -> 6.6985 | F13: 0 | G13: =C13-F13 -> 6.6985
A14: (chiclayano) | B14: Maiz Chufla | C14: =127+1.03*201-SUMIF(Producción!$F:$F,"<>0",Producción!L:L)*1.03 + SUMIF(Entradas[PRODUCTO],B14,Entradas[CANTIDAD])+400 -> 235.33182 | F14: 1333.2221 | G14: =C14-F14 -> -1097.8903
B15: Maca | C15: =3750-SUMIF(Producción!$F:$F,"<>0",Producción!M:M) + SUMIF(Entradas[PRODUCTO],B15,Entradas[CANTIDAD])+170 -500 -> 8483.8113 | D15: 50 | E15: =C15/D15 -> 169.67623 | F15: 2353.7846 | G15: =C15-F15 -> 6130.0267
B16: Leche en Polvo | C16: =397-SUMIF(Producción!$F:$F,"<>0",Producción!N:N) + SUMIF(Entradas[PRODUCTO],B16,Entradas[CANTIDAD])+160 -> 168.9075 | D16: 25 | E16: =C16/D16 -> 6.7563001 | F16: 481.34054 | G16: =C16-F16 -> -312.43304
B17: Azucar | C17: =7750-SUMIF(Producción!$F:$F,"<>0",Producción!O:O) + SUMIF(Entradas[PRODUCTO],B17,Entradas[CANTIDAD])-2100 -> 3443.943 | D17: 50 | E17: =C17/D17 -> 68.878859 | F17: 5803.6548 | G17: =C17-F17 -> -2359.7118
B18: Quinua Qaliwarma | C18: =0-SUMIF(Producción!$F:$F,"<>0",Producción!P:P) + SUMIF(Entradas[PRODUCTO],B18,Entradas[CANTIDAD])-148-55 -> 311.2288 | F18: 233.376 | G18: =C18-F18 -> 77.8528
B19: Kiwicha | C19: =78-SUMIF(Producción!$F:$F,"<>0",Producción!Q:Q) + SUMIF(Entradas[PRODUCTO],B19,Entradas[CANTIDAD])+183 -> -189.00686 | F19: 600.70114 | G19: =C19-F19 -> -789.70801
B20: Cocoa | C20: =0-SUMIF(Producción!$F:$F,"<>0",Producción!R:R) + SUMIF(Entradas[PRODUCTO],B20,Entradas[CANTIDAD])+1.53+1.55 -> -67.766575 | F20: 0 | G20: =C20-F20 -> -67.766575
B21: Sorbato | C21: =0-SUMIF(Producción!$F:$F,"<>0",Producción!S:S) + SUMIF(Entradas[PRODUCTO],B21,Entradas[CANTIDAD]) -> 0 | F21: 0 | G21: =C21-F21 -> 0
B22: S. Canela | C22: =19-SUMIF(Producción!$F:$F,"<>0",Producción!T:T) + SUMIF(Entradas[PRODUCTO],B22,Entradas[CANTIDAD]) -> 6.8187 | F22: 0 | G22: =C22-F22 -> 6.8187
B23: S. Leche | C23: =13-SUMIF(Producción!$F:$F,"<>0",Producción!U:U) + SUMIF(Entradas[PRODUCTO],B23,Entradas[CANTIDAD])+10 -> 10.971498 | F23: 9.40756 | G23: =C23-F23 -> 1.563938
B24: S. Platano | C24: =14-SUMIF(Producción!$F:$F,"<>0",Producción!V:V) + SUMIF(Entradas[PRODUCTO],B24,Entradas[CANTIDAD])-2+10 -> 36.540608 | F24: 38.191871 | G24: =C24-F24 -> -1.651263
B25: S. Vainilla | C25: =0-SUMIF(Producción!$F:$F,"<>0",Producción!W:W) + SUMIF(Entradas[PRODUCTO],B25,Entradas[CANTIDAD]) -> 16.056957 | F25: 0 | G25: =C25-F25 -> 16.056957
B26: S. Lucuma | C26: =22-SUMIF(Producción!$F:$F,"<>0",Producción!X:X) + SUMIF(Entradas[PRODUCTO],B26,Entradas[CANTIDAD])-5.64+5.48 -> 11.715566 | F26: 0 | G26: =C26-F26 -> 11.715566
B29: STOCK SACOS | C29: =(700-SUMIF(Cereal[PRODUCCIÓN],"<>",Cereal[N° SACOS]) -COUNTIF(Cereal[PRODUCCIÓN], "<>") +25858) + SUMIF(Entradas[PRODUCTO],"Sacos",Entradas[CANTIDAD])*0.965 +2700 -> -1806
B30: Proyección | C30: =Calculo!U17*1.035 -> 3385.485
B31: Saldo | C31: =C29-C30 -> -5191.485

Sheet Calculo
B2: PROYECCIÓN 2026
B3: Producto | C3: {=TRANSPOSE(_xlfn.ANCHORARRAY(Almacen!B9))} -> Trigo | D3: Avena | E3: Quinua | F3: Soya | G3: Maiz pollo | H3: Maiz Chufla | I3: Maca | J3: Leche en Polvo | K3: Azucar | L3: Quinua Qaliwarma | M3: Kiwicha | N3: Cocoa | O3: Sorbato | P3: S. Canela | Q3: S. Leche | R3: S. Platano | S3: S. Vainilla | T3: S. Lucuma | U3: Sacos
A4: FALSE | B4: Adelanto | C4: =SUMIFS(Producción!G:G, Producción!$D:$D, ">=" & DATE(2025,12,1), Producción!$D:$D, "<=" & DATE(2025,12,31), Producción!$F:$F, 0) -> 0 | D4: =SUMIFS(Producción!H:H, Producción!$D:$D, ">=" & DATE(2025,12,1), Producción!$D:$D, "<=" & DATE(2025,12,31), Producción!$F:$F, 0) -> 0 | E4: =SUMIFS(Producción!I:I, Producción!$D:$D, ">=" & DATE(2025,12,1), Producción!$D:$D, "<=" & DATE(2025,12,31), Producción!$F:$F, 0) -> 0 | F4: =SUMIFS(Producción!J:J, Producción!$D:$D, ">=" & DATE(2025,12,1), Producción!$D:$D, "<=" & DATE(2025,12,31), Producción!$F:$F, 0) -> 0 | G4: =SUMIFS(Producción!K:K, Producción!$D:$D, ">=" & DATE(2025,12,1), Producción!$D:$D, "<=" & DATE(2025,12,31), Producción!$F:$F, 0) -> 0 | H4: =SUMIFS(Producción!L:L, Producción!$D:$D, ">=" & DATE(2025,12,1), Producción!$D:$D, "<=" & DATE(2025,12,31), Producción!$F:$F, 0) -> 0 | I4: =SUMIFS(Producción!M:M, Producción!$D:$D, ">=" & DATE(2025,12,1), Producción!$D:$D, "<=" & DATE(2025,12,31), Producción!$F:$F, 0) -> 0 | J4: =SUMIFS(Producción!N:N, Producción!$D:$D, ">=" & DATE(2025,12,1), Producción!$D:$D, "<=" & DATE(2025,12,31), Producción!$F:$F, 0) -> 0 | K4: =SUMIFS(Producción!O:O, Producción!$D:$D, ">=" & DATE(2025,12,1), Producción!$D:$D, "<=" & DATE(2025,12,31), Producción!$F:$F, 0) -> 0 | L4: =SUMIFS(Producción!P:P, Producción!$D:$D, ">=" & DATE(2025,12,1), Producción!$D:$D, "<=" & DATE(2025,12,31), Producción!$F:$F, 0) -> 0 | M4: =SUMIFS(Producción!Q:Q, Producción!$D:$D, ">=" & DATE(2025,12,1), Producción!$D:$D, "<=" & DATE(2025,12,31), Producción!$F:$F, 0) -> 0 | N4: =SUMIFS(Producción!R:R, Producción!$D:$D, ">=" & DATE(2025,12,1), Producción!$D:$D, "<=" & DATE(2025,12,31), Producción!$F:$F, 0) -> 0 | O4: =SUMIFS(Producción!S:S, Producción!$D:$D, ">=" & DATE(2025,12,1), Producción!$D:$D, "<=" & DATE(2025,12,31), Producción!$F:$F, 0) -> 0 | P4: =SUMIFS(Producción!T:T, Producción!$D:$D, ">=" & DATE(2025,12,1), Producción!$D:$D, "<=" & DATE(2025,12,31), Producción!$F:$F, 0) -> 0 | Q4: =SUMIFS(Producción!U:U, Producción!$D:$D, ">=" & DATE(2025,12,1), Producción!$D:$D, "<=" & DATE(2025,12,31), Producción!$F:$F, 0) -> 0 | R4: =SUMIFS(Producción!V:V, Producción!$D:$D, ">=" & DATE(2025,12,1), Producción!$D:$D, "<=" & DATE(2025,12,31), Producción!$F:$F, 0) -> 0 | S4: =SUMIFS(Producción!W:W, Producción!$D:$D, ">=" & DATE(2025,12,1), Producción!$D:$D, "<=" & DATE(2025,12,31), Producción!$F:$F, 0) -> 0 | T4: =SUMIFS(Producción!X:X, Producción!$D:$D, ">=" & DATE(2025,12,1), Producción!$D:$D, "<=" & DATE(2025,12,31), Producción!$F:$F, 0) -> 0 | U4: 0
